Workbook

Sheet Inputs
A1: key | B1: value | C1: unit | D1: role
A2: total_investment_wan | B2: 42642 | C2: 万元 | D2: input
A3: construction_wan | B3: 41789.16 | C3: 万元 | D3: input
A4: interest_wan | B4: 477.59 | C4: 万元 | D4: input
A5: equity_capital_wan | B5: 12792.6 | C5: 万元 | D5: input
A6: loan_wan | B6: 29849.4 | C6: 万元 | D6: input
A7: calc_years | B7: 25 | C7: 年 | D7: input
A8: build_years | B8: 1 | C8: 年 | D8: input
A9: finance_schema_version | B9: 2.0 | D9: input

Sheet 附表1
A1: 附表1 固定资产投资估算表
A2: 匡算预览｜未批准，不得用于正式报批；口径：summary；有效：是
A3: 序号 | B3: 工程或费用名称 | C3: 计量单位 | D3: 工程量 | E3: 估算指标（元） | F3: 建筑工程 | G3: 设备原价 | H3: 运杂安装工程费 | I3: 其它费用 | J3: 合计 | K3: 比例(%)
A4: 1 | B4: 工程费用 | J4: 38502 | K4: 90.29
A5: 1.1 | B5: 建筑工程费 | C5: 万元 | F5: =J5 | J5: =D5*E5/10000 | K5: =J5/J15*100
A6: 1.2 | B6: 设备及工器具购置费 | C6: 万元 | G6: =J6 | J6: =D6*E6/10000 | K6: =J6/J15*100
A7: 1.3 | B7: 安装工程费 | C7: 万元 | H7: =J7 | J7: =D7*E7/10000 | K7: =J7/J15*100
A8: 2 | B8: 工程建设其他费用 | J8: 0 | K8: 0
A9: 3 | B9: 预备费 | J9: 1217.16 | K9: 2.85
A10: 3.1 | B10: 基本预备费 | C10: 万元 | I10: =J10 | J10: =D10*E10/10000 | K10: =J10/J15*100
A11: 4 | B11: 一至三项合计 | C11: 万元 | I11: 39719.16 | J11: 39719.16 | K11: 93.15
A12: 5 | B12: 建设期贷款利息 | C12: 万元 | I12: 477.59 | J12: 477.59 | K12: 1.12
A13: 6 | B13: 固定资产投资合计 | C13: 万元 | I13: 40196.75 | J13: 40196.75 | K13: 94.27
A14: 7 | B14: 流动资金 | C14: 万元 | I14: 0 | J14: 0 | K14: 0
B15: 项目总投资合计 | C15: 万元 | J15: 42642 | K15: 100
A16: 说明1：明细来自用户输入；未提供工程量/指标时保持空白，不反向造数
A17: 说明2：missing_fields: construction_items 工程量×估算指标明细（≥3 项；仅有分类金额不算 reference）；construction_items 明细（需≥3 项工程量×指标）
A18: 说明3：structure_gaps: 工程明细不足（需≥3项，当前0）；工程量×估算指标成对不足（需≥3，当前0）

Sheet 附表2
A1: 附表2 建设期贷款利息表
A2: 匡算预览｜未批准，不得用于正式报批；口径：reference；有效：是
A3: 序号 | B3: 项目 | C3: 合计 | D3: 分年1
A4: 1 | B4: 期初借款余额 | C4: =D4 | D4: =B14
A5: 2 | B5: 当期借款 | C5: =SUM(D5) | D5: =C14
A6: 3 | B6: 年利率 | C6: 3.20% | D6: 3.20%
A7: 4 | B7: 当期应付利息 | C7: =SUM(D7) | D7: =E14
A8: 5 | B8: 期末借款余额 | C8: =D8 | D8: =F14
A9: 6 | B9: 其他融资费用 | C9: 0 | D9: 0
B10: 小计 | C10: =SUM(D10) | D10: =E14
A12: 引擎逐年计算区（供公式与跨表追溯）
A13: 期间 | B13: 期初借款余额 | C13: 当期提款 | D13: 年利率(%) | E13: 当期利息 | F13: 期末借款余额
A14: 1 | B14: 0 | C14: 29849.4 | D14: 0.032 | E14: =(B14+C14/2)*D14 | F14: =B14+C14

Sheet 附表3
A1: 附表3 流动资金估算表
A2: 匡算预览｜未批准，不得用于正式报批；口径：not_applicable；有效：否
A3: 构成项 | B3: 金额（万元）
A4: 流动资金总额（汇总输入） | B4: 0
A5: 说明1：method=ratio_backsolve
A6: 说明2：未提供周转天数，不展示反解伪分项；不得标分项法完成
A7: 跨表依赖复核：附表6 | B7: ='附表6'!A16

Sheet 附表4
A1: 附表4 投资使用计划与资金筹措表
A2: 匡算预览｜未批准，不得用于正式报批；口径：summary；有效：是
A3: 序号 | B3: 项目 | C3: 建设期第1年 | D3: 合计
A4: 1 | B4: 项目总投资使用计划 | C4: =SUM(C5,C6,C7) | D4: ='附表1'!J15
A5: 1.1 | B5: 建设投资 | C5: 41789.16 | D5: 41789.16
A6: 1.2 | B6: 建设期贷款利息 | C6: 477.59 | D6: 477.59
A7: 1.3 | B7: 流动资金 | C7: 0 | D7: 0
A8: 2 | B8: 资金筹措 | C8: =SUM(C9,C11) | D8: ='附表1'!J15
A9: 2.1 | B9: 项目资本金（自筹） | C9: 12792.6 | D9: 12792.6
A10: 2.2 | B10: 债务资金 | C10: 29849.4 | D10: 29849.4
A11: 2.2.1 | B11: 银行贷款 | C11: 29849.4 | D11: 29849.4
A12: 说明1：无分年资金事实时按建设支出比例摊分；不得作为 formal 资金计划真源
A13: 说明2：structure_gaps: 资金计划为比例摊分回退，非事实包分年真源
A14: 跨表依赖复核：附表1 | B14: ='附表1'!J4
A15: 跨表依赖复核：附表3 | B15: ='附表3'!B4

Sheet 附表5
A1: 附表5 营业收入、税金及附加和增值税估算表
A2: 匡算预览｜未批准，不得用于正式报批；口径：summary；有效：是
A3: 序号 | B3: 项目 | C3: 单位 | D3: 合计 | E3: 分年1 | F3: 分年2 | G3: 分年3 | H3: 分年4 | I3: 分年5 | J3: 分年6 | K3: 分年7 | L3: 分年8 | M3: 分年9 | N3: 分年10 | O3: 分年11 | P3: 分年12 | Q3: 分年13 | R3: 分年14 | S3: 分年15 | T3: 分年16 | U3: 分年17 | V3: 分年18 | W3: 分年19 | X3: 分年20 | Y3: 分年21 | Z3: 分年22 | AA3: 分年23 | AB3: 分年24
A4: 1 | B4: 营业收入 | C4: 万元 | D4: =SUM(E4,F4,G4,H4,I4,J4,K4,L4,M4,N4,O4,P4,Q4,R4,S4,T4,U4,V4,W4,X4,Y4,Z4,AA4,AB4) | E4: =B16 | F4: =B17 | G4: =B18 | H4: =B19 | I4: =B20 | J4: =B21 | K4: =B22 | L4: =B23 | M4: =B24 | N4: =B25 | O4: =B26 | P4: =B27 | Q4: =B28 | R4: =B29 | S4: =B30 | T4: =B31 | U4: =B32 | V4: =B33 | W4: =B34 | X4: =B35 | Y4: =B36 | Z4: =B37 | AA4: =B38 | AB4: =B39
A5: 1.9 | B5: 营业收入合计 | C5: 万元 | D5: =SUM(E5,F5,G5,H5,I5,J5,K5,L5,M5,N5,O5,P5,Q5,R5,S5,T5,U5,V5,W5,X5,Y5,Z5,AA5,AB5) | E5: =B16 | F5: =B17 | G5: =B18 | H5: =B19 | I5: =B20 | J5: =B21 | K5: =B22 | L5: =B23 | M5: =B24 | N5: =B25 | O5: =B26 | P5: =B27 | Q5: =B28 | R5: =B29 | S5: =B30 | T5: =B31 | U5: =B32 | V5: =B33 | W5: =B34 | X5: =B35 | Y5: =B36 | Z5: =B37 | AA5: =B38 | AB5: =B39
A6: 2 | B6: 销项税额 | C6: 万元 | D6: =SUM(E6,F6,G6,H6,I6,J6,K6,L6,M6,N6,O6,P6,Q6,R6,S6,T6,U6,V6,W6,X6,Y6,Z6,AA6,AB6) | E6: =F16 | F6: =F17 | G6: =F18 | H6: =F19 | I6: =F20 | J6: =F21 | K6: =F22 | L6: =F23 | M6: =F24 | N6: =F25 | O6: =F26 | P6: =F27 | Q6: =F28 | R6: =F29 | S6: =F30 | T6: =F31 | U6: =F32 | V6: =F33 | W6: =F34 | X6: =F35 | Y6: =F36 | Z6: =F37 | AA6: =F38 | AB6: =F39
A7: 3 | B7: 营业税金与附加 | C7: 万元 | D7: =SUM(E7,F7,G7,H7,I7,J7,K7,L7,M7,N7,O7,P7,Q7,R7,S7,T7,U7,V7,W7,X7,Y7,Z7,AA7,AB7) | E7: =E16 | F7: =E17 | G7: =E18 | H7: =E19 | I7: =E20 | J7: =E21 | K7: =E22 | L7: =E23 | M7: =E24 | N7: =E25 | O7: =E26 | P7: =E27 | Q7: =E28 | R7: =E29 | S7: =E30 | T7: =E31 | U7: =E32 | V7: =E33 | W7: =E34 | X7: =E35 | Y7: =E36 | Z7: =E37 | AA7: =E38 | AB7: =E39
A8: 3.1 | B8: 城市维护建设税 | C8: 万元
A9: 3.2 | B9: 教育费附加 | C9: 万元
A10: 3.3 | B10: 地方教育附加 | C10: 万元
A11: 4 | B11: 进项税额 | C11: 万元 | D11: =SUM(E11,F11,G11,H11,I11,J11,K11,L11,M11,N11,O11,P11,Q11,R11,S11,T11,U11,V11,W11,X11,Y11,Z11,AA11,AB11) | E11: =G16 | F11: =G17 | G11: =G18 | H11: =G19 | I11: =G20 | J11: =G21 | K11: =G22 | L11: =G23 | M11: =G24 | N11: =G25 | O11: =G26 | P11: =G27 | Q11: =G28 | R11: =G29 | S11: =G30 | T11: =G31 | U11: =G32 | V11: =G33 | W11: =G34 | X11: =G35 | Y11: =G36 | Z11: =G37 | AA11: =G38 | AB11: =G39
A12: 5 | B12: 应纳增值税 | C12: 万元 | D12: =SUM(E12,F12,G12,H12,I12,J12,K12,L12,M12,N12,O12,P12,Q12,R12,S12,T12,U12,V12,W12,X12,Y12,Z12,AA12,AB12) | E12: =H16 | F12: =H17 | G12: =H18 | H12: =H19 | I12: =H20 | J12: =H21 | K12: =H22 | L12: =H23 | M12: =H24 | N12: =H25 | O12: =H26 | P12: =H27 | Q12: =H28 | R12: =H29 | S12: =H30 | T12: =H31 | U12: =H32 | V12: =H33 | W12: =H34 | X12: =H35 | Y12: =H36 | Z12: =H37 | AA12: =H38 | AB12: =H39
A14: 引擎逐年计算区（供公式与跨表追溯）
A15: 运营年 | B15: 营业收入 | C15: 经营成本 | D15: 折旧 | E15: 销售税金及附加 | F15: 销项税额 | G15: 进项税额 | H15: 应纳增值税 | I15: 调整所得税(融资前) | J15: 融资前净利
A16: 1 | B16: 4195.8 | C16: 1473.79 | D16: 2007.67 | E16: 47.77 | F16: 545.45 | G16: 147.38 | H16: 398.07 | I16: 166.64 | J16: 499.93
A17: 2 | B17: 4195.8 | C17: 1473.79 | D17: 2007.67 | E17: 47.77 | F17: 545.45 | G17: 147.38 | H17: 398.07 | I17: 166.64 | J17: 499.93
A18: 3 | B18: 4195.8 | C18: 1473.79 | D18: 2007.67 | E18: 47.77 | F18: 545.45 | G18: 147.38 | H18: 398.07 | I18: 166.64 | J18: 499.93
A19: 4 | B19: 4195.8 | C19: 1473.79 | D19: 2007.67 | E19: 47.77 | F19: 545.45 | G19: 147.38 | H19: 398.07 | I19: 166.64 | J19: 499.93
A20: 5 | B20: 4195.8 | C20: 1473.79 | D20: 2007.67 | E20: 47.77 | F20: 545.45 | G20: 147.38 | H20: 398.07 | I20: 166.64 | J20: 499.93
A21: 6 | B21: 4195.8 | C21: 1473.79 | D21: 2007.67 | E21: 47.77 | F21: 545.45 | G21: 147.38 | H21: 398.07 | I21: 166.64 | J21: 499.93
A22: 7 | B22: 4195.8 | C22: 1473.79 | D22: 2007.67 | E22: 47.77 | F22: 545.45 | G22: 147.38 | H22: 398.07 | I22: 166.64 | J22: 499.93
A23: 8 | B23: 4195.8 | C23: 1473.79 | D23: 2007.67 | E23: 47.77 | F23: 545.45 | G23: 147.38 | H23: 398.07 | I23: 166.64 | J23: 499.93
A24: 9 | B24: 4195.8 | C24: 1473.79 | D24: 2007.67 | E24: 47.77 | F24: 545.45 | G24: 147.38 | H24: 398.07 | I24: 166.64 | J24: 499.93
A25: 10 | B25: 4195.8 | C25: 1473.79 | D25: 2007.67 | E25: 47.77 | F25: 545.45 | G25: 147.38 | H25: 398.07 | I25: 166.64 | J25: 499.93
A26: 11 | B26: 4195.8 | C26: 1473.79 | D26: 2007.67 | E26: 47.77 | F26: 545.45 | G26: 147.38 | H26: 398.07 | I26: 166.64 | J26: 499.93
A27: 12 | B27: 4195.8 | C27: 1473.79 | D27: 2007.67 | E27: 47.77 | F27: 545.45 | G27: 147.38 | H27: 398.07 | I27: 166.64 | J27: 499.93
... A39: 24 | B39: 4195.8 | C39: 1473.79 | D39: 0 | E39: 47.77 | F39: 545.45 | G39: 147.38 | H39: 398.07 | I39: 668.56 | J39: 2005.68
A40: 说明1：missing_fields: 正式级收入明细（flat 单点收入仅可作摘要）
A41: 说明2：structure_gaps: 行业变体未冻结(variant=flat_estimate, model=flat)；缺参考行组 price（单价）；缺参考行组 quantity（数量）；缺分产品量价 product_tree；产品爬坡/去化序列不足（仅单点）；城建税/教育费附加/地方教育附加缺明确政策口径
A42: 跨表依赖复核：附表6 | B42: ='附表6'!A16

Sheet 附表6
A1: 附表6 总成本费用估算表
A2: 匡算预览｜未批准，不得用于正式报批；口径：summary；有效：是
A3: 序号 | B3: 项目 | C3: 合计 | D3: 计算期1 | E3: 计算期2 | F3: 计算期3 | G3: 计算期4 | H3: 计算期5 | I3: 计算期6 | J3: 计算期7 | K3: 计算期8 | L3: 计算期9 | M3: 计算期10 | N3: 计算期11 | O3: 计算期12 | P3: 计算期13 | Q3: 计算期14 | R3: 计算期15 | S3: 计算期16 | T3: 计算期17 | U3: 计算期18 | V3: 计算期19 | W3: 计算期20 | X3: 计算期21 | Y3: 计算期22 | Z3: 计算期23 | AA3: 计算期24
A4: 1 | B4: 生产负荷（%） | C4: 100 | D4: 100 | E4: 100 | F4: 100 | G4: 100 | H4: 100 | I4: 100 | J4: 100 | K4: 100 | L4: 100 | M4: 100 | N4: 100 | O4: 100 | P4: 100 | Q4: 100 | R4: 100 | S4: 100 | T4: 100 | U4: 100 | V4: 100 | W4: 100 | X4: 100 | Y4: 100 | Z4: 100 | AA4: 100
A5: 8 | B5: 经营成本 | C5: =SUM(D5,E5,F5,G5,H5,I5,J5,K5,L5,M5,N5,O5,P5,Q5,R5,S5,T5,U5,V5,W5,X5,Y5,Z5,AA5) | D5: =B16 | E5: =B17 | F5: =B18 | G5: =B19 | H5: =B20 | I5: =B21 | J5: =B22 | K5: =B23 | L5: =B24 | M5: =B25 | N5: =B26 | O5: =B27 | P5: =B28 | Q5: =B29 | R5: =B30 | S5: =B31 | T5: =B32 | U5: =B33 | V5: =B34 | W5: =B35 | X5: =B36 | Y5: =B37 | Z5: =B38 | AA5: =B39
A6: 9 | B6: 折旧费 | C6: =SUM(D6,E6,F6,G6,H6,I6,J6,K6,L6,M6,N6,O6,P6,Q6,R6,S6,T6,U6,V6,W6,X6,Y6,Z6,AA6) | D6: =C16 | E6: =C17 | F6: =C18 | G6: =C19 | H6: =C20 | I6: =C21 | J6: =C22 | K6: =C23 | L6: =C24 | M6: =C25 | N6: =C26 | O6: =C27 | P6: =C28 | Q6: =C29 | R6: =C30 | S6: =C31 | T6: =C32 | U6: =C33 | V6: =C34 | W6: =C35 | X6: =C36 | Y6: =C37 | Z6: =C38 | AA6: =C39
A7: 10 | B7: 摊销费 | C7: =SUM(D7,E7,F7,G7,H7,I7,J7,K7,L7,M7,N7,O7,P7,Q7,R7,S7,T7,U7,V7,W7,X7,Y7,Z7,AA7) | D7: =D16 | E7: =D17 | F7: =D18 | G7: =D19 | H7: =D20 | I7: =D21 | J7: =D22 | K7: =D23 | L7: =D24 | M7: =D25 | N7: =D26 | O7: =D27 | P7: =D28 | Q7: =D29 | R7: =D30 | S7: =D31 | T7: =D32 | U7: =D33 | V7: =D34 | W7: =D35 | X7: =D36 | Y7: =D37 | Z7: =D38 | AA7: =D39
A8: 11 | B8: 财务费用 | C8: =SUM(D8,E8,F8,G8,H8,I8,J8,K8,L8,M8,N8,O8,P8,Q8,R8,S8,T8,U8,V8,W8,X8,Y8,Z8,AA8) | D8: =E16 | E8: =E17 | F8: =E18 | G8: =E19 | H8: =E20 | I8: =E21 | J8: =E22 | K8: =E23 | L8: =E24 | M8: =E25 | N8: =E26 | O8: =E27 | P8: =E28 | Q8: =E29 | R8: =E30 | S8: =E31 | T8: =E32 | U8: =E33 | V8: =E34 | W8: =E35 | X8: =E36 | Y8: =E37 | Z8: =E38 | AA8: =E39
A9: 11.1 | B9: 长期贷款利息 | C9: =SUM(D9,E9,F9,G9,H9,I9,J9,K9,L9,M9,N9,O9,P9,Q9,R9,S9,T9,U9,V9,W9,X9,Y9,Z9,AA9) | D9: =E16 | E9: =E17 | F9: =E18 | G9: =E19 | H9: =E20 | I9: =E21 | J9: =E22 | K9: =E23 | L9: =E24 | M9: =E25 | N9: =E26 | O9: =E27 | P9: =E28 | Q9: =E29 | R9: =E30 | S9: =E31 | T9: =E32 | U9: =E33 | V9: =E34 | W9: =E35 | X9: =E36 | Y9: =E37 | Z9: =E38 | AA9: =E39
A10: 12 | B10: 总成本费用 | C10: =SUM(D10,E10,F10,G10,H10,I10,J10,K10,L10,M10,N10,O10,P10,Q10,R10,S10,T10,U10,V10,W10,X10,Y10,Z10,AA10) | D10: =F16 | E10: =F17 | F10: =F18 | G10: =F19 | H10: =F20 | I10: =F21 | J10: =F22 | K10: =F23 | L10: =F24 | M10: =F25 | N10: =F26 | O10: =F27 | P10: =F28 | Q10: =F29 | R10: =F30 | S10: =F31 | T10: =F32 | U10: =F33 | V10: =F34 | W10: =F35 | X10: =F36 | Y10: =F37 | Z10: =F38 | AA10: =F39
A11: 12.1 | B11: 固定成本 | C11: 0 | D11: 0 | E11: 0 | F11: 0 | G11: 0 | H11: 0 | I11: 0 | J11: 0 | K11: 0 | L11: 0 | M11: 0 | N11: 0 | O11: 0 | P11: 0 | Q11: 0 | R11: 0 | S11: 0 | T11: 0 | U11: 0 | V11: 0 | W11: 0 | X11: 0 | Y11: 0 | Z11: 0 | AA11: 0
A12: 12.2 | B12: 变动成本 | C12: 0 | D12: 0 | E12: 0 | F12: 0 | G12: 0 | H12: 0 | I12: 0 | J12: 0 | K12: 0 | L12: 0 | M12: 0 | N12: 0 | O12: 0 | P12: 0 | Q12: 0 | R12: 0 | S12: 0 | T12: 0 | U12: 0 | V12: 0 | W12: 0 | X12: 0 | Y12: 0 | Z12: 0 | AA12: 0
A14: 引擎逐年计算区（供公式与跨表追溯）
A15: 运营年 | B15: 经营成本 | C15: 折旧费 | D15: 摊销费 | E15: 利息支出 | F15: 总成本费用
A16: 1 | B16: 1473.79 | C16: 2007.67 | D16: 0 | E16: 955.18 | F16: =SUM(B16,C16,D16,E16)
A17: 2 | B17: 1473.79 | C17: 2007.67 | D17: 0 | E17: 891.5 | F17: =SUM(B17,C17,D17,E17)
A18: 3 | B18: 1473.79 | C18: 2007.67 | D18: 0 | E18: 827.82 | F18: =SUM(B18,C18,D18,E18)
A19: 4 | B19: 1473.79 | C19: 2007.67 | D19: 0 | E19: 764.14 | F19: =SUM(B19,C19,D19,E19)
A20: 5 | B20: 1473.79 | C20: 2007.67 | D20: 0 | E20: 700.47 | F20: =SUM(B20,C20,D20,E20)
A21: 6 | B21: 1473.79 | C21: 2007.67 | D21: 0 | E21: 636.79 | F21: =SUM(B21,C21,D21,E21)
A22: 7 | B22: 1473.79 | C22: 2007.67 | D22: 0 | E22: 573.11 | F22: =SUM(B22,C22,D22,E22)
A23: 8 | B23: 1473.79 | C23: 2007.67 | D23: 0 | E23: 509.43 | F23: =SUM(B23,C23,D23,E23)
A24: 9 | B24: 1473.79 | C24: 2007.67 | D24: 0 | E24: 445.75 | F24: =SUM(B24,C24,D24,E24)
A25: 10 | B25: 1473.79 | C25: 2007.67 | D25: 0 | E25: 382.07 | F25: =SUM(B25,C25,D25,E25)
A26: 11 | B26: 1473.79 | C26: 2007.67 | D26: 0 | E26: 318.39 | F26: =SUM(B26,C26,D26,E26)
A27: 12 | B27: 1473.79 | C27: 2007.67 | D27: 0 | E27: 254.71 | F27: =SUM(B27,C27,D27,E27)
... A39: 24 | B39: 1473.79 | C39: 0 | D39: 0 | E39: 0 | F39: =SUM(B39,C39,D39,E39)
A40: 说明1：missing_fields: cost_items 成本明细树（≥3 项；默认总成本率不算 reference）
A41: 说明2：structure_gaps: 行业变体未冻结(variant=flat_estimate, model=flat)；缺参考行组 raw（外购原材料费）；缺参考行组 fuel（外购燃料及动力费/外购燃料和动力费）；缺参考行组 wage（工资及福利费）；缺参考行组 repair（修理费）；缺 cost_items 成本明细树（≥3 项）；固定/变动成本分类未确认（cost_behavior）；名称猜测仅估算，不得升 reference
A42: 跨表依赖复核：附表4 | B42: ='附表4'!C4
A43: 跨表依赖复核：附表5 | B43: ='附表5'!A16
A44: 跨表依赖复核：附表6-1 | B44: ='附表6-1'!A11
A45: 跨表依赖复核：附表6-2 | B45: ='附表6-2'!A8
A46: 跨表依赖复核：附表6-3 | B46: ='附表6-3'!A8
A47: 跨表依赖复核：附表8 | B47: ='附表8'!A24

Sheet 附表6-1
A1: 附表6-1 工资及附加估算表
A2: 匡算预览｜未批准，不得用于正式报批；口径：summary；有效：是
A3: 序号 | B3: 项目 | C3: 单位 | D3: 人数 | E3: 人均年工资 | F3: 合计 | G3: 分年1 | H3: 分年2 | I3: 分年3 | J3: 分年4 | K3: 分年5 | L3: 分年6 | M3: 分年7 | N3: 分年8 | O3: 分年9 | P3: 分年10 | Q3: 分年11 | R3: 分年12 | S3: 分年13 | T3: 分年14 | U3: 分年15 | V3: 分年16 | W3: 分年17 | X3: 分年18 | Y3: 分年19 | Z3: 分年20 | AA3: 分年21 | AB3: 分年22 | AC3: 分年23 | AD3: 分年24
A4: 1 | B4: 劳动定员 | C4: 人 | F4: 0 | G4: 0 | H4: 0 | I4: 0 | J4: 0 | K4: 0 | L4: 0 | M4: 0 | N4: 0 | O4: 0 | P4: 0 | Q4: 0 | R4: 0 | S4: 0 | T4: 0 | U4: 0 | V4: 0 | W4: 0 | X4: 0 | Y4: 0 | Z4: 0 | AA4: 0 | AB4: 0 | AC4: 0 | AD4: 0
A5: 2 | B5: 工资额 | C5: 万元 | F5: =SUM(G5,H5,I5,J5,K5,L5,M5,N5,O5,P5,Q5,R5,S5,T5,U5,V5,W5,X5,Y5,Z5,AA5,AB5,AC5,AD5) | G5: =B11 | H5: =B12 | I5: =B13 | J5: =B14 | K5: =B15 | L5: =B16 | M5: =B17 | N5: =B18 | O5: =B19 | P5: =B20 | Q5: =B21 | R5: =B22 | S5: =B23 | T5: =B24 | U5: =B25 | V5: =B26 | W5: =B27 | X5: =B28 | Y5: =B29 | Z5: =B30 | AA5: =B31 | AB5: =B32 | AC5: =B33 | AD5: =B34
A6: 3 | B6: 福利费 | C6: 万元 | F6: =SUM(G6,H6,I6,J6,K6,L6,M6,N6,O6,P6,Q6,R6,S6,T6,U6,V6,W6,X6,Y6,Z6,AA6,AB6,AC6,AD6) | G6: =C11 | H6: =C12 | I6: =C13 | J6: =C14 | K6: =C15 | L6: =C16 | M6: =C17 | N6: =C18 | O6: =C19 | P6: =C20 | Q6: =C21 | R6: =C22 | S6: =C23 | T6: =C24 | U6: =C25 | V6: =C26 | W6: =C27 | X6: =C28 | Y6: =C29 | Z6: =C30 | AA6: =C31 | AB6: =C32 | AC6: =C33 | AD6: =C34
B7: 合计 | C7: 万元 | F7: =SUM(G7,H7,I7,J7,K7,L7,M7,N7,O7,P7,Q7,R7,S7,T7,U7,V7,W7,X7,Y7,Z7,AA7,AB7,AC7,AD7) | G7: =D11 | H7: =D12 | I7: =D13 | J7: =D14 | K7: =D15 | L7: =D16 | M7: =D17 | N7: =D18 | O7: =D19 | P7: =D20 | Q7: =D21 | R7: =D22 | S7: =D23 | T7: =D24 | U7: =D25 | V7: =D26 | W7: =D27 | X7: =D28 | Y7: =D29 | Z7: =D30 | AA7: =D31 | AB7: =D32 | AC7: =D33 | AD7: =D34
A9: 引擎逐年计算区（供公式与跨表追溯）
A10: 运营年 | B10: 工资 | C10: 职工福利及附加 | D10: 工资及附加合计
A11: 1 | B11: 221.07 | C11: 30.95 | D11: =B11+C11
A12: 2 | B12: 221.07 | C12: 30.95 | D12: =B12+C12
A13: 3 | B13: 221.07 | C13: 30.95 | D13: =B13+C13
A14: 4 | B14: 221.07 | C14: 30.95 | D14: =B14+C14
A15: 5 | B15: 221.07 | C15: 30.95 | D15: =B15+C15
A16: 6 | B16: 221.07 | C16: 30.95 | D16: =B16+C16
A17: 7 | B17: 221.07 | C17: 30.95 | D17: =B17+C17
A18: 8 | B18: 221.07 | C18: 30.95 | D18: =B18+C18
A19: 9 | B19: 221.07 | C19: 30.95 | D19: =B19+C19
A20: 10 | B20: 221.07 | C20: 30.95 | D20: =B20+C20
A21: 11 | B21: 221.07 | C21: 30.95 | D21: =B21+C21
A22: 12 | B22: 221.07 | C22: 30.95 | D22: =B22+C22
... A34: 24 | B34: 221.07 | C34: 30.95 | D34: =B34+C34
A35: 说明1：missing_fields: staff_detail 劳动定员（人数×人均年工资，可多类）
A36: 说明2：structure_gaps: 行业变体未冻结(variant=flat_estimate, model=flat)；工资表缺可复算的人员类别×人数×人均年工资

Sheet 附表6-2
A1: 附表6-2 固定资产折旧费估算表
A2: 匡算预览｜未批准，不得用于正式报批；口径：summary；有效：是
A3: 序号 | B3: 项目 | C3: 合计 | D3: 折旧年限 | E3: 分年1 | F3: 分年2 | G3: 分年3 | H3: 分年4 | I3: 分年5 | J3: 分年6 | K3: 分年7 | L3: 分年8 | M3: 分年9 | N3: 分年10 | O3: 分年11 | P3: 分年12 | Q3: 分年13 | R3: 分年14 | S3: 分年15 | T3: 分年16 | U3: 分年17 | V3: 分年18 | W3: 分年19 | X3: 分年20 | Y3: 分年21 | Z3: 分年22 | AA3: 分年23 | AB3: 分年24
B4: 合计 | C4: =SUM(E4,F4,G4,H4,I4,J4,K4,L4,M4,N4,O4,P4,Q4,R4,S4,T4,U4,V4,W4,X4,Y4,Z4,AA4,AB4) | E4: =E8 | F4: =E9 | G4: =E10 | H4: =E11 | I4: =E12 | J4: =E13 | K4: =E14 | L4: =E15 | M4: =E16 | N4: =E17 | O4: =E18 | P4: =E19 | Q4: =E20 | R4: =E21 | S4: =E22 | T4: =E23 | U4: =E24 | V4: =E25 | W4: =E26 | X4: =E27 | Y4: =E28 | Z4: =E29 | AA4: =E30 | AB4: =E31
A6: 引擎逐年计算区（供公式与跨表追溯）
A7: 运营年 | B7: 固定资产原值 | C7: 残值率 | D7: 折旧年限 | E7: 当期折旧费 | F7: 累计折旧 | G7: 净值
A8: 1 | B8: 42266.75 | C8: 0.05 | D8: 20 | E8: 2007.67 | F8: =E8 | G8: =B8-F8
A9: 2 | B9: 42266.75 | C9: 0.05 | D9: 20 | E9: 2007.67 | F9: =F8+E9 | G9: =B9-F9
A10: 3 | B10: 42266.75 | C10: 0.05 | D10: 20 | E10: 2007.67 | F10: =F9+E10 | G10: =B10-F10
A11: 4 | B11: 42266.75 | C11: 0.05 | D11: 20 | E11: 2007.67 | F11: =F10+E11 | G11: =B11-F11
A12: 5 | B12: 42266.75 | C12: 0.05 | D12: 20 | E12: 2007.67 | F12: =F11+E12 | G12: =B12-F12
A13: 6 | B13: 42266.75 | C13: 0.05 | D13: 20 | E13: 2007.67 | F13: =F12+E13 | G13: =B13-F13
A14: 7 | B14: 42266.75 | C14: 0.05 | D14: 20 | E14: 2007.67 | F14: =F13+E14 | G14: =B14-F14
A15: 8 | B15: 42266.75 | C15: 0.05 | D15: 20 | E15: 2007.67 | F15: =F14+E15 | G15: =B15-F15
A16: 9 | B16: 42266.75 | C16: 0.05 | D16: 20 | E16: 2007.67 | F16: =F15+E16 | G16: =B16-F16
A17: 10 | B17: 42266.75 | C17: 0.05 | D17: 20 | E17: 2007.67 | F17: =F16+E17 | G17: =B17-F17
A18: 11 | B18: 42266.75 | C18: 0.05 | D18: 20 | E18: 2007.67 | F18: =F17+E18 | G18: =B18-F18
A19: 12 | B19: 42266.75 | C19: 0.05 | D19: 20 | E19: 2007.67 | F19: =F18+E19 | G19: =B19-F19
A20: 13 | B20: 42266.75 | C20: 0.05 | D20: 20 | E20: 2007.67 | F20: =F19+E20 | G20: =B20-F20
... A31: 24 | B31: 42266.75 | C31: 0.05 | D31: 20 | E31: 0 | F31: =F30+E31 | G31: =B31-F31
A32: 说明1：missing_fields: asset_classes 资产类别原值与折旧年限（≥2 类）
A33: 说明2：structure_gaps: 行业变体未冻结(variant=flat_estimate, model=flat)；缺参考行组 building（房屋、建筑物/房屋建筑物）；缺参考行组 equipment（机器设备）；缺参考行组 original（原值）；缺参考行组 depreciation（当期折旧费）；缺参考行组 net（净值）；缺资产类别折旧（房屋/设备等），综合原值合计不算 reference；缺累计折旧/净值滚动列；折旧表缺至少 2 类资产的原值×年限明细
A34: 跨表依赖复核：附表1 | B34: ='附表1'!J4

Sheet 附表6-3
A1: 附表6-3 无形资产及其他资产摊销估算表
A2: 匡算预览｜未批准，不得用于正式报批；口径：not_applicable；有效：否
A3: 序号 | B3: 项目 | C3: 合计 | D3: 摊销年限 | E3: 分年1 | F3: 分年2 | G3: 分年3 | H3: 分年4 | I3: 分年5 | J3: 分年6 | K3: 分年7 | L3: 分年8 | M3: 分年9 | N3: 分年10 | O3: 分年11 | P3: 分年12 | Q3: 分年13 | R3: 分年14 | S3: 分年15 | T3: 分年16 | U3: 分年17 | V3: 分年18 | W3: 分年19 | X3: 分年20 | Y3: 分年21 | Z3: 分年22 | AA3: 分年23 | AB3: 分年24
B4: 合计 | C4: =SUM(E4,F4,G4,H4,I4,J4,K4,L4,M4,N4,O4,P4,Q4,R4,S4,T4,U4,V4,W4,X4,Y4,Z4,AA4,AB4) | E4: =D8 | F4: =D9 | G4: =D10 | H4: =D11 | I4: =D12 | J4: =D13 | K4: =D14 | L4: =D15 | M4: =D16 | N4: =D17 | O4: =D18 | P4: =D19 | Q4: =D20 | R4: =D21 | S4: =D22 | T4: =D23 | U4: =D24 | V4: =D25 | W4: =D26 | X4: =D27 | Y4: =D28 | Z4: =D29 | AA4: =D30 | AB4: =D31
A6: 引擎逐年计算区（供公式与跨表追溯）
A7: 运营年 | B7: 摊销基数 | C7: 摊销年限 | D7: 当期摊销费
A8: 1 | B8: 0 | C8: 10 | D8: =IF(A8<=C8,B8/C8,0)
A9: 2 | B9: 0 | C9: 10 | D9: =IF(A9<=C9,B9/C9,0)
A10: 3 | B10: 0 | C10: 10 | D10: =IF(A10<=C10,B10/C10,0)
A11: 4 | B11: 0 | C11: 10 | D11: =IF(A11<=C11,B11/C11,0)
A12: 5 | B12: 0 | C12: 10 | D12: =IF(A12<=C12,B12/C12,0)
A13: 6 | B13: 0 | C13: 10 | D13: =IF(A13<=C13,B13/C13,0)
A14: 7 | B14: 0 | C14: 10 | D14: =IF(A14<=C14,B14/C14,0)
A15: 8 | B15: 0 | C15: 10 | D15: =IF(A15<=C15,B15/C15,0)
A16: 9 | B16: 0 | C16: 10 | D16: =IF(A16<=C16,B16/C16,0)
A17: 10 | B17: 0 | C17: 10 | D17: =IF(A17<=C17,B17/C17,0)
A18: 11 | B18: 0 | C18: 10 | D18: =IF(A18<=C18,B18/C18,0)
A19: 12 | B19: 0 | C19: 10 | D19: =IF(A19<=C19,B19/C19,0)
... A31: 24 | B31: 0 | C31: 10 | D31: =IF(A31<=C31,B31/C31,0)
A32: 跨表依赖复核：附表1 | B32: ='附表1'!J4

Sheet 附表7
A1: 附表7 利润与利润分配表
A2: 匡算预览｜未批准，不得用于正式报批；口径：summary；有效：是
A3: 序号 | B3: 项目 | C3: 合计 | D3: 计算期1 | E3: 计算期2 | F3: 计算期3 | G3: 计算期4 | H3: 计算期5 | I3: 计算期6 | J3: 计算期7 | K3: 计算期8 | L3: 计算期9 | M3: 计算期10 | N3: 计算期11 | O3: 计算期12 | P3: 计算期13 | Q3: 计算期14 | R3: 计算期15 | S3: 计算期16 | T3: 计算期17 | U3: 计算期18 | V3: 计算期19 | W3: 计算期20 | X3: 计算期21 | Y3: 计算期22 | Z3: 计算期23 | AA3: 计算期24
A4: 1 | B4: 营业收入 | C4: =SUM(D4,E4,F4,G4,H4,I4,J4,K4,L4,M4,N4,O4,P4,Q4,R4,S4,T4,U4,V4,W4,X4,Y4,Z4,AA4) | D4: =B24 | E4: =B25 | F4: =B26 | G4: =B27 | H4: =B28 | I4: =B29 | J4: =B30 | K4: =B31 | L4: =B32 | M4: =B33 | N4: =B34 | O4: =B35 | P4: =B36 | Q4: =B37 | R4: =B38 | S4: =B39 | T4: =B40 | U4: =B41 | V4: =B42 | W4: =B43 | X4: =B44 | Y4: =B45 | Z4: =B46 | AA4: =B47
A5: 2 | B5: 营业税金及附加 | C5: =SUM(D5,E5,F5,G5,H5,I5,J5,K5,L5,M5,N5,O5,P5,Q5,R5,S5,T5,U5,V5,W5,X5,Y5,Z5,AA5) | D5: =D24 | E5: =D25 | F5: =D26 | G5: =D27 | H5: =D28 | I5: =D29 | J5: =D30 | K5: =D31 | L5: =D32 | M5: =D33 | N5: =D34 | O5: =D35 | P5: =D36 | Q5: =D37 | R5: =D38 | S5: =D39 | T5: =D40 | U5: =D41 | V5: =D42 | W5: =D43 | X5: =D44 | Y5: =D45 | Z5: =D46 | AA5: =D47
A6: 3 | B6: 总成本费用 | C6: =SUM(D6,E6,F6,G6,H6,I6,J6,K6,L6,M6,N6,O6,P6,Q6,R6,S6,T6,U6,V6,W6,X6,Y6,Z6,AA6) | D6: =C24 | E6: =C25 | F6: =C26 | G6: =C27 | H6: =C28 | I6: =C29 | J6: =C30 | K6: =C31 | L6: =C32 | M6: =C33 | N6: =C34 | O6: =C35 | P6: =C36 | Q6: =C37 | R6: =C38 | S6: =C39 | T6: =C40 | U6: =C41 | V6: =C42 | W6: =C43 | X6: =C44 | Y6: =C45 | Z6: =C46 | AA6: =C47
A7: 4 | B7: 利润总额 | C7: =SUM(D7,E7,F7,G7,H7,I7,J7,K7,L7,M7,N7,O7,P7,Q7,R7,S7,T7,U7,V7,W7,X7,Y7,Z7,AA7) | D7: =E24 | E7: =E25 | F7: =E26 | G7: =E27 | H7: =E28 | I7: =E29 | J7: =E30 | K7: =E31 | L7: =E32 | M7: =E33 | N7: =E34 | O7: =E35 | P7: =E36 | Q7: =E37 | R7: =E38 | S7: =E39 | T7: =E40 | U7: =E41 | V7: =E42 | W7: =E43 | X7: =E44 | Y7: =E45 | Z7: =E46 | AA7: =E47
A8: 5 | B8: 弥补以前年度亏损 | C8: =SUM(D8,E8,F8,G8,H8,I8,J8,K8,L8,M8,N8,O8,P8,Q8,R8,S8,T8,U8,V8,W8,X8,Y8,Z8,AA8) | D8: =H24 | E8: =H25 | F8: =H26 | G8: =H27 | H8: =H28 | I8: =H29 | J8: =H30 | K8: =H31 | L8: =H32 | M8: =H33 | N8: =H34 | O8: =H35 | P8: =H36 | Q8: =H37 | R8: =H38 | S8: =H39 | T8: =H40 | U8: =H41 | V8: =H42 | W8: =H43 | X8: =H44 | Y8: =H45 | Z8: =H46 | AA8: =H47
A9: 6 | B9: 应纳税所得额 | C9: =SUM(D9,E9,F9,G9,H9,I9,J9,K9,L9,M9,N9,O9,P9,Q9,R9,S9,T9,U9,V9,W9,X9,Y9,Z9,AA9) | D9: =I24 | E9: =I25 | F9: =I26 | G9: =I27 | H9: =I28 | I9: =I29 | J9: =I30 | K9: =I31 | L9: =I32 | M9: =I33 | N9: =I34 | O9: =I35 | P9: =I36 | Q9: =I37 | R9: =I38 | S9: =I39 | T9: =I40 | U9: =I41 | V9: =I42 | W9: =I43 | X9: =I44 | Y9: =I45 | Z9: =I46 | AA9: =I47
A10: 7 | B10: 所得税 | C10: =SUM(D10,E10,F10,G10,H10,I10,J10,K10,L10,M10,N10,O10,P10,Q10,R10,S10,T10,U10,V10,W10,X10,Y10,Z10,AA10) | D10: =J24 | E10: =J25 | F10: =J26 | G10: =J27 | H10: =J28 | I10: =J29 | J10: =J30 | K10: =J31 | L10: =J32 | M10: =J33 | N10: =J34 | O10: =J35 | P10: =J36 | Q10: =J37 | R10: =J38 | S10: =J39 | T10: =J40 | U10: =J41 | V10: =J42 | W10: =J43 | X10: =J44 | Y10: =J45 | Z10: =J46 | AA10: =J47
A11: 8 | B11: 净利润 | C11: =SUM(D11,E11,F11,G11,H11,I11,J11,K11,L11,M11,N11,O11,P11,Q11,R11,S11,T11,U11,V11,W11,X11,Y11,Z11,AA11) | D11: =K24 | E11: =K25 | F11: =K26 | G11: =K27 | H11: =K28 | I11: =K29 | J11: =K30 | K11: =K31 | L11: =K32 | M11: =K33 | N11: =K34 | O11: =K35 | P11: =K36 | Q11: =K37 | R11: =K38 | S11: =K39 | T11: =K40 | U11: =K41 | V11: =K42 | W11: =K43 | X11: =K44 | Y11: =K45 | Z11: =K46 | AA11: =K47
A12: 9 | B12: 期初未分配利润 | C12: =SUM(D12,E12,F12,G12,H12,I12,J12,K12,L12,M12,N12,O12,P12,Q12,R12,S12,T12,U12,V12,W12,X12,Y12,Z12,AA12) | D12: =L24 | E12: =L25 | F12: =L26 | G12: =L27 | H12: =L28 | I12: =L29 | J12: =L30 | K12: =L31 | L12: =L32 | M12: =L33 | N12: =L34 | O12: =L35 | P12: =L36 | Q12: =L37 | R12: =L38 | S12: =L39 | T12: =L40 | U12: =L41 | V12: =L42 | W12: =L43 | X12: =L44 | Y12: =L45 | Z12: =L46 | AA12: =L47
A13: 10 | B13: 可供分配的利润 | C13: =SUM(D13,E13,F13,G13,H13,I13,J13,K13,L13,M13,N13,O13,P13,Q13,R13,S13,T13,U13,V13,W13,X13,Y13,Z13,AA13) | D13: =M24 | E13: =M25 | F13: =M26 | G13: =M27 | H13: =M28 | I13: =M29 | J13: =M30 | K13: =M31 | L13: =M32 | M13: =M33 | N13: =M34 | O13: =M35 | P13: =M36 | Q13: =M37 | R13: =M38 | S13: =M39 | T13: =M40 | U13: =M41 | V13: =M42 | W13: =M43 | X13: =M44 | Y13: =M45 | Z13: =M46 | AA13: =M47
A14: 11 | B14: 提取法定盈余公积金 | C14: =SUM(D14,E14,F14,G14,H14,I14,J14,K14,L14,M14,N14,O14,P14,Q14,R14,S14,T14,U14,V14,W14,X14,Y14,Z14,AA14) | D14: =N24 | E14: =N25 | F14: =N26 | G14: =N27 | H14: =N28 | I14: =N29 | J14: =N30 | K14: =N31 | L14: =N32 | M14: =N33 | N14: =N34 | O14: =N35 | P14: =N36 | Q14: =N37 | R14: =N38 | S14: =N39 | T14: =N40 | U14: =N41 | V14: =N42 | W14: =N43 | X14: =N44 | Y14: =N45 | Z14: =N46 | AA14: =N47
A15: 12 | B15: 可供投资者分配的利润 | C15: =SUM(D15,E15,F15,G15,H15,I15,J15,K15,L15,M15,N15,O15,P15,Q15,R15,S15,T15,U15,V15,W15,X15,Y15,Z15,AA15) | D15: =O24 | E15: =O25 | F15: =O26 | G15: =O27 | H15: =O28 | I15: =O29 | J15: =O30 | K15: =O31 | L15: =O32 | M15: =O33 | N15: =O34 | O15: =O35 | P15: =O36 | Q15: =O37 | R15: =O38 | S15: =O39 | T15: =O40 | U15: =O41 | V15: =O42 | W15: =O43 | X15: =O44 | Y15: =O45 | Z15: =O46 | AA15: =O47
A16: 13 | B16: 提取任意盈余公积金 | C16: =SUM(D16,E16,F16,G16,H16,I16,J16,K16,L16,M16,N16,O16,P16,Q16,R16,S16,T16,U16,V16,W16,X16,Y16,Z16,AA16) | D16: =P24 | E16: =P25 | F16: =P26 | G16: =P27 | H16: =P28 | I16: =P29 | J16: =P30 | K16: =P31 | L16: =P32 | M16: =P33 | N16: =P34 | O16: =P35 | P16: =P36 | Q16: =P37 | R16: =P38 | S16: =P39 | T16: =P40 | U16: =P41 | V16: =P42 | W16: =P43 | X16: =P44 | Y16: =P45 | Z16: =P46 | AA16: =P47
A17: 14 | B17: 投资各方利润分配 | C17: =SUM(D17,E17,F17,G17,H17,I17,J17,K17,L17,M17,N17,O17,P17,Q17,R17,S17,T17,U17,V17,W17,X17,Y17,Z17,AA17) | D17: =Q24 | E17: =Q25 | F17: =Q26 | G17: =Q27 | H17: =Q28 | I17: =Q29 | J17: =Q30 | K17: =Q31 | L17: =Q32 | M17: =Q33 | N17: =Q34 | O17: =Q35 | P17: =Q36 | Q17: =Q37 | R17: =Q38 | S17: =Q39 | T17: =Q40 | U17: =Q41 | V17: =Q42 | W17: =Q43 | X17: =Q44 | Y17: =Q45 | Z17: =Q46 | AA17: =Q47
A18: 15 | B18: 未分配利润 | C18: =SUM(D18,E18,F18,G18,H18,I18,J18,K18,L18,M18,N18,O18,P18,Q18,R18,S18,T18,U18,V18,W18,X18,Y18,Z18,AA18) | D18: =R24 | E18: =R25 | F18: =R26 | G18: =R27 | H18: =R28 | I18: =R29 | J18: =R30 | K18: =R31 | L18: =R32 | M18: =R33 | N18: =R34 | O18: =R35 | P18: =R36 | Q18: =R37 | R18: =R38 | S18: =R39 | T18: =R40 | U18: =R41 | V18: =R42 | W18: =R43 | X18: =R44 | Y18: =R45 | Z18: =R46 | AA18: =R47
A19: 16 | B19: 息税前利润（EBIT） | C19: =SUM(D19,E19,F19,G19,H19,I19,J19,K19,L19,M19,N19,O19,P19,Q19,R19,S19,T19,U19,V19,W19,X19,Y19,Z19,AA19) | D19: =F24 | E19: =F25 | F19: =F26 | G19: =F27 | H19: =F28 | I19: =F29 | J19: =F30 | K19: =F31 | L19: =F32 | M19: =F33 | N19: =F34 | O19: =F35 | P19: =F36 | Q19: =F37 | R19: =F38 | S19: =F39 | T19: =F40 | U19: =F41 | V19: =F42 | W19: =F43 | X19: =F44 | Y19: =F45 | Z19: =F46 | AA19: =F47
A20: 17 | B20: 息税折旧摊销前利润（EBITDA） | C20: =SUM(D20,E20,F20,G20,H20,I20,J20,K20,L20,M20,N20,O20,P20,Q20,R20,S20,T20,U20,V20,W20,X20,Y20,Z20,AA20) | D20: =G24 | E20: =G25 | F20: =G26 | G20: =G27 | H20: =G28 | I20: =G29 | J20: =G30 | K20: =G31 | L20: =G32 | M20: =G33 | N20: =G34 | O20: =G35 | P20: =G36 | Q20: =G37 | R20: =G38 | S20: =G39 | T20: =G40 | U20: =G41 | V20: =G42 | W20: =G43 | X20: =G44 | Y20: =G45 | Z20: =G46 | AA20: =G47
A22: 引擎逐年计算区（供公式与跨表追溯）
A23: 运营年 | B23: 营业收入 | C23: 总成本费用 | D23: 税金及附加 | E23: 利润总额 | F23: 息税前利润(EBIT) | G23: 息税折旧摊销前利润(EBITDA) | H23: 弥补以前年度亏损 | I23: 应纳税所得额 | J23: 所得税 | K23: 净利润 | L23: 期初未分配利润 | M23: 可供分配的利润 | N23: 提取法定盈余公积金 | O23: 可供投资者分配的利润 | P23: 提取任意盈余公积金 | Q23: 投资各方利润分配 | R23: 未分配利润
A24: 1 | B24: ='附表5'!B16 | C24: ='附表6'!F16 | D24: ='附表5'!E16 | E24: =B24-C24-D24 | F24: =E24+'附表6'!E16 | G24: =F24+'附表6'!C16+'附表6'!D16 | H24: 0 | I24: =MAX(E24-H24,0) | J24: 0 | K24: =E24-J24 | L24: 0 | M24: =L24+K24 | N24: =MAX(K24,0)*10% | O24: =M24-N24 | R24: =O24-N(P24)-N(Q24)
A25: 2 | B25: ='附表5'!B17 | C25: ='附表6'!F17 | D25: ='附表5'!E17 | E25: =B25-C25-D25 | F25: =E25+'附表6'!E17 | G25: =F25+'附表6'!C17+'附表6'!D17 | H25: 0 | I25: =MAX(E25-H25,0) | J25: 0 | K25: =E25-J25 | L25: =R24 | M25: =L25+K25 | N25: =MAX(K25,0)*10% | O25: =M25-N25 | R25: =O25-N(P25)-N(Q25)
A26: 3 | B26: ='附表5'!B18 | C26: ='附表6'!F18 | D26: ='附表5'!E18 | E26: =B26-C26-D26 | F26: =E26+'附表6'!E18 | G26: =F26+'附表6'!C18+'附表6'!D18 | H26: 0 | I26: =MAX(E26-H26,0) | J26: 0 | K26: =E26-J26 | L26: =R25 | M26: =L26+K26 | N26: =MAX(K26,0)*10% | O26: =M26-N26 | R26: =O26-N(P26)-N(Q26)
A27: 4 | B27: ='附表5'!B19 | C27: ='附表6'!F19 | D27: ='附表5'!E19 | E27: =B27-C27-D27 | F27: =E27+'附表6'!E19 | G27: =F27+'附表6'!C19+'附表6'!D19 | H27: 0 | I27: =MAX(E27-H27,0) | J27: 0 | K27: =E27-J27 | L27: =R26 | M27: =L27+K27 | N27: =MAX(K27,0)*10% | O27: =M27-N27 | R27: =O27-N(P27)-N(Q27)
A28: 5 | B28: ='附表5'!B20 | C28: ='附表6'!F20 | D28: ='附表5'!E20 | E28: =B28-C28-D28 | F28: =E28+'附表6'!E20 | G28: =F28+'附表6'!C20+'附表6'!D20 | H28: 0 | I28: =MAX(E28-H28,0) | J28: 0 | K28: =E28-J28 | L28: =R27 | M28: =L28+K28 | N28: =MAX(K28,0)*10% | O28: =M28-N28 | R28: =O28-N(P28)-N(Q28)
A29: 6 | B29: ='附表5'!B21 | C29: ='附表6'!F21 | D29: ='附表5'!E21 | E29: =B29-C29-D29 | F29: =E29+'附表6'!E21 | G29: =F29+'附表6'!C21+'附表6'!D21 | H29: 0 | I29: =MAX(E29-H29,0) | J29: 7.45 | K29: =E29-J29 | L29: =R28 | M29: =L29+K29 | N29: =MAX(K29,0)*10% | O29: =M29-N29 | R29: =O29-N(P29)-N(Q29)
A30: 7 | B30: ='附表5'!B22 | C30: ='附表6'!F22 | D30: ='附表5'!E22 | E30: =B30-C30-D30 | F30: =E30+'附表6'!E22 | G30: =F30+'附表6'!C22+'附表6'!D22 | H30: 0 | I30: =MAX(E30-H30,0) | J30: 23.36 | K30: =E30-J30 | L30: =R29 | M30: =L30+K30 | N30: =MAX(K30,0)*10% | O30: =M30-N30 | R30: =O30-N(P30)-N(Q30)
A31: 8 | B31: ='附表5'!B23 | C31: ='附表6'!F23 | D31: ='附表5'!E23 | E31: =B31-C31-D31 | F31: =E31+'附表6'!E23 | G31: =F31+'附表6'!C23+'附表6'!D23 | H31: 0 | I31: =MAX(E31-H31,0) | J31: 39.28 | K31: =E31-J31 | L31: =R30 | M31: =L31+K31 | N31: =MAX(K31,0)*10% | O31: =M31-N31 | R31: =O31-N(P31)-N(Q31)
A32: 9 | B32: ='附表5'!B24 | C32: ='附表6'!F24 | D32: ='附表5'!E24 | E32: =B32-C32-D32 | F32: =E32+'附表6'!E24 | G32: =F32+'附表6'!C24+'附表6'!D24 | H32: 0 | I32: =MAX(E32-H32,0) | J32: 55.2 | K32: =E32-J32 | L32: =R31 | M32: =L32+K32 | N32: =MAX(K32,0)*10% | O32: =M32-N32 | R32: =O32-N(P32)-N(Q32)
A33: 10 | B33: ='附表5'!B25 | C33: ='附表6'!F25 | D33: ='附表5'!E25 | E33: =B33-C33-D33 | F33: =E33+'附表6'!E25 | G33: =F33+'附表6'!C25+'附表6'!D25 | H33: 0 | I33: =MAX(E33-H33,0) | J33: 71.12 | K33: =E33-J33 | L33: =R32 | M33: =L33+K33 | N33: =MAX(K33,0)*10% | O33: =M33-N33 | R33: =O33-N(P33)-N(Q33)
A34: 11 | B34: ='附表5'!B26 | C34: ='附表6'!F26 | D34: ='附表5'!E26 | E34: =B34-C34-D34 | F34: =E34+'附表6'!E26 | G34: =F34+'附表6'!C26+'附表6'!D26 | H34: 0 | I34: =MAX(E34-H34,0) | J34: 87.05 | K34: =E34-J34 | L34: =R33 | M34: =L34+K34 | N34: =MAX(K34,0)*10% | O34: =M34-N34 | R34: =O34-N(P34)-N(Q34)
A35: 12 | B35: ='附表5'!B27 | C35: ='附表6'!F27 | D35: ='附表5'!E27 | E35: =B35-C35-D35 | F35: =E35+'附表6'!E27 | G35: =F35+'附表6'!C27+'附表6'!D27 | H35: 0 | I35: =MAX(E35-H35,0) | J35: 102.97 | K35: =E35-J35 | L35: =R34 | M35: =L35+K35 | N35: =MAX(K35,0)*10% | O35: =M35-N35 | R35: =O35-N(P35)-N(Q35)
A36: 13 | B36: ='附表5'!B28 | C36: ='附表6'!F28 | D36: ='附表5'!E28 | E36: =B36-C36-D36 | F36: =E36+'附表6'!E28 | G36: =F36+'附表6'!C28+'附表6'!D28 | H36: 0 | I36: =MAX(E36-H36,0) | J36: 118.88 | K36: =E36-J36 | L36: =R35 | M36: =L36+K36 | N36: =MAX(K36,0)*10% | O36: =M36-N36 | R36: =O36-N(P36)-N(Q36)
... A47: 24 | B47: ='附表5'!B39 | C47: ='附表6'!F39 | D47: ='附表5'!E39 | E47: =B47-C47-D47 | F47: =E47+'附表6'!E39 | G47: =F47+'附表6'!C39+'附表6'!D39 | H47: 0 | I47: =MAX(E47-H47,0) | J47: 668.56 | K47: =E47-J47 | L47: =R46 | M47: =L47+K47 | N47: =MAX(K47,0)*10% | O47: =M47-N47 | R47: =O47-N(P47)-N(Q47)
A48: 说明1：structure_gaps: 行业变体未冻结(variant=flat_estimate, model=flat)
A49: 跨表依赖复核：附表5 | B49: ='附表5'!A16
A50: 跨表依赖复核：附表6 | B50: ='附表6'!A16
A51: 跨表依赖复核：附表6-2 | B51: ='附表6-2'!A8
...

Sheet 附表8
A1: 附表8 还款付息测算表
A2: 匡算预览｜未批准，不得用于正式报批；口径：summary；有效：是
A3: 序号 | B3: 项目 | C3: 合计 | D3: 分年1 | E3: 分年2 | F3: 分年3 | G3: 分年4 | H3: 分年5 | I3: 分年6 | J3: 分年7 | K3: 分年8 | L3: 分年9 | M3: 分年10 | N3: 分年11 | O3: 分年12 | P3: 分年13 | Q3: 分年14 | R3: 分年15 | S3: 分年16 | T3: 分年17 | U3: 分年18 | V3: 分年19 | W3: 分年20 | X3: 分年21 | Y3: 分年22 | Z3: 分年23 | AA3: 分年24
A4: 1 | B4: 期初借款余额 | C4: =AA4 | D4: =B24 | E4: =B25 | F4: =B26 | G4: =B27 | H4: =B28 | I4: =B29 | J4: =B30 | K4: =B31 | L4: =B32 | M4: =B33 | N4: =B34 | O4: =B35 | P4: =B36 | Q4: =B37 | R4: =B38 | S4: =B39 | T4: =B40 | U4: =B41 | V4: =B42 | W4: =B43 | X4: =B44 | Y4: =B45 | Z4: =B46 | AA4: =B47
A5: 2 | B5: 本年借款 | C5: =SUM(D5,E5,F5,G5,H5,I5,J5,K5,L5,M5,N5,O5,P5,Q5,R5,S5,T5,U5,V5,W5,X5,Y5,Z5,AA5) | D5: =C24 | E5: =C25 | F5: =C26 | G5: =C27 | H5: =C28 | I5: =C29 | J5: =C30 | K5: =C31 | L5: =C32 | M5: =C33 | N5: =C34 | O5: =C35 | P5: =C36 | Q5: =C37 | R5: =C38 | S5: =C39 | T5: =C40 | U5: =C41 | V5: =C42 | W5: =C43 | X5: =C44 | Y5: =C45 | Z5: =C46 | AA5: =C47
A6: 3 | B6: 当期还本付息 | C6: =SUM(D6,E6,F6,G6,H6,I6,J6,K6,L6,M6,N6,O6,P6,Q6,R6,S6,T6,U6,V6,W6,X6,Y6,Z6,AA6) | D6: =G24 | E6: =G25 | F6: =G26 | G6: =G27 | H6: =G28 | I6: =G29 | J6: =G30 | K6: =G31 | L6: =G32 | M6: =G33 | N6: =G34 | O6: =G35 | P6: =G36 | Q6: =G37 | R6: =G38 | S6: =G39 | T6: =G40 | U6: =G41 | V6: =G42 | W6: =G43 | X6: =G44 | Y6: =G45 | Z6: =G46 | AA6: =G47
A7: 3.1 | B7: 还本 | C7: =SUM(D7,E7,F7,G7,H7,I7,J7,K7,L7,M7,N7,O7,P7,Q7,R7,S7,T7,U7,V7,W7,X7,Y7,Z7,AA7) | D7: =E24 | E7: =E25 | F7: =E26 | G7: =E27 | H7: =E28 | I7: =E29 | J7: =E30 | K7: =E31 | L7: =E32 | M7: =E33 | N7: =E34 | O7: =E35 | P7: =E36 | Q7: =E37 | R7: =E38 | S7: =E39 | T7: =E40 | U7: =E41 | V7: =E42 | W7: =E43 | X7: =E44 | Y7: =E45 | Z7: =E46 | AA7: =E47
A8: 3.2 | B8: 付息 | C8: =SUM(D8,E8,F8,G8,H8,I8,J8,K8,L8,M8,N8,O8,P8,Q8,R8,S8,T8,U8,V8,W8,X8,Y8,Z8,AA8) | D8: =F24 | E8: =F25 | F8: =F26 | G8: =F27 | H8: =F28 | I8: =F29 | J8: =F30 | K8: =F31 | L8: =F32 | M8: =F33 | N8: =F34 | O8: =F35 | P8: =F36 | Q8: =F37 | R8: =F38 | S8: =F39 | T8: =F40 | U8: =F41 | V8: =F42 | W8: =F43 | X8: =F44 | Y8: =F45 | Z8: =F46 | AA8: =F47
A9: 4 | B9: 期末借款余额 | C9: =AA9 | D9: =H24 | E9: =H25 | F9: =H26 | G9: =H27 | H9: =H28 | I9: =H29 | J9: =H30 | K9: =H31 | L9: =H32 | M9: =H33 | N9: =H34 | O9: =H35 | P9: =H36 | Q9: =H37 | R9: =H38 | S9: =H39 | T9: =H40 | U9: =H41 | V9: =H42 | W9: =H43 | X9: =H44 | Y9: =H45 | Z9: =H46 | AA9: =H47
A10: 5 | B10: 偿债资金来源（可用） | C10: 0 | D10: 0 | E10: 0 | F10: 0 | G10: 0 | H10: 0 | I10: 0 | J10: 0 | K10: 0 | L10: 0 | M10: 0 | N10: 0 | O10: 0 | P10: 0 | Q10: 0 | R10: 0 | S10: 0 | T10: 0 | U10: 0 | V10: 0 | W10: 0 | X10: 0 | Y10: 0 | Z10: 0 | AA10: 0
A11: 5.1 | B11: 可供投资者分配的利润 | C11: =SUM(D11,E11,F11,G11,H11,I11,J11,K11,L11,M11,N11,O11,P11,Q11,R11,S11,T11,U11,V11,W11,X11,Y11,Z11,AA11) | D11: =I24 | E11: =I25 | F11: =I26 | G11: =I27 | H11: =I28 | I11: =I29 | J11: =I30 | K11: =I31 | L11: =I32 | M11: =I33 | N11: =I34 | O11: =I35 | P11: =I36 | Q11: =I37 | R11: =I38 | S11: =I39 | T11: =I40 | U11: =I41 | V11: =I42 | W11: =I43 | X11: =I44 | Y11: =I45 | Z11: =I46 | AA11: =I47
A12: 5.2 | B12: 折旧费 | C12: =SUM(D12,E12,F12,G12,H12,I12,J12,K12,L12,M12,N12,O12,P12,Q12,R12,S12,T12,U12,V12,W12,X12,Y12,Z12,AA12) | D12: =J24 | E12: =J25 | F12: =J26 | G12: =J27 | H12: =J28 | I12: =J29 | J12: =J30 | K12: =J31 | L12: =J32 | M12: =J33 | N12: =J34 | O12: =J35 | P12: =J36 | Q12: =J37 | R12: =J38 | S12: =J39 | T12: =J40 | U12: =J41 | V12: =J42 | W12: =J43 | X12: =J44 | Y12: =J45 | Z12: =J46 | AA12: =J47
A13: 5.3 | B13: 摊销费 | C13: =SUM(D13,E13,F13,G13,H13,I13,J13,K13,L13,M13,N13,O13,P13,Q13,R13,S13,T13,U13,V13,W13,X13,Y13,Z13,AA13) | D13: =K24 | E13: =K25 | F13: =K26 | G13: =K27 | H13: =K28 | I13: =K29 | J13: =K30 | K13: =K31 | L13: =K32 | M13: =K33 | N13: =K34 | O13: =K35 | P13: =K36 | Q13: =K37 | R13: =K38 | S13: =K39 | T13: =K40 | U13: =K41 | V13: =K42 | W13: =K43 | X13: =K44 | Y13: =K45 | Z13: =K46 | AA13: =K47
A14: 6 | B14: 实际用于偿债的资金 | C14: 0 | D14: 0 | E14: 0 | F14: 0 | G14: 0 | H14: 0 | I14: 0 | J14: 0 | K14: 0 | L14: 0 | M14: 0 | N14: 0 | O14: 0 | P14: 0 | Q14: 0 | R14: 0 | S14: 0 | T14: 0 | U14: 0 | V14: 0 | W14: 0 | X14: 0 | Y14: 0 | Z14: 0 | AA14: 0
A15: 6.1 | B15: 实际使用利润 | C15: 0 | D15: 0 | E15: 0 | F15: 0 | G15: 0 | H15: 0 | I15: 0 | J15: 0 | K15: 0 | L15: 0 | M15: 0 | N15: 0 | O15: 0 | P15: 0 | Q15: 0 | R15: 0 | S15: 0 | T15: 0 | U15: 0 | V15: 0 | W15: 0 | X15: 0 | Y15: 0 | Z15: 0 | AA15: 0
A16: 6.2 | B16: 实际使用折旧 | C16: 0 | D16: 0 | E16: 0 | F16: 0 | G16: 0 | H16: 0 | I16: 0 | J16: 0 | K16: 0 | L16: 0 | M16: 0 | N16: 0 | O16: 0 | P16: 0 | Q16: 0 | R16: 0 | S16: 0 | T16: 0 | U16: 0 | V16: 0 | W16: 0 | X16: 0 | Y16: 0 | Z16: 0 | AA16: 0
A17: 6.3 | B17: 实际使用摊销 | C17: 0 | D17: 0 | E17: 0 | F17: 0 | G17: 0 | H17: 0 | I17: 0 | J17: 0 | K17: 0 | L17: 0 | M17: 0 | N17: 0 | O17: 0 | P17: 0 | Q17: 0 | R17: 0 | S17: 0 | T17: 0 | U17: 0 | V17: 0 | W17: 0 | X17: 0 | Y17: 0 | Z17: 0 | AA17: 0
A18: 7 | B18: 偿债后剩余资金 | C18: 0 | D18: 0 | E18: 0 | F18: 0 | G18: 0 | H18: 0 | I18: 0 | J18: 0 | K18: 0 | L18: 0 | M18: 0 | N18: 0 | O18: 0 | P18: 0 | Q18: 0 | R18: 0 | S18: 0 | T18: 0 | U18: 0 | V18: 0 | W18: 0 | X18: 0 | Y18: 0 | Z18: 0 | AA18: 0
A19: 8 | B19: 利息备付率（ICR） | C19: =AA19 | D19: =M24 | E19: =M25 | F19: =M26 | G19: =M27 | H19: =M28 | I19: =M29 | J19: =M30 | K19: =M31 | L19: =M32 | M19: =M33 | N19: =M34 | O19: =M35 | P19: =M36 | Q19: =M37 | R19: =M38 | S19: =M39 | T19: =M40 | U19: =M41 | V19: =M42 | W19: =M43 | X19: =M44 | Y19: =M45 | Z19: =M46 | AA19: =M47
A20: 9 | B20: 偿债备付率（DSCR） | C20: =AA20 | D20: =L24 | E20: =L25 | F20: =L26 | G20: =L27 | H20: =L28 | I20: =L29 | J20: =L30 | K20: =L31 | L20: =L32 | M20: =L33 | N20: =L34 | O20: =L35 | P20: =L36 | Q20: =L37 | R20: =L38 | S20: =L39 | T20: =L40 | U20: =L41 | V20: =L42 | W20: =L43 | X20: =L44 | Y20: =L45 | Z20: =L46 | AA20: =L47
A22: 引擎逐年计算区（供公式与跨表追溯）
A23: 运营年 | B23: 期初借款余额 | C23: 本年借款 | D23: 年利率(%) | E23: 当期还本 | F23: 当期付息 | G23: 当期还本付息 | H23: 期末借款余额 | I23: 偿债资金来源-利润 | J23: 偿债资金来源-折旧费 | K23: 偿债资金来源-摊销费 | L23: 偿债备付率(DSCR) | M23: 利息备付率(ICR)
A24: 1 | B24: 29849.4 | D24: 0.032 | E24: 1989.96 | F24: =B24*D24 | G24: =E24+F24 | H24: =MAX(B24-E24,0) | L24: =IF(G24>0,SUM(I24,J24,K24)/G24,"") | M24: =IF(F24>0,'附表7'!F24/F24,"")
A25: 2 | B25: =H24 | D25: 0.032 | E25: 1989.96 | F25: =B25*D25 | G25: =E25+F25 | H25: =MAX(B25-E25,0) | L25: =IF(G25>0,SUM(I25,J25,K25)/G25,"") | M25: =IF(F25>0,'附表7'!F25/F25,"")
A26: 3 | B26: =H25 | D26: 0.032 | E26: 1989.96 | F26: =B26*D26 | G26: =E26+F26 | H26: =MAX(B26-E26,0) | L26: =IF(G26>0,SUM(I26,J26,K26)/G26,"") | M26: =IF(F26>0,'附表7'!F26/F26,"")
A27: 4 | B27: =H26 | D27: 0.032 | E27: 1989.96 | F27: =B27*D27 | G27: =E27+F27 | H27: =MAX(B27-E27,0) | L27: =IF(G27>0,SUM(I27,J27,K27)/G27,"") | M27: =IF(F27>0,'附表7'!F27/F27,"")
A28: 5 | B28: =H27 | D28: 0.032 | E28: 1989.96 | F28: =B28*D28 | G28: =E28+F28 | H28: =MAX(B28-E28,0) | L28: =IF(G28>0,SUM(I28,J28,K28)/G28,"") | M28: =IF(F28>0,'附表7'!F28/F28,"")
A29: 6 | B29: =H28 | D29: 0.032 | E29: 1989.96 | F29: =B29*D29 | G29: =E29+F29 | H29: =MAX(B29-E29,0) | L29: =IF(G29>0,SUM(I29,J29,K29)/G29,"") | M29: =IF(F29>0,'附表7'!F29/F29,"")
A30: 7 | B30: =H29 | D30: 0.032 | E30: 1989.96 | F30: =B30*D30 | G30: =E30+F30 | H30: =MAX(B30-E30,0) | L30: =IF(G30>0,SUM(I30,J30,K30)/G30,"") | M30: =IF(F30>0,'附表7'!F30/F30,"")
A31: 8 | B31: =H30 | D31: 0.032 | E31: 1989.96 | F31: =B31*D31 | G31: =E31+F31 | H31: =MAX(B31-E31,0) | L31: =IF(G31>0,SUM(I31,J31,K31)/G31,"") | M31: =IF(F31>0,'附表7'!F31/F31,"")
A32: 9 | B32: =H31 | D32: 0.032 | E32: 1989.96 | F32: =B32*D32 | G32: =E32+F32 | H32: =MAX(B32-E32,0) | L32: =IF(G32>0,SUM(I32,J32,K32)/G32,"") | M32: =IF(F32>0,'附表7'!F32/F32,"")
A33: 10 | B33: =H32 | D33: 0.032 | E33: 1989.96 | F33: =B33*D33 | G33: =E33+F33 | H33: =MAX(B33-E33,0) | L33: =IF(G33>0,SUM(I33,J33,K33)/G33,"") | M33: =IF(F33>0,'附表7'!F33/F33,"")
A34: 11 | B34: =H33 | D34: 0.032 | E34: 1989.96 | F34: =B34*D34 | G34: =E34+F34 | H34: =MAX(B34-E34,0) | L34: =IF(G34>0,SUM(I34,J34,K34)/G34,"") | M34: =IF(F34>0,'附表7'!F34/F34,"")
A35: 12 | B35: =H34 | D35: 0.032 | E35: 1989.96 | F35: =B35*D35 | G35: =E35+F35 | H35: =MAX(B35-E35,0) | L35: =IF(G35>0,SUM(I35,J35,K35)/G35,"") | M35: =IF(F35>0,'附表7'!F35/F35,"")
A36: 13 | B36: =H35 | D36: 0.032 | E36: 1989.96 | F36: =B36*D36 | G36: =E36+F36 | H36: =MAX(B36-E36,0) | L36: =IF(G36>0,SUM(I36,J36,K36)/G36,"") | M36: =IF(F36>0,'附表7'!F36/F36,"")
... A47: 24 | B47: =H46 | D47: 0.032 | E47: 0 | F47: =B47*D47 | G47: =E47+F47 | H47: =MAX(B47-E47,0) | L47: =IF(G47>0,SUM(I47,J47,K47)/G47,"") | M47: =IF(F47>0,'附表7'!F47/F47,"")
A48: 说明1：structure_gaps: 偿债资金来源未绑定 confirmed fact_pack/已批准明细；禁止默认 75% 伪造；偿债资金来源的利润/折旧/摊销年度金额不完整；可用偿债资金合计不足以覆盖各年还本付息额；偿债来源父子不勾稽：可用/实际/剩余三组父子恒等式失败
A49: 跨表依赖复核：附表2 | B49: ='附表2'!A14
A50: 跨表依赖复核：附表6 | B50: ='附表6'!A16
A51: 跨表依赖复核：附表7 | B51: ='附表7'!A24

Sheet 附表9
A1: 附表9 项目投资现金流量表
A2: 匡算预览｜未批准，不得用于正式报批；口径：summary；有效：是
A3: 序号 | B3: 项目 | C3: 合计 | D3: 计算期0 | E3: 计算期1 | F3: 计算期2 | G3: 计算期3 | H3: 计算期4 | I3: 计算期5 | J3: 计算期6 | K3: 计算期7 | L3: 计算期8 | M3: 计算期9 | N3: 计算期10 | O3: 计算期11 | P3: 计算期12 | Q3: 计算期13 | R3: 计算期14 | S3: 计算期15 | T3: 计算期16 | U3: 计算期17 | V3: 计算期18 | W3: 计算期19 | X3: 计算期20 | Y3: 计算期21 | Z3: 计算期22 | AA3: 计算期23 | AB3: 计算期24
A4: 1 | B4: 现金流入
A5: 1.1 | B5: 营业收入 | C5: =SUM(D5,E5,F5,G5,H5,I5,J5,K5,L5,M5,N5,O5,P5,Q5,R5,S5,T5,U5,V5,W5,X5,Y5,Z5,AA5,AB5) | D5: =C20 | E5: =C21 | F5: =C22 | G5: =C23 | H5: =C24 | I5: =C25 | J5: =C26 | K5: =C27 | L5: =C28 | M5: =C29 | N5: =C30 | O5: =C31 | P5: =C32 | Q5: =C33 | R5: =C34 | S5: =C35 | T5: =C36 | U5: =C37 | V5: =C38 | W5: =C39 | X5: =C40 | Y5: =C41 | Z5: =C42 | AA5: =C43 | AB5: =C44
A6: 1.2 | B6: 回收固定资产余值 | C6: 2113.34 | D6: 0 | E6: 0 | F6: 0 | G6: 0 | H6: 0 | I6: 0 | J6: 0 | K6: 0 | L6: 0 | M6: 0 | N6: 0 | O6: 0 | P6: 0 | Q6: 0 | R6: 0 | S6: 0 | T6: 0 | U6: 0 | V6: 0 | W6: 0 | X6: 0 | Y6: 0 | Z6: 0 | AA6: 0 | AB6: 2113.34
A7: 1.3 | B7: 回收新增流动资金 | C7: 0 | D7: 0 | E7: 0 | F7: 0 | G7: 0 | H7: 0 | I7: 0 | J7: 0 | K7: 0 | L7: 0 | M7: 0 | N7: 0 | O7: 0 | P7: 0 | Q7: 0 | R7: 0 | S7: 0 | T7: 0 | U7: 0 | V7: 0 | W7: 0 | X7: 0 | Y7: 0 | Z7: 0 | AA7: 0 | AB7: 0
A8: 2 | B8: 现金流出
A9: 2.1 | B9: 固定资产投资 | C9: =SUM(D9,E9,F9,G9,H9,I9,J9,K9,L9,M9,N9,O9,P9,Q9,R9,S9,T9,U9,V9,W9,X9,Y9,Z9,AA9,AB9) | D9: =G20 | E9: =G21 | F9: =G22 | G9: =G23 | H9: =G24 | I9: =G25 | J9: =G26 | K9: =G27 | L9: =G28 | M9: =G29 | N9: =G30 | O9: =G31 | P9: =G32 | Q9: =G33 | R9: =G34 | S9: =G35 | T9: =G36 | U9: =G37 | V9: =G38 | W9: =G39 | X9: =G40 | Y9: =G41 | Z9: =G42 | AA9: =G43 | AB9: =G44
A10: 2.2 | B10: 新增铺底流动资金 | C10: =SUM(D10,E10,F10,G10,H10,I10,J10,K10,L10,M10,N10,O10,P10,Q10,R10,S10,T10,U10,V10,W10,X10,Y10,Z10,AA10,AB10) | D10: =H20 | E10: =H21 | F10: =H22 | G10: =H23 | H10: =H24 | I10: =H25 | J10: =H26 | K10: =H27 | L10: =H28 | M10: =H29 | N10: =H30 | O10: =H31 | P10: =H32 | Q10: =H33 | R10: =H34 | S10: =H35 | T10: =H36 | U10: =H37 | V10: =H38 | W10: =H39 | X10: =H40 | Y10: =H41 | Z10: =H42 | AA10: =H43 | AB10: =H44
A11: 2.3 | B11: 经营成本 | C11: =SUM(D11,E11,F11,G11,H11,I11,J11,K11,L11,M11,N11,O11,P11,Q11,R11,S11,T11,U11,V11,W11,X11,Y11,Z11,AA11,AB11) | D11: =D20 | E11: =D21 | F11: =D22 | G11: =D23 | H11: =D24 | I11: =D25 | J11: =D26 | K11: =D27 | L11: =D28 | M11: =D29 | N11: =D30 | O11: =D31 | P11: =D32 | Q11: =D33 | R11: =D34 | S11: =D35 | T11: =D36 | U11: =D37 | V11: =D38 | W11: =D39 | X11: =D40 | Y11: =D41 | Z11: =D42 | AA11: =D43 | AB11: =D44
A12: 2.4 | B12: 营业税金及附加 | C12: =SUM(D12,E12,F12,G12,H12,I12,J12,K12,L12,M12,N12,O12,P12,Q12,R12,S12,T12,U12,V12,W12,X12,Y12,Z12,AA12,AB12) | D12: =E20 | E12: =E21 | F12: =E22 | G12: =E23 | H12: =E24 | I12: =E25 | J12: =E26 | K12: =E27 | L12: =E28 | M12: =E29 | N12: =E30 | O12: =E31 | P12: =E32 | Q12: =E33 | R12: =E34 | S12: =E35 | T12: =E36 | U12: =E37 | V12: =E38 | W12: =E39 | X12: =E40 | Y12: =E41 | Z12: =E42 | AA12: =E43 | AB12: =E44
A13: 2.5 | B13: 所得税 | C13: =SUM(D13,E13,F13,G13,H13,I13,J13,K13,L13,M13,N13,O13,P13,Q13,R13,S13,T13,U13,V13,W13,X13,Y13,Z13,AA13,AB13) | D13: =F20 | E13: =F21 | F13: =F22 | G13: =F23 | H13: =F24 | I13: =F25 | J13: =F26 | K13: =F27 | L13: =F28 | M13: =F29 | N13: =F30 | O13: =F31 | P13: =F32 | Q13: =F33 | R13: =F34 | S13: =F35 | T13: =F36 | U13: =F37 | V13: =F38 | W13: =F39 | X13: =F40 | Y13: =F41 | Z13: =F42 | AA13: =F43 | AB13: =F44
A14: 3 | B14: 所得税前净现金流量 | C14: 24028.35 | D14: -42266.75 | E14: 2674.24 | F14: 2674.24 | G14: 2674.24 | H14: 2674.24 | I14: 2674.24 | J14: 2674.24 | K14: 2674.24 | L14: 2674.24 | M14: 2674.24 | N14: 2674.24 | O14: 2674.24 | P14: 2674.24 | Q14: 2674.24 | R14: 2674.24 | S14: 2674.24 | T14: 2674.24 | U14: 2674.24 | V14: 2674.24 | W14: 2674.24 | X14: 2674.24 | Y14: 2674.24 | Z14: 2674.24 | AA14: 2674.24 | AB14: 4787.58
A15: 4 | B15: 所得税后净现金流量 | C15: =SUM(D15,E15,F15,G15,H15,I15,J15,K15,L15,M15,N15,O15,P15,Q15,R15,S15,T15,U15,V15,W15,X15,Y15,Z15,AA15,AB15) | D15: =J20 | E15: =J21 | F15: =J22 | G15: =J23 | H15: =J24 | I15: =J25 | J15: =J26 | K15: =J27 | L15: =J28 | M15: =J29 | N15: =J30 | O15: =J31 | P15: =J32 | Q15: =J33 | R15: =J34 | S15: =J35 | T15: =J36 | U15: =J37 | V15: =J38 | W15: =J39 | X15: =J40 | Y15: =J41 | Z15: =J42 | AA15: =J43 | AB15: =J44
A16: 5 | B16: 累计所得税后净现金流量 | C16: =AB16 | D16: =K20 | E16: =K21 | F16: =K22 | G16: =K23 | H16: =K24 | I16: =K25 | J16: =K26 | K16: =K27 | L16: =K28 | M16: =K29 | N16: =K30 | O16: =K31 | P16: =K32 | Q16: =K33 | R16: =K34 | S16: =K35 | T16: =K36 | U16: =K37 | V16: =K38 | W16: =K39 | X16: =K40 | Y16: =K41 | Z16: =K42 | AA16: =K43 | AB16: =K44
A18: 引擎逐年计算区（供公式与跨表追溯）
A19: 计算期(年) | B19: 阶段 | C19: 营业收入 | D19: 经营成本 | E19: 税金及附加 | F19: 调整所得税 | G19: 建设投资(含建设期利息) | H19: 流动资金增加 | I19: 回收(流资+余值) | J19: 净现金流 | K19: 累计净现金流
A20: 0 | B20: 建设期 | C20: 0 | D20: 0 | E20: 0 | F20: 0 | G20: =SUM('附表1'!J4,'附表1'!J8,'附表1'!J9)*1 | H20: 0 | I20: 0 | J20: -42266.75 | K20: -42266.75
A21: 1 | B21: 运营期 | C21: ='附表5'!B16 | D21: ='附表6'!B16 | E21: ='附表5'!E16 | F21: ='附表5'!I16 | G21: 0 | H21: ='附表3'!B4 | I21: 0 | J21: =C21-D21-E21-F21-G21-H21+I21 | K21: =K20+J21
A22: 2 | B22: 运营期 | C22: ='附表5'!B17 | D22: ='附表6'!B17 | E22: ='附表5'!E17 | F22: ='附表5'!I17 | G22: 0 | H22: 0 | I22: 0 | J22: =C22-D22-E22-F22-G22-H22+I22 | K22: =K21+J22
A23: 3 | B23: 运营期 | C23: ='附表5'!B18 | D23: ='附表6'!B18 | E23: ='附表5'!E18 | F23: ='附表5'!I18 | G23: 0 | H23: 0 | I23: 0 | J23: =C23-D23-E23-F23-G23-H23+I23 | K23: =K22+J23
A24: 4 | B24: 运营期 | C24: ='附表5'!B19 | D24: ='附表6'!B19 | E24: ='附表5'!E19 | F24: ='附表5'!I19 | G24: 0 | H24: 0 | I24: 0 | J24: =C24-D24-E24-F24-G24-H24+I24 | K24: =K23+J24
A25: 5 | B25: 运营期 | C25: ='附表5'!B20 | D25: ='附表6'!B20 | E25: ='附表5'!E20 | F25: ='附表5'!I20 | G25: 0 | H25: 0 | I25: 0 | J25: =C25-D25-E25-F25-G25-H25+I25 | K25: =K24+J25
A26: 6 | B26: 运营期 | C26: ='附表5'!B21 | D26: ='附表6'!B21 | E26: ='附表5'!E21 | F26: ='附表5'!I21 | G26: 0 | H26: 0 | I26: 0 | J26: =C26-D26-E26-F26-G26-H26+I26 | K26: =K25+J26
A27: 7 | B27: 运营期 | C27: ='附表5'!B22 | D27: ='附表6'!B22 | E27: ='附表5'!E22 | F27: ='附表5'!I22 | G27: 0 | H27: 0 | I27: 0 | J27: =C27-D27-E27-F27-G27-H27+I27 | K27: =K26+J27
A28: 8 | B28: 运营期 | C28: ='附表5'!B23 | D28: ='附表6'!B23 | E28: ='附表5'!E23 | F28: ='附表5'!I23 | G28: 0 | H28: 0 | I28: 0 | J28: =C28-D28-E28-F28-G28-H28+I28 | K28: =K27+J28
A29: 9 | B29: 运营期 | C29: ='附表5'!B24 | D29: ='附表6'!B24 | E29: ='附表5'!E24 | F29: ='附表5'!I24 | G29: 0 | H29: 0 | I29: 0 | J29: =C29-D29-E29-F29-G29-H29+I29 | K29: =K28+J29
A30: 10 | B30: 运营期 | C30: ='附表5'!B25 | D30: ='附表6'!B25 | E30: ='附表5'!E25 | F30: ='附表5'!I25 | G30: 0 | H30: 0 | I30: 0 | J30: =C30-D30-E30-F30-G30-H30+I30 | K30: =K29+J30
A31: 11 | B31: 运营期 | C31: ='附表5'!B26 | D31: ='附表6'!B26 | E31: ='附表5'!E26 | F31: ='附表5'!I26 | G31: 0 | H31: 0 | I31: 0 | J31: =C31-D31-E31-F31-G31-H31+I31 | K31: =K30+J31
A32: 12 | B32: 运营期 | C32: ='附表5'!B27 | D32: ='附表6'!B27 | E32: ='附表5'!E27 | F32: ='附表5'!I27 | G32: 0 | H32: 0 | I32: 0 | J32: =C32-D32-E32-F32-G32-H32+I32 | K32: =K31+J32
A33: 13 | B33: 运营期 | C33: ='附表5'!B28 | D33: ='附表6'!B28 | E33: ='附表5'!E28 | F33: ='附表5'!I28 | G33: 0 | H33: 0 | I33: 0 | J33: =C33-D33-E33-F33-G33-H33+I33 | K33: =K32+J33
... A44: 24 | B44: 运营期 | C44: ='附表5'!B39 | D44: ='附表6'!B39 | E44: ='附表5'!E39 | F44: ='附表5'!I39 | G44: 0 | H44: 0 | I44: 2113.34 | J44: =C44-D44-E44-F44-G44-H44+I44 | K44: =K43+J44
A45: 说明1：建设投资列含建设期利息（与项目 CF 同源）
A46: 说明2：structure_gaps: 行业变体未冻结(variant=flat_estimate, model=flat)
A48: 现金流量组成树
A49: 项目 | B49: 0 | C49: 1 | D49: 2 | E49: 3 | F49: 4 | G49: 5 | H49: 6 | I49: 7 | J49: 8 | K49: 9 | L49: 10 | M49: 11 | N49: 12 | O49: 13 | P49: 14 | Q49: 15 | R49: 16 | S49: 17 | T49: 18 | U49: 19 | V49: 20 | W49: 21 | X49: 22 | Y49: 23 | Z49: 24
A50: 现金流入
A51: revenue | B51: ='附表9'!C20 | C51: ='附表9'!C21 | D51: ='附表9'!C22 | E51: ='附表9'!C23 | F51: ='附表9'!C24 | G51: ='附表9'!C25 | H51: ='附表9'!C26 | I51: ='附表9'!C27 | J51: ='附表9'!C28 | K51: ='附表9'!C29 | L51: ='附表9'!C30 | M51: ='附表9'!C31 | N51: ='附表9'!C32 | O51: ='附表9'!C33 | P51: ='附表9'!C34 | Q51: ='附表9'!C35 | R51: ='附表9'!C36 | S51: ='附表9'!C37 | T51: ='附表9'!C38 | U51: ='附表9'!C39 | V51: ='附表9'!C40 | W51: ='附表9'!C41 | X51: ='附表9'!C42 | Y51: ='附表9'!C43 | Z51: ='附表9'!C44
A52: recover | B52: ='附表9'!I20 | C52: ='附表9'!I21 | D52: ='附表9'!I22 | E52: ='附表9'!I23 | F52: ='附表9'!I24 | G52: ='附表9'!I25 | H52: ='附表9'!I26 | I52: ='附表9'!I27 | J52: ='附表9'!I28 | K52: ='附表9'!I29 | L52: ='附表9'!I30 | M52: ='附表9'!I31 | N52: ='附表9'!I32 | O52: ='附表9'!I33 | P52: ='附表9'!I34 | Q52: ='附表9'!I35 | R52: ='附表9'!I36 | S52: ='附表9'!I37 | T52: ='附表9'!I38 | U52: ='附表9'!I39 | V52: ='附表9'!I40 | W52: ='附表9'!I41 | X52: ='附表9'!I42 | Y52: ='附表9'!I43 | Z52: ='附表9'!I44
...

Sheet 附表10
A1: 附表10 项目资本金流量表
A2: 匡算预览｜未批准，不得用于正式报批；口径：summary；有效：是
A3: 序号 | B3: 项目 | C3: 合计 | D3: 计算期0 | E3: 计算期1 | F3: 计算期2 | G3: 计算期3 | H3: 计算期4 | I3: 计算期5 | J3: 计算期6 | K3: 计算期7 | L3: 计算期8 | M3: 计算期9 | N3: 计算期10 | O3: 计算期11 | P3: 计算期12 | Q3: 计算期13 | R3: 计算期14 | S3: 计算期15 | T3: 计算期16 | U3: 计算期17 | V3: 计算期18 | W3: 计算期19 | X3: 计算期20 | Y3: 计算期21 | Z3: 计算期22 | AA3: 计算期23 | AB3: 计算期24
A4: 1 | B4: 现金流入 | C4: =SUM(D4,E4,F4,G4,H4,I4,J4,K4,L4,M4,N4,O4,P4,Q4,R4,S4,T4,U4,V4,W4,X4,Y4,Z4,AA4,AB4) | D4: =J20 | E4: =J21 | F4: =J22 | G4: =J23 | H4: =J24 | I4: =J25 | J4: =J26 | K4: =J27 | L4: =J28 | M4: =J29 | N4: =J30 | O4: =J31 | P4: =J32 | Q4: =J33 | R4: =J34 | S4: =J35 | T4: =J36 | U4: =J37 | V4: =J38 | W4: =J39 | X4: =J40 | Y4: =J41 | Z4: =J42 | AA4: =J43 | AB4: =J44
A5: 1.1 | B5: 营业收入 | C5: =SUM(D5,E5,F5,G5,H5,I5,J5,K5,L5,M5,N5,O5,P5,Q5,R5,S5,T5,U5,V5,W5,X5,Y5,Z5,AA5,AB5) | D5: =D20 | E5: =D21 | F5: =D22 | G5: =D23 | H5: =D24 | I5: =D25 | J5: =D26 | K5: =D27 | L5: =D28 | M5: =D29 | N5: =D30 | O5: =D31 | P5: =D32 | Q5: =D33 | R5: =D34 | S5: =D35 | T5: =D36 | U5: =D37 | V5: =D38 | W5: =D39 | X5: =D40 | Y5: =D41 | Z5: =D42 | AA5: =D43 | AB5: =D44
A6: 1.2 | B6: 回收固定资产余值 | C6: =SUM(D6,E6,F6,G6,H6,I6,J6,K6,L6,M6,N6,O6,P6,Q6,R6,S6,T6,U6,V6,W6,X6,Y6,Z6,AA6,AB6) | D6: =E20 | E6: =E21 | F6: =E22 | G6: =E23 | H6: =E24 | I6: =E25 | J6: =E26 | K6: =E27 | L6: =E28 | M6: =E29 | N6: =E30 | O6: =E31 | P6: =E32 | Q6: =E33 | R6: =E34 | S6: =E35 | T6: =E36 | U6: =E37 | V6: =E38 | W6: =E39 | X6: =E40 | Y6: =E41 | Z6: =E42 | AA6: =E43 | AB6: =E44
A7: 1.3 | B7: 回收流动资金 | C7: =SUM(D7,E7,F7,G7,H7,I7,J7,K7,L7,M7,N7,O7,P7,Q7,R7,S7,T7,U7,V7,W7,X7,Y7,Z7,AA7,AB7) | D7: =F20 | E7: =F21 | F7: =F22 | G7: =F23 | H7: =F24 | I7: =F25 | J7: =F26 | K7: =F27 | L7: =F28 | M7: =F29 | N7: =F30 | O7: =F31 | P7: =F32 | Q7: =F33 | R7: =F34 | S7: =F35 | T7: =F36 | U7: =F37 | V7: =F38 | W7: =F39 | X7: =F40 | Y7: =F41 | Z7: =F42 | AA7: =F43 | AB7: =F44
A8: 2 | B8: 现金流出 | C8: =SUM(D8,E8,F8,G8,H8,I8,J8,K8,L8,M8,N8,O8,P8,Q8,R8,S8,T8,U8,V8,W8,X8,Y8,Z8,AA8,AB8) | D8: =K20 | E8: =K21 | F8: =K22 | G8: =K23 | H8: =K24 | I8: =K25 | J8: =K26 | K8: =K27 | L8: =K28 | M8: =K29 | N8: =K30 | O8: =K31 | P8: =K32 | Q8: =K33 | R8: =K34 | S8: =K35 | T8: =K36 | U8: =K37 | V8: =K38 | W8: =K39 | X8: =K40 | Y8: =K41 | Z8: =K42 | AA8: =K43 | AB8: =K44
A9: 2.1 | B9: 项目资本金 | C9: =SUM(D9,E9,F9,G9,H9,I9,J9,K9,L9,M9,N9,O9,P9,Q9,R9,S9,T9,U9,V9,W9,X9,Y9,Z9,AA9,AB9) | D9: =C20 | E9: =C21 | F9: =C22 | G9: =C23 | H9: =C24 | I9: =C25 | J9: =C26 | K9: =C27 | L9: =C28 | M9: =C29 | N9: =C30 | O9: =C31 | P9: =C32 | Q9: =C33 | R9: =C34 | S9: =C35 | T9: =C36 | U9: =C37 | V9: =C38 | W9: =C39 | X9: =C40 | Y9: =C41 | Z9: =C42 | AA9: =C43 | AB9: =C44
A10: 2.2 | B10: 借款本金偿还 | C10: =SUM(D10,E10,F10,G10,H10,I10,J10,K10,L10,M10,N10,O10,P10,Q10,R10,S10,T10,U10,V10,W10,X10,Y10,Z10,AA10,AB10) | D10: =M20 | E10: =M21 | F10: =M22 | G10: =M23 | H10: =M24 | I10: =M25 | J10: =M26 | K10: =M27 | L10: =M28 | M10: =M29 | N10: =M30 | O10: =M31 | P10: =M32 | Q10: =M33 | R10: =M34 | S10: =M35 | T10: =M36 | U10: =M37 | V10: =M38 | W10: =M39 | X10: =M40 | Y10: =M41 | Z10: =M42 | AA10: =M43 | AB10: =M44
A11: 2.3 | B11: 借款利息支付 | C11: =SUM(D11,E11,F11,G11,H11,I11,J11,K11,L11,M11,N11,O11,P11,Q11,R11,S11,T11,U11,V11,W11,X11,Y11,Z11,AA11,AB11) | D11: =N20 | E11: =N21 | F11: =N22 | G11: =N23 | H11: =N24 | I11: =N25 | J11: =N26 | K11: =N27 | L11: =N28 | M11: =N29 | N11: =N30 | O11: =N31 | P11: =N32 | Q11: =N33 | R11: =N34 | S11: =N35 | T11: =N36 | U11: =N37 | V11: =N38 | W11: =N39 | X11: =N40 | Y11: =N41 | Z11: =N42 | AA11: =N43 | AB11: =N44
A12: 2.4 | B12: 经营成本 | C12: =SUM(D12,E12,F12,G12,H12,I12,J12,K12,L12,M12,N12,O12,P12,Q12,R12,S12,T12,U12,V12,W12,X12,Y12,Z12,AA12,AB12) | D12: =G20 | E12: =G21 | F12: =G22 | G12: =G23 | H12: =G24 | I12: =G25 | J12: =G26 | K12: =G27 | L12: =G28 | M12: =G29 | N12: =G30 | O12: =G31 | P12: =G32 | Q12: =G33 | R12: =G34 | S12: =G35 | T12: =G36 | U12: =G37 | V12: =G38 | W12: =G39 | X12: =G40 | Y12: =G41 | Z12: =G42 | AA12: =G43 | AB12: =G44
A13: 2.5 | B13: 税金及附加 | C13: =SUM(D13,E13,F13,G13,H13,I13,J13,K13,L13,M13,N13,O13,P13,Q13,R13,S13,T13,U13,V13,W13,X13,Y13,Z13,AA13,AB13) | D13: =H20 | E13: =H21 | F13: =H22 | G13: =H23 | H13: =H24 | I13: =H25 | J13: =H26 | K13: =H27 | L13: =H28 | M13: =H29 | N13: =H30 | O13: =H31 | P13: =H32 | Q13: =H33 | R13: =H34 | S13: =H35 | T13: =H36 | U13: =H37 | V13: =H38 | W13: =H39 | X13: =H40 | Y13: =H41 | Z13: =H42 | AA13: =H43 | AB13: =H44
A14: 2.6 | B14: 所得税 | C14: =SUM(D14,E14,F14,G14,H14,I14,J14,K14,L14,M14,N14,O14,P14,Q14,R14,S14,T14,U14,V14,W14,X14,Y14,Z14,AA14,AB14) | D14: =I20 | E14: =I21 | F14: =I22 | G14: =I23 | H14: =I24 | I14: =I25 | J14: =I26 | K14: =I27 | L14: =I28 | M14: =I29 | N14: =I30 | O14: =I31 | P14: =I32 | Q14: =I33 | R14: =I34 | S14: =I35 | T14: =I36 | U14: =I37 | V14: =I38 | W14: =I39 | X14: =I40 | Y14: =I41 | Z14: =I42 | AA14: =I43 | AB14: =I44
A15: 3 | B15: 资本金净现金流量 | C15: =SUM(D15,E15,F15,G15,H15,I15,J15,K15,L15,M15,N15,O15,P15,Q15,R15,S15,T15,U15,V15,W15,X15,Y15,Z15,AA15,AB15) | D15: =O20 | E15: =O21 | F15: =O22 | G15: =O23 | H15: =O24 | I15: =O25 | J15: =O26 | K15: =O27 | L15: =O28 | M15: =O29 | N15: =O30 | O15: =O31 | P15: =O32 | Q15: =O33 | R15: =O34 | S15: =O35 | T15: =O36 | U15: =O37 | V15: =O38 | W15: =O39 | X15: =O40 | Y15: =O41 | Z15: =O42 | AA15: =O43 | AB15: =O44
A16: 4 | B16: 累计净现金流量 | C16: 10379.95 | D16: -12417.35 | E16: -12938.54 | F16: -13396.05 | G16: -13789.88 | H16: -14120.03 | I16: -14386.51 | J16: -14589.31 | K16: -14728.43 | L16: -14803.87 | M16: -14815.63 | N16: -14763.71 | O16: -14648.11 | P16: -14468.83 | Q16: -14225.88 | R16: -13919.25 | S16: -13548.94 | T16: -11124.99 | U16: -8701.04 | V16: -6277.09 | W16: -3853.14 | X16: -1429.19 | Y16: 994.76 | Z16: 3418.71 | AA16: 5842.66 | AB16: 10379.95
A18: 引擎逐年计算区（供公式与跨表追溯）
A19: 计算期(年) | B19: 阶段 | C19: 资本金投入 | D19: 营业收入 | E19: 回收固定资产余值 | F19: 回收流动资金 | G19: 经营成本 | H19: 税金及附加 | I19: 所得税 | J19: 现金流入 | K19: 现金流出 | L19: 经营现金流入 | M19: 还本 | N19: 付息 | O19: 资本金净现金流
A20: 0 | B20: 建设期 | C20: 12417.35 | D20: 0 | E20: 0 | F20: 0 | G20: 0 | H20: 0 | I20: 0 | J20: =SUM(D20,E20,F20) | K20: =SUM(C20,G20,H20,I20,M20,N20) | L20: 0 | M20: 0 | N20: 0 | O20: =J20-K20
A21: 1 | B21: 运营期 | C21: 0 | D21: 4195.8 | E21: 0 | F21: 0 | G21: 1473.79 | H21: 47.77 | I21: 250.29 | J21: =SUM(D21,E21,F21) | K21: =SUM(C21,G21,H21,I21,M21,N21) | L21: 2423.95 | M21: ='附表8'!E24 | N21: ='附表8'!F24 | O21: =J21-K21
A22: 2 | B22: 运营期 | C22: 0 | D22: 4195.8 | E22: 0 | F22: 0 | G22: 1473.79 | H22: 47.77 | I22: 250.29 | J22: =SUM(D22,E22,F22) | K22: =SUM(C22,G22,H22,I22,M22,N22) | L22: 2423.95 | M22: ='附表8'!E25 | N22: ='附表8'!F25 | O22: =J22-K22
A23: 3 | B23: 运营期 | C23: 0 | D23: 4195.8 | E23: 0 | F23: 0 | G23: 1473.79 | H23: 47.77 | I23: 250.29 | J23: =SUM(D23,E23,F23) | K23: =SUM(C23,G23,H23,I23,M23,N23) | L23: 2423.95 | M23: ='附表8'!E26 | N23: ='附表8'!F26 | O23: =J23-K23
A24: 4 | B24: 运营期 | C24: 0 | D24: 4195.8 | E24: 0 | F24: 0 | G24: 1473.79 | H24: 47.77 | I24: 250.29 | J24: =SUM(D24,E24,F24) | K24: =SUM(C24,G24,H24,I24,M24,N24) | L24: 2423.95 | M24: ='附表8'!E27 | N24: ='附表8'!F27 | O24: =J24-K24
A25: 5 | B25: 运营期 | C25: 0 | D25: 4195.8 | E25: 0 | F25: 0 | G25: 1473.79 | H25: 47.77 | I25: 250.29 | J25: =SUM(D25,E25,F25) | K25: =SUM(C25,G25,H25,I25,M25,N25) | L25: 2423.95 | M25: ='附表8'!E28 | N25: ='附表8'!F28 | O25: =J25-K25
A26: 6 | B26: 运营期 | C26: 0 | D26: 4195.8 | E26: 0 | F26: 0 | G26: 1473.79 | H26: 47.77 | I26: 250.29 | J26: =SUM(D26,E26,F26) | K26: =SUM(C26,G26,H26,I26,M26,N26) | L26: 2423.95 | M26: ='附表8'!E29 | N26: ='附表8'!F29 | O26: =J26-K26
A27: 7 | B27: 运营期 | C27: 0 | D27: 4195.8 | E27: 0 | F27: 0 | G27: 1473.79 | H27: 47.77 | I27: 250.29 | J27: =SUM(D27,E27,F27) | K27: =SUM(C27,G27,H27,I27,M27,N27) | L27: 2423.95 | M27: ='附表8'!E30 | N27: ='附表8'!F30 | O27: =J27-K27
A28: 8 | B28: 运营期 | C28: 0 | D28: 4195.8 | E28: 0 | F28: 0 | G28: 1473.79 | H28: 47.77 | I28: 250.29 | J28: =SUM(D28,E28,F28) | K28: =SUM(C28,G28,H28,I28,M28,N28) | L28: 2423.95 | M28: ='附表8'!E31 | N28: ='附表8'!F31 | O28: =J28-K28
A29: 9 | B29: 运营期 | C29: 0 | D29: 4195.8 | E29: 0 | F29: 0 | G29: 1473.79 | H29: 47.77 | I29: 250.29 | J29: =SUM(D29,E29,F29) | K29: =SUM(C29,G29,H29,I29,M29,N29) | L29: 2423.95 | M29: ='附表8'!E32 | N29: ='附表8'!F32 | O29: =J29-K29
A30: 10 | B30: 运营期 | C30: 0 | D30: 4195.8 | E30: 0 | F30: 0 | G30: 1473.79 | H30: 47.77 | I30: 250.29 | J30: =SUM(D30,E30,F30) | K30: =SUM(C30,G30,H30,I30,M30,N30) | L30: 2423.95 | M30: ='附表8'!E33 | N30: ='附表8'!F33 | O30: =J30-K30
A31: 11 | B31: 运营期 | C31: 0 | D31: 4195.8 | E31: 0 | F31: 0 | G31: 1473.79 | H31: 47.77 | I31: 250.29 | J31: =SUM(D31,E31,F31) | K31: =SUM(C31,G31,H31,I31,M31,N31) | L31: 2423.95 | M31: ='附表8'!E34 | N31: ='附表8'!F34 | O31: =J31-K31
A32: 12 | B32: 运营期 | C32: 0 | D32: 4195.8 | E32: 0 | F32: 0 | G32: 1473.79 | H32: 47.77 | I32: 250.29 | J32: =SUM(D32,E32,F32) | K32: =SUM(C32,G32,H32,I32,M32,N32) | L32: 2423.95 | M32: ='附表8'!E35 | N32: ='附表8'!F35 | O32: =J32-K32
... A44: 24 | B44: 运营期 | C44: 0 | D44: 4195.8 | E44: 2113.34 | F44: 0 | G44: 1473.79 | H44: 47.77 | I44: 250.29 | J44: =SUM(D44,E44,F44) | K44: =SUM(C44,G44,H44,I44,M44,N44) | L44: 4537.29 | M44: ='附表8'!E47 | N44: ='附表8'!F47 | O44: =J44-K44
A45: 说明1：资本金IRR=2.78
A46: 说明2：项目IRR=2.96
A47: 说明3：structure_gaps: 行业变体未冻结(variant=flat_estimate, model=flat)
A49: 现金流量组成树
A50: 项目 | B50: 0 | C50: 1 | D50: 2 | E50: 3 | F50: 4 | G50: 5 | H50: 6 | I50: 7 | J50: 8 | K50: 9 | L50: 10 | M50: 11 | N50: 12 | O50: 13 | P50: 14 | Q50: 15 | R50: 16 | S50: 17 | T50: 18 | U50: 19 | V50: 20 | W50: 21 | X50: 22 | Y50: 23 | Z50: 24
A51: 现金流入
A52: revenue | B52: ='附表10'!D20 | C52: ='附表10'!D21 | D52: ='附表10'!D22 | E52: ='附表10'!D23 | F52: ='附表10'!D24 | G52: ='附表10'!D25 | H52: ='附表10'!D26 | I52: ='附表10'!D27 | J52: ='附表10'!D28 | K52: ='附表10'!D29 | L52: ='附表10'!D30 | M52: ='附表10'!D31 | N52: ='附表10'!D32 | O52: ='附表10'!D33 | P52: ='附表10'!D34 | Q52: ='附表10'!D35 | R52: ='附表10'!D36 | S52: ='附表10'!D37 | T52: ='附表10'!D38 | U52: ='附表10'!D39 | V52: ='附表10'!D40 | W52: ='附表10'!D41 | X52: ='附表10'!D42 | Y52: ='附表10'!D43 | Z52: ='附表10'!D44
A53: recover_fixed | B53: ='附表10'!E20 | C53: ='附表10'!E21 | D53: ='附表10'!E22 | E53: ='附表10'!E23 | F53: ='附表10'!E24 | G53: ='附表10'!E25 | H53: ='附表10'!E26 | I53: ='附表10'!E27 | J53: ='附表10'!E28 | K53: ='附表10'!E29 | L53: ='附表10'!E30 | M53: ='附表10'!E31 | N53: ='附表10'!E32 | O53: ='附表10'!E33 | P53: ='附表10'!E34 | Q53: ='附表10'!E35 | R53: ='附表10'!E36 | S53: ='附表10'!E37 | T53: ='附表10'!E38 | U53: ='附表10'!E39 | V53: ='附表10'!E40 | W53: ='附表10'!E41 | X53: ='附表10'!E42 | Y53: ='附表10'!E43 | Z53: ='附表10'!E44
...

Sheet Indicators
A1: metric | B1: value | C1: unit | D1: source
A2: total_investment | B2: =Inputs!B2 | C2: 万元 | D2: formula→Inputs
A3: equity_capital | B3: =Inputs!B5 | C3: 万元 | D3: formula→Inputs
A4: loan | B4: =Inputs!B6 | C4: 万元 | D4: formula→Inputs
A5: project_irr_pct | B5: 2.96 | C5: % | D5: engine
A6: npv_wan | B6: -16412.29 | C6: 万元 | D6: engine
A7: static_payback_years | B7: 17.44 | C7: 年 | D7: engine
