Workbook

Sheet 附表1
A1: 附表1 固定资产投资估算表
A2: 计算状态：computed；口径：reference；有效：是
A3: 序号 | B3: 工程或费用名称 | C3: 计量单位 | D3: 工程量 | E3: 估算指标（元） | F3: 建筑工程 | G3: 设备原价 | H3: 运杂安装工程费 | I3: 其它费用 | J3: 合计 | K3: 比例(%)
A4: 1 | B4: 工程费用 | J4: 26227 | K4: 81.96
A5: 1.1 | B5: 游客服务中心 | C5: m2 | D5: 6000 | E5: 4800 | F5: =J5 | J5: =D5*E5/10000 | K5: =J5/J28*100
A6: 1.2 | B6: 生态景观与绿化工程 | C6: m2 | D6: 165000 | E6: 320 | F6: =J6 | J6: =D6*E6/10000 | K6: =J6/J28*100
A7: 1.3 | B7: 儿童游乐区场地与设施基础 | C7: m2 | D7: 15000 | E7: 2600 | F7: =J7 | J7: =D7*E7/10000 | K7: =J7/J28*100
A8: 1.4 | B8: 环湖步道与栈道 | C8: m | D8: 8500 | E8: 1800 | F8: =J8 | J8: =D8*E8/10000 | K8: =J8/J28*100
A9: 1.5 | B9: 民宿与康养住宿楼 | C9: m2 | D9: 9000 | E9: 5200 | F9: =J9 | J9: =D9*E9/10000 | K9: =J9/J28*100
A10: 1.6 | B10: 道路与停车场 | C10: m2 | D10: 45000 | E10: 420 | F10: =J10 | J10: =D10*E10/10000 | K10: =J10/J28*100
A11: 1.7 | B11: 给排水与电气管网 | C11: 项 | D11: 1 | E11: 11950000 | F11: =J11 | J11: =D11*E11/10000 | K11: =J11/J28*100
A12: 1.8 | B12: 大型游乐设备 | C12: 套 | D12: 6 | E12: 4800000 | G12: =J12 | J12: =D12*E12/10000 | K12: =J12/J28*100
A13: 1.9 | B13: 智慧景区系统 | C13: 套 | D13: 1 | E13: 6200000 | G13: =J13 | J13: =D13*E13/10000 | K13: =J13/J28*100
A14: 1.10 | B14: 运营设备与家具 | C14: 批 | D14: 1 | E14: 8500000 | G14: =J14 | J14: =D14*E14/10000 | K14: =J14/J28*100
A15: 1.11 | B15: 设备安装工程 | C15: 项 | D15: 1 | E15: 5220000 | H15: =J15 | J15: =D15*E15/10000 | K15: =J15/J28*100
A16: 2 | B16: 工程建设其他费用 | J16: 3583.8 | K16: 11.2
A17: 2.1 | B17: 土地使用费 | C17: 万元 | I17: =J17 | J17: =D17*E17/10000 | K17: =J17/J28*100
A18: 2.2 | B18: 勘察设计费 | C18: 万元 | I18: =J18 | J18: =D18*E18/10000 | K18: =J18/J28*100
A19: 2.3 | B19: 项目管理费 | C19: 万元 | I19: =J19 | J19: =D19*E19/10000 | K19: =J19/J28*100
A20: 2.4 | B20: 工程监理费 | C20: 万元 | I20: =J20 | J20: =D20*E20/10000 | K20: =J20/J28*100
A21: 2.5 | B21: 可研与咨询费 | C21: 万元 | I21: =J21 | J21: =D21*E21/10000 | K21: =J21/J28*100
A22: 3 | B22: 预备费 | J22: 1541.2 | K22: 4.82
A23: 3.1 | B23: 预备费合计 | C23: 万元 | I23: =J23 | J23: =D23*E23/10000 | K23: =J23/J28*100
A24: 4 | B24: 一至三项合计 | C24: 万元 | I24: 31352 | J24: 31352 | K24: 97.97
A25: 5 | B25: 建设期贷款利息 | C25: 万元 | I25: 648 | J25: 648 | K25: 2.02
A26: 6 | B26: 固定资产投资合计 | C26: 万元 | I26: 32000 | J26: 32000 | K26: 100
A27: 7 | B27: 流动资金 | C27: 万元 | I27: 0 | J27: 0 | K27: 0
B28: 项目总投资合计 | C28: 万元 | J28: 32000 | K28: 100
A29: 说明1：明细来自用户输入；未提供工程量/指标时保持空白，不反向造数

Sheet 附表2
A1: 附表2 建设期贷款利息表
A2: 计算状态：computed；口径：reference；有效：是
A3: 序号 | B3: 项目 | C3: 合计 | D3: 分年1 | E3: 分年2
A4: 1 | B4: 期初借款余额 | C4: =E4 | D4: =B14 | E4: =B15
A5: 2 | B5: 当期借款 | C5: =SUM(D5,E5) | D5: =C14 | E5: =C15
A6: 3 | B6: 年利率 | C6: 4.50% | D6: 4.50% | E6: 4.50%
A7: 4 | B7: 当期应付利息 | C7: =SUM(D7,E7) | D7: =E14 | E7: =E15
A8: 5 | B8: 期末借款余额 | C8: =E8 | D8: =F14 | E8: =F15
A9: 6 | B9: 其他融资费用 | C9: 0 | D9: 0 | E9: 0
B10: 小计 | C10: =SUM(D10,E10) | D10: =E14 | E10: =E15
A12: 引擎逐年计算区（供公式与跨表追溯）
A13: 期间 | B13: 期初借款余额 | C13: 当期提款 | D13: 年利率(%) | E13: 当期利息 | F13: 期末借款余额
A14: 1 | B14: 0 | C14: 7200 | D14: 0.045 | E14: =ROUND(324.00,2) | F14: =B14+C14
A15: 2 | B15: =F14 | C15: 7200 | D15: 0.045 | E15: =ROUND(324.00,2) | F15: =B15+C15

Sheet 附表3
A1: 附表3 流动资金估算表
A2: 计算状态：computed；口径：not_applicable；有效：否
A3: 构成项 | B3: 金额（万元）
A4: 流动资金总额（汇总输入） | B4: 0
A5: 说明1：method=ratio_backsolve
A6: 说明2：未提供周转天数，不展示反解伪分项；不得标分项法完成
A7: 跨表依赖复核：附表6 | B7: ='附表6'!A17

Sheet 附表4
A1: 附表4 投资使用计划与资金筹措表
A2: 计算状态：computed；口径：summary；有效：是
A3: 序号 | B3: 项目 | C3: 建设期第1年 | D3: 建设期第2年 | E3: 合计
A4: 1 | B4: 项目总投资使用计划 | C4: =SUM(C5,C6,C7) | D4: =SUM(D5,D6,D7) | E4: ='附表1'!J28
A5: 1.1 | B5: 建设投资 | C5: 15676 | D5: 15676 | E5: 31352
A6: 1.2 | B6: 建设期贷款利息 | C6: 324 | D6: 324 | E6: 648
A7: 1.3 | B7: 流动资金 | C7: 0 | D7: 0 | E7: 0
A8: 2 | B8: 资金筹措 | C8: =SUM(C9,C11) | D8: =SUM(D9,D11) | E8: ='附表1'!J28
A9: 2.1 | B9: 项目资本金（自筹） | C9: 8800 | D9: 8800 | E9: 17600
A10: 2.2 | B10: 债务资金 | C10: 7200 | D10: 7200 | E10: 14400
A11: 2.2.1 | B11: 银行贷款 | C11: 7200 | D11: 7200 | E11: 14400
A12: 说明1：无分年资金事实时按建设支出比例摊分；不得作为 formal 资金计划真源
A13: 说明2：structure_gaps: 资金计划为比例摊分回退，非事实包分年真源
A14: 跨表依赖复核：附表1 | B14: ='附表1'!J4
A15: 跨表依赖复核：附表3 | B15: ='附表3'!B4

Sheet 附表5
A1: 附表5 营业收入、税金及附加和增值税估算表
A2: 计算状态：computed；口径：summary；有效：是
A3: 序号 | B3: 项目 | C3: 单位 | D3: 合计 | E3: 分年1 | F3: 分年2 | G3: 分年3 | H3: 分年4 | I3: 分年5 | J3: 分年6 | K3: 分年7 | L3: 分年8 | M3: 分年9 | N3: 分年10 | O3: 分年11 | P3: 分年12 | Q3: 分年13 | R3: 分年14 | S3: 分年15 | T3: 分年16 | U3: 分年17 | V3: 分年18 | W3: 分年19 | X3: 分年20
A4: 1 | B4: 营业收入 | C4: 万元 | D4: =SUM(E4,F4,G4,H4,I4,J4,K4,L4,M4,N4,O4,P4,Q4,R4,S4,T4,U4,V4,W4,X4) | E4: =B22 | F4: =B23 | G4: =B24 | H4: =B25 | I4: =B26 | J4: =B27 | K4: =B28 | L4: =B29 | M4: =B30 | N4: =B31 | O4: =B32 | P4: =B33 | Q4: =B34 | R4: =B35 | S4: =B36 | T4: =B37 | U4: =B38 | V4: =B39 | W4: =B40 | X4: =B41
A5: 1.1 | B5: 门票收入 | C5: 万人次 | D5: 137160 | E5: 3600 | F5: 5040 | G5: 6120 | H5: 7200 | I5: 7200 | J5: 7200 | K5: 7200 | L5: 7200 | M5: 7200 | N5: 7200 | O5: 7200 | P5: 7200 | Q5: 7200 | R5: 7200 | S5: 7200 | T5: 7200 | U5: 7200 | V5: 7200 | W5: 7200 | X5: 7200
A6: 1.1.1 | B6: 单价 | C6: yuan | D6: 60 | E6: 60 | F6: 60 | G6: 60 | H6: 60 | I6: 60 | J6: 60 | K6: 60 | L6: 60 | M6: 60 | N6: 60 | O6: 60 | P6: 60 | Q6: 60 | R6: 60 | S6: 60 | T6: 60 | U6: 60 | V6: 60 | W6: 60 | X6: 60
A7: 1.1.2 | B7: 数量 | C7: 万人次 | D7: 2286 | E7: 60 | F7: 84 | G7: 102 | H7: 120 | I7: 120 | J7: 120 | K7: 120 | L7: 120 | M7: 120 | N7: 120 | O7: 120 | P7: 120 | Q7: 120 | R7: 120 | S7: 120 | T7: 120 | U7: 120 | V7: 120 | W7: 120 | X7: 120
A8: 1.2 | B8: 二次消费 | C8: 万人次 | D8: 56578.5 | E8: 1485 | F8: 2079 | G8: 2524.5 | H8: 2970 | I8: 2970 | J8: 2970 | K8: 2970 | L8: 2970 | M8: 2970 | N8: 2970 | O8: 2970 | P8: 2970 | Q8: 2970 | R8: 2970 | S8: 2970 | T8: 2970 | U8: 2970 | V8: 2970 | W8: 2970 | X8: 2970
A9: 1.2.1 | B9: 单价 | C9: yuan | D9: 45 | E9: 45 | F9: 45 | G9: 45 | H9: 45 | I9: 45 | J9: 45 | K9: 45 | L9: 45 | M9: 45 | N9: 45 | O9: 45 | P9: 45 | Q9: 45 | R9: 45 | S9: 45 | T9: 45 | U9: 45 | V9: 45 | W9: 45 | X9: 45
A10: 1.2.2 | B10: 数量 | C10: 万人次 | D10: 1257.3 | E10: 33 | F10: 46.2 | G10: 56.1 | H10: 66 | I10: 66 | J10: 66 | K10: 66 | L10: 66 | M10: 66 | N10: 66 | O10: 66 | P10: 66 | Q10: 66 | R10: 66 | S10: 66 | T10: 66 | U10: 66 | V10: 66 | W10: 66 | X10: 66
A11: 1.9 | B11: 营业收入合计 | C11: 万元 | D11: =SUM(E11,F11,G11,H11,I11,J11,K11,L11,M11,N11,O11,P11,Q11,R11,S11,T11,U11,V11,W11,X11) | E11: =B22 | F11: =B23 | G11: =B24 | H11: =B25 | I11: =B26 | J11: =B27 | K11: =B28 | L11: =B29 | M11: =B30 | N11: =B31 | O11: =B32 | P11: =B33 | Q11: =B34 | R11: =B35 | S11: =B36 | T11: =B37 | U11: =B38 | V11: =B39 | W11: =B40 | X11: =B41
A12: 2 | B12: 销项税额 | C12: 万元 | D12: =SUM(E12,F12,G12,H12,I12,J12,K12,L12,M12,N12,O12,P12,Q12,R12,S12,T12,U12,V12,W12,X12) | E12: =F22 | F12: =F23 | G12: =F24 | H12: =F25 | I12: =F26 | J12: =F27 | K12: =F28 | L12: =F29 | M12: =F30 | N12: =F31 | O12: =F32 | P12: =F33 | Q12: =F34 | R12: =F35 | S12: =F36 | T12: =F37 | U12: =F38 | V12: =F39 | W12: =F40 | X12: =F41
A13: 3 | B13: 营业税金与附加 | C13: 万元 | D13: =SUM(E13,F13,G13,H13,I13,J13,K13,L13,M13,N13,O13,P13,Q13,R13,S13,T13,U13,V13,W13,X13) | E13: =E22 | F13: =E23 | G13: =E24 | H13: =E25 | I13: =E26 | J13: =E27 | K13: =E28 | L13: =E29 | M13: =E30 | N13: =E31 | O13: =E32 | P13: =E33 | Q13: =E34 | R13: =E35 | S13: =E36 | T13: =E37 | U13: =E38 | V13: =E39 | W13: =E40 | X13: =E41
A14: 3.1 | B14: 城市维护建设税 | C14: 万元
A15: 3.2 | B15: 教育费附加 | C15: 万元
A16: 3.3 | B16: 地方教育附加 | C16: 万元
A17: 4 | B17: 进项税额 | C17: 万元 | D17: =SUM(E17,F17,G17,H17,I17,J17,K17,L17,M17,N17,O17,P17,Q17,R17,S17,T17,U17,V17,W17,X17) | E17: =G22 | F17: =G23 | G17: =G24 | H17: =G25 | I17: =G26 | J17: =G27 | K17: =G28 | L17: =G29 | M17: =G30 | N17: =G31 | O17: =G32 | P17: =G33 | Q17: =G34 | R17: =G35 | S17: =G36 | T17: =G37 | U17: =G38 | V17: =G39 | W17: =G40 | X17: =G41
A18: 5 | B18: 应纳增值税 | C18: 万元 | D18: =SUM(E18,F18,G18,H18,I18,J18,K18,L18,M18,N18,O18,P18,Q18,R18,S18,T18,U18,V18,W18,X18) | E18: =H22 | F18: =H23 | G18: =H24 | H18: =H25 | I18: =H26 | J18: =H27 | K18: =H28 | L18: =H29 | M18: =H30 | N18: =H31 | O18: =H32 | P18: =H33 | Q18: =H34 | R18: =H35 | S18: =H36 | T18: =H37 | U18: =H38 | V18: =H39 | W18: =H40 | X18: =H41
A20: 引擎逐年计算区（供公式与跨表追溯）
A21: 运营年 | B21: 营业收入 | C21: 经营成本 | D21: 折旧 | E21: 销售税金及附加 | F21: 销项税额 | G21: 进项税额 | H21: 应纳增值税 | I21: 调整所得税(融资前) | J21: 融资前净利
A22: 1 | B22: =SUM('附表5'!E45,'附表5'!E46) | C22: 2100 | D22: 1216 | E22: =H22*0.12 | F22: =B22*0.06 | G22: =C22*0.1 | H22: =MAX(F22-G22,0) | I22: 439.4 | J22: 1318.19
A23: 2 | B23: =SUM('附表5'!F45,'附表5'!F46) | C23: 2940 | D23: 1216 | E23: =H23*0.12 | F23: =B23*0.06 | G23: =C23*0.1 | H23: =MAX(F23-G23,0) | I23: 736.75 | J23: 2210.27
A24: 3 | B24: =SUM('附表5'!G45,'附表5'!G46) | C24: 3570 | D24: 1216 | E24: =H24*0.12 | F24: =B24*0.06 | G24: =C24*0.1 | H24: =MAX(F24-G24,0) | I24: 959.77 | J24: 2879.33
A25: 4 | B25: =SUM('附表5'!H45,'附表5'!H46) | C25: 4200 | D25: 1216 | E25: =H25*0.12 | F25: =B25*0.06 | G25: =C25*0.1 | H25: =MAX(F25-G25,0) | I25: 1182.8 | J25: 3548.38
A26: 5 | B26: =SUM('附表5'!I45,'附表5'!I46) | C26: 4200 | D26: 1216 | E26: =H26*0.12 | F26: =B26*0.06 | G26: =C26*0.1 | H26: =MAX(F26-G26,0) | I26: 1182.8 | J26: 3548.38
A27: 6 | B27: =SUM('附表5'!J45,'附表5'!J46) | C27: 4200 | D27: 1216 | E27: =H27*0.12 | F27: =B27*0.06 | G27: =C27*0.1 | H27: =MAX(F27-G27,0) | I27: 1182.8 | J27: 3548.38
A28: 7 | B28: =SUM('附表5'!K45,'附表5'!K46) | C28: 4200 | D28: 1216 | E28: =H28*0.12 | F28: =B28*0.06 | G28: =C28*0.1 | H28: =MAX(F28-G28,0) | I28: 1182.8 | J28: 3548.38
A29: 8 | B29: =SUM('附表5'!L45,'附表5'!L46) | C29: 4200 | D29: 1216 | E29: =H29*0.12 | F29: =B29*0.06 | G29: =C29*0.1 | H29: =MAX(F29-G29,0) | I29: 1182.8 | J29: 3548.38
A30: 9 | B30: =SUM('附表5'!M45,'附表5'!M46) | C30: 4200 | D30: 1216 | E30: =H30*0.12 | F30: =B30*0.06 | G30: =C30*0.1 | H30: =MAX(F30-G30,0) | I30: 1182.8 | J30: 3548.38
A31: 10 | B31: =SUM('附表5'!N45,'附表5'!N46) | C31: 4200 | D31: 1216 | E31: =H31*0.12 | F31: =B31*0.06 | G31: =C31*0.1 | H31: =MAX(F31-G31,0) | I31: 1182.8 | J31: 3548.38
A32: 11 | B32: =SUM('附表5'!O45,'附表5'!O46) | C32: 4200 | D32: 1216 | E32: =H32*0.12 | F32: =B32*0.06 | G32: =C32*0.1 | H32: =MAX(F32-G32,0) | I32: 1182.8 | J32: 3548.38
A33: 12 | B33: =SUM('附表5'!P45,'附表5'!P46) | C33: 4200 | D33: 1216 | E33: =H33*0.12 | F33: =B33*0.06 | G33: =C33*0.1 | H33: =MAX(F33-G33,0) | I33: 1182.8 | J33: 3548.38
A34: 13 | B34: =SUM('附表5'!Q45,'附表5'!Q46) | C34: 4200 | D34: 1216 | E34: =H34*0.12 | F34: =B34*0.06 | G34: =C34*0.1 | H34: =MAX(F34-G34,0) | I34: 1182.8 | J34: 3548.38
A35: 14 | B35: =SUM('附表5'!R45,'附表5'!R46) | C35: 4200 | D35: 1216 | E35: =H35*0.12 | F35: =B35*0.06 | G35: =C35*0.1 | H35: =MAX(F35-G35,0) | I35: 1182.8 | J35: 3548.38
A36: 15 | B36: =SUM('附表5'!S45,'附表5'!S46) | C36: 4200 | D36: 1216 | E36: =H36*0.12 | F36: =B36*0.06 | G36: =C36*0.1 | H36: =MAX(F36-G36,0) | I36: 1182.8 | J36: 3548.38
A37: 16 | B37: =SUM('附表5'!T45,'附表5'!T46) | C37: 4200 | D37: 1216 | E37: =H37*0.12 | F37: =B37*0.06 | G37: =C37*0.1 | H37: =MAX(F37-G37,0) | I37: 1182.8 | J37: 3548.38
A38: 17 | B38: =SUM('附表5'!U45,'附表5'!U46) | C38: 4200 | D38: 1216 | E38: =H38*0.12 | F38: =B38*0.06 | G38: =C38*0.1 | H38: =MAX(F38-G38,0) | I38: 1182.8 | J38: 3548.38
A39: 18 | B39: =SUM('附表5'!V45,'附表5'!V46) | C39: 4200 | D39: 1216 | E39: =H39*0.12 | F39: =B39*0.06 | G39: =C39*0.1 | H39: =MAX(F39-G39,0) | I39: 1182.8 | J39: 3548.38
A40: 19 | B40: =SUM('附表5'!W45,'附表5'!W46) | C40: 4200 | D40: 1216 | E40: =H40*0.12 | F40: =B40*0.06 | G40: =C40*0.1 | H40: =MAX(F40-G40,0) | I40: 1182.8 | J40: 3548.38
A41: 20 | B41: =SUM('附表5'!X45,'附表5'!X46) | C41: 4200 | D41: 1216 | E41: =H41*0.12 | F41: =B41*0.06 | G41: =C41*0.1 | H41: =MAX(F41-G41,0) | I41: 1182.8 | J41: 3548.38
...

Sheet 附表6
A1: 附表6 总成本费用估算表
A2: 计算状态：computed；口径：summary；有效：是
A3: 序号 | B3: 项目 | C3: 合计 | D3: 计算期1 | E3: 计算期2 | F3: 计算期3 | G3: 计算期4 | H3: 计算期5 | I3: 计算期6 | J3: 计算期7 | K3: 计算期8 | L3: 计算期9 | M3: 计算期10 | N3: 计算期11 | O3: 计算期12 | P3: 计算期13 | Q3: 计算期14 | R3: 计算期15 | S3: 计算期16 | T3: 计算期17 | U3: 计算期18 | V3: 计算期19 | W3: 计算期20
A4: 1 | B4: 生产负荷（%） | C4: 100 | D4: 50 | E4: 70 | F4: 85 | G4: 100 | H4: 100 | I4: 100 | J4: 100 | K4: 100 | L4: 100 | M4: 100 | N4: 100 | O4: 100 | P4: 100 | Q4: 100 | R4: 100 | S4: 100 | T4: 100 | U4: 100 | V4: 100 | W4: 100
A5: 2 | B5: 年经营成本 | C5: 80010 | D5: 2100 | E5: 2940 | F5: 3570 | G5: 4200 | H5: 4200 | I5: 4200 | J5: 4200 | K5: 4200 | L5: 4200 | M5: 4200 | N5: 4200 | O5: 4200 | P5: 4200 | Q5: 4200 | R5: 4200 | S5: 4200 | T5: 4200 | U5: 4200 | V5: 4200 | W5: 4200
A6: 8 | B6: 经营成本 | C6: =SUM(D6,E6,F6,G6,H6,I6,J6,K6,L6,M6,N6,O6,P6,Q6,R6,S6,T6,U6,V6,W6) | D6: =B17 | E6: =B18 | F6: =B19 | G6: =B20 | H6: =B21 | I6: =B22 | J6: =B23 | K6: =B24 | L6: =B25 | M6: =B26 | N6: =B27 | O6: =B28 | P6: =B29 | Q6: =B30 | R6: =B31 | S6: =B32 | T6: =B33 | U6: =B34 | V6: =B35 | W6: =B36
A7: 9 | B7: 折旧费 | C7: =SUM(D7,E7,F7,G7,H7,I7,J7,K7,L7,M7,N7,O7,P7,Q7,R7,S7,T7,U7,V7,W7) | D7: =C17 | E7: =C18 | F7: =C19 | G7: =C20 | H7: =C21 | I7: =C22 | J7: =C23 | K7: =C24 | L7: =C25 | M7: =C26 | N7: =C27 | O7: =C28 | P7: =C29 | Q7: =C30 | R7: =C31 | S7: =C32 | T7: =C33 | U7: =C34 | V7: =C35 | W7: =C36
A8: 10 | B8: 摊销费 | C8: =SUM(D8,E8,F8,G8,H8,I8,J8,K8,L8,M8,N8,O8,P8,Q8,R8,S8,T8,U8,V8,W8) | D8: =D17 | E8: =D18 | F8: =D19 | G8: =D20 | H8: =D21 | I8: =D22 | J8: =D23 | K8: =D24 | L8: =D25 | M8: =D26 | N8: =D27 | O8: =D28 | P8: =D29 | Q8: =D30 | R8: =D31 | S8: =D32 | T8: =D33 | U8: =D34 | V8: =D35 | W8: =D36
A9: 11 | B9: 财务费用 | C9: =SUM(D9,E9,F9,G9,H9,I9,J9,K9,L9,M9,N9,O9,P9,Q9,R9,S9,T9,U9,V9,W9) | D9: =E17 | E9: =E18 | F9: =E19 | G9: =E20 | H9: =E21 | I9: =E22 | J9: =E23 | K9: =E24 | L9: =E25 | M9: =E26 | N9: =E27 | O9: =E28 | P9: =E29 | Q9: =E30 | R9: =E31 | S9: =E32 | T9: =E33 | U9: =E34 | V9: =E35 | W9: =E36
A10: 11.1 | B10: 长期贷款利息 | C10: =SUM(D10,E10,F10,G10,H10,I10,J10,K10,L10,M10,N10,O10,P10,Q10,R10,S10,T10,U10,V10,W10) | D10: =E17 | E10: =E18 | F10: =E19 | G10: =E20 | H10: =E21 | I10: =E22 | J10: =E23 | K10: =E24 | L10: =E25 | M10: =E26 | N10: =E27 | O10: =E28 | P10: =E29 | Q10: =E30 | R10: =E31 | S10: =E32 | T10: =E33 | U10: =E34 | V10: =E35 | W10: =E36
A11: 12 | B11: 总成本费用 | C11: =SUM(D11,E11,F11,G11,H11,I11,J11,K11,L11,M11,N11,O11,P11,Q11,R11,S11,T11,U11,V11,W11) | D11: =F17 | E11: =F18 | F11: =F19 | G11: =F20 | H11: =F21 | I11: =F22 | J11: =F23 | K11: =F24 | L11: =F25 | M11: =F26 | N11: =F27 | O11: =F28 | P11: =F29 | Q11: =F30 | R11: =F31 | S11: =F32 | T11: =F33 | U11: =F34 | V11: =F35 | W11: =F36
A12: 12.1 | B12: 固定成本 | C12: 80010 | D12: 2100 | E12: 2940 | F12: 3570 | G12: 4200 | H12: 4200 | I12: 4200 | J12: 4200 | K12: 4200 | L12: 4200 | M12: 4200 | N12: 4200 | O12: 4200 | P12: 4200 | Q12: 4200 | R12: 4200 | S12: 4200 | T12: 4200 | U12: 4200 | V12: 4200 | W12: 4200
A13: 12.2 | B13: 变动成本 | C13: 0 | D13: 0 | E13: 0 | F13: 0 | G13: 0 | H13: 0 | I13: 0 | J13: 0 | K13: 0 | L13: 0 | M13: 0 | N13: 0 | O13: 0 | P13: 0 | Q13: 0 | R13: 0 | S13: 0 | T13: 0 | U13: 0 | V13: 0 | W13: 0
A15: 引擎逐年计算区（供公式与跨表追溯）
A16: 运营年 | B16: 经营成本 | C16: 折旧费 | D16: 摊销费 | E16: 利息支出 | F16: 总成本费用
A17: 1 | B17: =SUM('附表6'!B40) | C17: 1216 | D17: 0 | E17: 648 | F17: =SUM(B17,C17,D17,E17)
A18: 2 | B18: =SUM('附表6'!C40) | C18: 1216 | D18: 0 | E18: 594 | F18: =SUM(B18,C18,D18,E18)
A19: 3 | B19: =SUM('附表6'!D40) | C19: 1216 | D19: 0 | E19: 540 | F19: =SUM(B19,C19,D19,E19)
A20: 4 | B20: =SUM('附表6'!E40) | C20: 1216 | D20: 0 | E20: 486 | F20: =SUM(B20,C20,D20,E20)
A21: 5 | B21: =SUM('附表6'!F40) | C21: 1216 | D21: 0 | E21: 432 | F21: =SUM(B21,C21,D21,E21)
A22: 6 | B22: =SUM('附表6'!G40) | C22: 1216 | D22: 0 | E22: 378 | F22: =SUM(B22,C22,D22,E22)
A23: 7 | B23: =SUM('附表6'!H40) | C23: 1216 | D23: 0 | E23: 324 | F23: =SUM(B23,C23,D23,E23)
A24: 8 | B24: =SUM('附表6'!I40) | C24: 1216 | D24: 0 | E24: 270 | F24: =SUM(B24,C24,D24,E24)
A25: 9 | B25: =SUM('附表6'!J40) | C25: 1216 | D25: 0 | E25: 216 | F25: =SUM(B25,C25,D25,E25)
A26: 10 | B26: =SUM('附表6'!K40) | C26: 1216 | D26: 0 | E26: 162 | F26: =SUM(B26,C26,D26,E26)
A27: 11 | B27: =SUM('附表6'!L40) | C27: 1216 | D27: 0 | E27: 108 | F27: =SUM(B27,C27,D27,E27)
A28: 12 | B28: =SUM('附表6'!M40) | C28: 1216 | D28: 0 | E28: 54 | F28: =SUM(B28,C28,D28,E28)
A29: 13 | B29: =SUM('附表6'!N40) | C29: 1216 | D29: 0 | E29: 0 | F29: =SUM(B29,C29,D29,E29)
A30: 14 | B30: =SUM('附表6'!O40) | C30: 1216 | D30: 0 | E30: 0 | F30: =SUM(B30,C30,D30,E30)
A31: 15 | B31: =SUM('附表6'!P40) | C31: 1216 | D31: 0 | E31: 0 | F31: =SUM(B31,C31,D31,E31)
A32: 16 | B32: =SUM('附表6'!Q40) | C32: 1216 | D32: 0 | E32: 0 | F32: =SUM(B32,C32,D32,E32)
A33: 17 | B33: =SUM('附表6'!R40) | C33: 1216 | D33: 0 | E33: 0 | F33: =SUM(B33,C33,D33,E33)
A34: 18 | B34: =SUM('附表6'!S40) | C34: 1216 | D34: 0 | E34: 0 | F34: =SUM(B34,C34,D34,E34)
A35: 19 | B35: =SUM('附表6'!T40) | C35: 1216 | D35: 0 | E35: 0 | F35: =SUM(B35,C35,D35,E35)
A36: 20 | B36: =SUM('附表6'!U40) | C36: 1216 | D36: 0 | E36: 0 | F36: =SUM(B36,C36,D36,E36)
A38: 成本费用明细树
A39: 成本项目 | B39: 运营年1 | C39: 运营年2 | D39: 运营年3 | E39: 运营年4 | F39: 运营年5 | G39: 运营年6 | H39: 运营年7 | I39: 运营年8 | J39: 运营年9 | K39: 运营年10 | L39: 运营年11 | M39: 运营年12 | N39: 运营年13 | O39: 运营年14 | P39: 运营年15 | Q39: 运营年16 | R39: 运营年17 | S39: 运营年18 | T39: 运营年19 | U39: 运营年20
A40: 年经营成本 | B40: 2100 | C40: 2940 | D40: 3570 | E40: 4200 | F40: 4200 | G40: 4200 | H40: 4200 | I40: 4200 | J40: 4200 | K40: 4200 | L40: 4200 | M40: 4200 | N40: 4200 | O40: 4200 | P40: 4200 | Q40: 4200 | R40: 4200 | S40: 4200 | T40: 4200 | U40: 4200
A41: 说明1：missing_fields: cost_items 成本明细树（≥3 项；默认总成本率不算 reference）
A42: 说明2：structure_gaps: 行业变体未冻结(variant=tourism, model=tourism)；缺参考行组 raw（外购原材料费）；缺参考行组 fuel（外购燃料及动力费/外购燃料和动力费）；缺参考行组 wage（工资及福利费）；缺参考行组 repair（修理费）；缺 cost_items 成本明细树（≥3 项）；固定/变动成本分类未确认（cost_behavior）；名称猜测仅估算，不得升 reference
...

Sheet 附表6-1
A1: 附表6-1 工资及附加估算表
A2: 计算状态：computed；口径：summary；有效：是
A3: 序号 | B3: 项目 | C3: 单位 | D3: 人数 | E3: 人均年工资 | F3: 合计 | G3: 分年1 | H3: 分年2 | I3: 分年3 | J3: 分年4 | K3: 分年5 | L3: 分年6 | M3: 分年7 | N3: 分年8 | O3: 分年9 | P3: 分年10 | Q3: 分年11 | R3: 分年12 | S3: 分年13 | T3: 分年14 | U3: 分年15 | V3: 分年16 | W3: 分年17 | X3: 分年18 | Y3: 分年19 | Z3: 分年20
A4: 1 | B4: 劳动定员 | C4: 人 | D4: 0 | F4: 0 | G4: 0 | H4: 0 | I4: 0 | J4: 0 | K4: 0 | L4: 0 | M4: 0 | N4: 0 | O4: 0 | P4: 0 | Q4: 0 | R4: 0 | S4: 0 | T4: 0 | U4: 0 | V4: 0 | W4: 0 | X4: 0 | Y4: 0 | Z4: 0
A5: 2 | B5: 工资额 | C5: 万元 | F5: =SUM(G5,H5,I5,J5,K5,L5,M5,N5,O5,P5,Q5,R5,S5,T5,U5,V5,W5,X5,Y5,Z5) | G5: =B11 | H5: =B12 | I5: =B13 | J5: =B14 | K5: =B15 | L5: =B16 | M5: =B17 | N5: =B18 | O5: =B19 | P5: =B20 | Q5: =B21 | R5: =B22 | S5: =B23 | T5: =B24 | U5: =B25 | V5: =B26 | W5: =B27 | X5: =B28 | Y5: =B29 | Z5: =B30
A6: 3 | B6: 福利费 | C6: 万元 | F6: =SUM(G6,H6,I6,J6,K6,L6,M6,N6,O6,P6,Q6,R6,S6,T6,U6,V6,W6,X6,Y6,Z6) | G6: =C11 | H6: =C12 | I6: =C13 | J6: =C14 | K6: =C15 | L6: =C16 | M6: =C17 | N6: =C18 | O6: =C19 | P6: =C20 | Q6: =C21 | R6: =C22 | S6: =C23 | T6: =C24 | U6: =C25 | V6: =C26 | W6: =C27 | X6: =C28 | Y6: =C29 | Z6: =C30
B7: 合计 | C7: 万元 | F7: =SUM(G7,H7,I7,J7,K7,L7,M7,N7,O7,P7,Q7,R7,S7,T7,U7,V7,W7,X7,Y7,Z7) | G7: =D11 | H7: =D12 | I7: =D13 | J7: =D14 | K7: =D15 | L7: =D16 | M7: =D17 | N7: =D18 | O7: =D19 | P7: =D20 | Q7: =D21 | R7: =D22 | S7: =D23 | T7: =D24 | U7: =D25 | V7: =D26 | W7: =D27 | X7: =D28 | Y7: =D29 | Z7: =D30
A9: 引擎逐年计算区（供公式与跨表追溯）
A10: 运营年 | B10: 工资 | C10: 职工福利及附加 | D10: 工资及附加合计
A11: 1 | B11: 630 | C11: 88.2 | D11: =B11+C11
A12: 2 | B12: 630 | C12: 88.2 | D12: =B12+C12
A13: 3 | B13: 630 | C13: 88.2 | D13: =B13+C13
A14: 4 | B14: 630 | C14: 88.2 | D14: =B14+C14
A15: 5 | B15: 630 | C15: 88.2 | D15: =B15+C15
A16: 6 | B16: 630 | C16: 88.2 | D16: =B16+C16
A17: 7 | B17: 630 | C17: 88.2 | D17: =B17+C17
A18: 8 | B18: 630 | C18: 88.2 | D18: =B18+C18
A19: 9 | B19: 630 | C19: 88.2 | D19: =B19+C19
A20: 10 | B20: 630 | C20: 88.2 | D20: =B20+C20
A21: 11 | B21: 630 | C21: 88.2 | D21: =B21+C21
A22: 12 | B22: 630 | C22: 88.2 | D22: =B22+C22
... A30: 20 | B30: 630 | C30: 88.2 | D30: =B30+C30
A31: 说明1：missing_fields: staff_detail 劳动定员（人数×人均年工资，可多类）
A32: 说明2：structure_gaps: 行业变体未冻结(variant=tourism, model=tourism)；工资表缺可复算的人员类别×人数×人均年工资

Sheet 附表6-2
A1: 附表6-2 固定资产折旧费估算表
A2: 计算状态：computed；口径：summary；有效：是
A3: 序号 | B3: 项目 | C3: 合计 | D3: 折旧年限 | E3: 分年1 | F3: 分年2 | G3: 分年3 | H3: 分年4 | I3: 分年5 | J3: 分年6 | K3: 分年7 | L3: 分年8 | M3: 分年9 | N3: 分年10 | O3: 分年11 | P3: 分年12 | Q3: 分年13 | R3: 分年14 | S3: 分年15 | T3: 分年16 | U3: 分年17 | V3: 分年18 | W3: 分年19 | X3: 分年20
B4: 合计 | C4: =SUM(E4,F4,G4,H4,I4,J4,K4,L4,M4,N4,O4,P4,Q4,R4,S4,T4,U4,V4,W4,X4) | E4: =E8 | F4: =E9 | G4: =E10 | H4: =E11 | I4: =E12 | J4: =E13 | K4: =E14 | L4: =E15 | M4: =E16 | N4: =E17 | O4: =E18 | P4: =E19 | Q4: =E20 | R4: =E21 | S4: =E22 | T4: =E23 | U4: =E24 | V4: =E25 | W4: =E26 | X4: =E27
A6: 引擎逐年计算区（供公式与跨表追溯）
A7: 运营年 | B7: 固定资产原值 | C7: 残值率 | D7: 折旧年限 | E7: 当期折旧费 | F7: 累计折旧 | G7: 净值
A8: 1 | B8: 32000 | C8: 0.05 | D8: 25 | E8: 1216 | F8: =E8 | G8: =B8-F8
A9: 2 | B9: 32000 | C9: 0.05 | D9: 25 | E9: 1216 | F9: =F8+E9 | G9: =B9-F9
A10: 3 | B10: 32000 | C10: 0.05 | D10: 25 | E10: 1216 | F10: =F9+E10 | G10: =B10-F10
A11: 4 | B11: 32000 | C11: 0.05 | D11: 25 | E11: 1216 | F11: =F10+E11 | G11: =B11-F11
A12: 5 | B12: 32000 | C12: 0.05 | D12: 25 | E12: 1216 | F12: =F11+E12 | G12: =B12-F12
A13: 6 | B13: 32000 | C13: 0.05 | D13: 25 | E13: 1216 | F13: =F12+E13 | G13: =B13-F13
A14: 7 | B14: 32000 | C14: 0.05 | D14: 25 | E14: 1216 | F14: =F13+E14 | G14: =B14-F14
A15: 8 | B15: 32000 | C15: 0.05 | D15: 25 | E15: 1216 | F15: =F14+E15 | G15: =B15-F15
A16: 9 | B16: 32000 | C16: 0.05 | D16: 25 | E16: 1216 | F16: =F15+E16 | G16: =B16-F16
A17: 10 | B17: 32000 | C17: 0.05 | D17: 25 | E17: 1216 | F17: =F16+E17 | G17: =B17-F17
A18: 11 | B18: 32000 | C18: 0.05 | D18: 25 | E18: 1216 | F18: =F17+E18 | G18: =B18-F18
A19: 12 | B19: 32000 | C19: 0.05 | D19: 25 | E19: 1216 | F19: =F18+E19 | G19: =B19-F19
A20: 13 | B20: 32000 | C20: 0.05 | D20: 25 | E20: 1216 | F20: =F19+E20 | G20: =B20-F20
... A27: 20 | B27: 32000 | C27: 0.05 | D27: 25 | E27: 1216 | F27: =F26+E27 | G27: =B27-F27
A28: 说明1：missing_fields: asset_classes 资产类别原值与折旧年限（≥2 类）
A29: 说明2：structure_gaps: 行业变体未冻结(variant=tourism, model=tourism)；缺参考行组 building（房屋、建筑物/房屋建筑物/房屋建筑及构筑物）；缺参考行组 equipment（机器设备/游乐设备）；缺参考行组 original（原值）；缺参考行组 depreciation（当期折旧费）；缺参考行组 net（净值）；缺资产类别折旧（房屋/设备等），综合原值合计不算 reference；缺累计折旧/净值滚动列；折旧表缺至少 2 类资产的原值×年限明细
A30: 跨表依赖复核：附表1 | B30: ='附表1'!J4

Sheet 附表6-3
A1: 附表6-3 无形资产及其他资产摊销估算表
A2: 计算状态：computed；口径：not_applicable；有效：否
A3: 序号 | B3: 项目 | C3: 合计 | D3: 摊销年限 | E3: 分年1 | F3: 分年2 | G3: 分年3 | H3: 分年4 | I3: 分年5 | J3: 分年6 | K3: 分年7 | L3: 分年8 | M3: 分年9 | N3: 分年10 | O3: 分年11 | P3: 分年12 | Q3: 分年13 | R3: 分年14 | S3: 分年15 | T3: 分年16 | U3: 分年17 | V3: 分年18 | W3: 分年19 | X3: 分年20
B4: 合计 | C4: =SUM(E4,F4,G4,H4,I4,J4,K4,L4,M4,N4,O4,P4,Q4,R4,S4,T4,U4,V4,W4,X4) | E4: =D8 | F4: =D9 | G4: =D10 | H4: =D11 | I4: =D12 | J4: =D13 | K4: =D14 | L4: =D15 | M4: =D16 | N4: =D17 | O4: =D18 | P4: =D19 | Q4: =D20 | R4: =D21 | S4: =D22 | T4: =D23 | U4: =D24 | V4: =D25 | W4: =D26 | X4: =D27
A6: 引擎逐年计算区（供公式与跨表追溯）
A7: 运营年 | B7: 摊销基数 | C7: 摊销年限 | D7: 当期摊销费
A8: 1 | B8: 0 | C8: 10 | D8: =IF(A8<=C8,B8/C8,0)
A9: 2 | B9: 0 | C9: 10 | D9: =IF(A9<=C9,B9/C9,0)
A10: 3 | B10: 0 | C10: 10 | D10: =IF(A10<=C10,B10/C10,0)
A11: 4 | B11: 0 | C11: 10 | D11: =IF(A11<=C11,B11/C11,0)
A12: 5 | B12: 0 | C12: 10 | D12: =IF(A12<=C12,B12/C12,0)
A13: 6 | B13: 0 | C13: 10 | D13: =IF(A13<=C13,B13/C13,0)
A14: 7 | B14: 0 | C14: 10 | D14: =IF(A14<=C14,B14/C14,0)
A15: 8 | B15: 0 | C15: 10 | D15: =IF(A15<=C15,B15/C15,0)
A16: 9 | B16: 0 | C16: 10 | D16: =IF(A16<=C16,B16/C16,0)
A17: 10 | B17: 0 | C17: 10 | D17: =IF(A17<=C17,B17/C17,0)
A18: 11 | B18: 0 | C18: 10 | D18: =IF(A18<=C18,B18/C18,0)
A19: 12 | B19: 0 | C19: 10 | D19: =IF(A19<=C19,B19/C19,0)
... A27: 20 | B27: 0 | C27: 10 | D27: =IF(A27<=C27,B27/C27,0)
A28: 跨表依赖复核：附表1 | B28: ='附表1'!J4

Sheet 附表7
A1: 附表7 利润与利润分配表
A2: 计算状态：computed；口径：summary；有效：是
A3: 序号 | B3: 项目 | C3: 合计 | D3: 计算期1 | E3: 计算期2 | F3: 计算期3 | G3: 计算期4 | H3: 计算期5 | I3: 计算期6 | J3: 计算期7 | K3: 计算期8 | L3: 计算期9 | M3: 计算期10 | N3: 计算期11 | O3: 计算期12 | P3: 计算期13 | Q3: 计算期14 | R3: 计算期15 | S3: 计算期16 | T3: 计算期17 | U3: 计算期18 | V3: 计算期19 | W3: 计算期20
A4: 1 | B4: 营业收入 | C4: =SUM(D4,E4,F4,G4,H4,I4,J4,K4,L4,M4,N4,O4,P4,Q4,R4,S4,T4,U4,V4,W4) | D4: =B24 | E4: =B25 | F4: =B26 | G4: =B27 | H4: =B28 | I4: =B29 | J4: =B30 | K4: =B31 | L4: =B32 | M4: =B33 | N4: =B34 | O4: =B35 | P4: =B36 | Q4: =B37 | R4: =B38 | S4: =B39 | T4: =B40 | U4: =B41 | V4: =B42 | W4: =B43
A5: 2 | B5: 营业税金及附加 | C5: =SUM(D5,E5,F5,G5,H5,I5,J5,K5,L5,M5,N5,O5,P5,Q5,R5,S5,T5,U5,V5,W5) | D5: =D24 | E5: =D25 | F5: =D26 | G5: =D27 | H5: =D28 | I5: =D29 | J5: =D30 | K5: =D31 | L5: =D32 | M5: =D33 | N5: =D34 | O5: =D35 | P5: =D36 | Q5: =D37 | R5: =D38 | S5: =D39 | T5: =D40 | U5: =D41 | V5: =D42 | W5: =D43
A6: 3 | B6: 总成本费用 | C6: =SUM(D6,E6,F6,G6,H6,I6,J6,K6,L6,M6,N6,O6,P6,Q6,R6,S6,T6,U6,V6,W6) | D6: =C24 | E6: =C25 | F6: =C26 | G6: =C27 | H6: =C28 | I6: =C29 | J6: =C30 | K6: =C31 | L6: =C32 | M6: =C33 | N6: =C34 | O6: =C35 | P6: =C36 | Q6: =C37 | R6: =C38 | S6: =C39 | T6: =C40 | U6: =C41 | V6: =C42 | W6: =C43
A7: 4 | B7: 利润总额 | C7: =SUM(D7,E7,F7,G7,H7,I7,J7,K7,L7,M7,N7,O7,P7,Q7,R7,S7,T7,U7,V7,W7) | D7: =E24 | E7: =E25 | F7: =E26 | G7: =E27 | H7: =E28 | I7: =E29 | J7: =E30 | K7: =E31 | L7: =E32 | M7: =E33 | N7: =E34 | O7: =E35 | P7: =E36 | Q7: =E37 | R7: =E38 | S7: =E39 | T7: =E40 | U7: =E41 | V7: =E42 | W7: =E43
A8: 5 | B8: 弥补以前年度亏损 | C8: =SUM(D8,E8,F8,G8,H8,I8,J8,K8,L8,M8,N8,O8,P8,Q8,R8,S8,T8,U8,V8,W8) | D8: =H24 | E8: =H25 | F8: =H26 | G8: =H27 | H8: =H28 | I8: =H29 | J8: =H30 | K8: =H31 | L8: =H32 | M8: =H33 | N8: =H34 | O8: =H35 | P8: =H36 | Q8: =H37 | R8: =H38 | S8: =H39 | T8: =H40 | U8: =H41 | V8: =H42 | W8: =H43
A9: 6 | B9: 应纳税所得额 | C9: =SUM(D9,E9,F9,G9,H9,I9,J9,K9,L9,M9,N9,O9,P9,Q9,R9,S9,T9,U9,V9,W9) | D9: =I24 | E9: =I25 | F9: =I26 | G9: =I27 | H9: =I28 | I9: =I29 | J9: =I30 | K9: =I31 | L9: =I32 | M9: =I33 | N9: =I34 | O9: =I35 | P9: =I36 | Q9: =I37 | R9: =I38 | S9: =I39 | T9: =I40 | U9: =I41 | V9: =I42 | W9: =I43
A10: 7 | B10: 所得税 | C10: =SUM(D10,E10,F10,G10,H10,I10,J10,K10,L10,M10,N10,O10,P10,Q10,R10,S10,T10,U10,V10,W10) | D10: =J24 | E10: =J25 | F10: =J26 | G10: =J27 | H10: =J28 | I10: =J29 | J10: =J30 | K10: =J31 | L10: =J32 | M10: =J33 | N10: =J34 | O10: =J35 | P10: =J36 | Q10: =J37 | R10: =J38 | S10: =J39 | T10: =J40 | U10: =J41 | V10: =J42 | W10: =J43
A11: 8 | B11: 净利润 | C11: =SUM(D11,E11,F11,G11,H11,I11,J11,K11,L11,M11,N11,O11,P11,Q11,R11,S11,T11,U11,V11,W11) | D11: =K24 | E11: =K25 | F11: =K26 | G11: =K27 | H11: =K28 | I11: =K29 | J11: =K30 | K11: =K31 | L11: =K32 | M11: =K33 | N11: =K34 | O11: =K35 | P11: =K36 | Q11: =K37 | R11: =K38 | S11: =K39 | T11: =K40 | U11: =K41 | V11: =K42 | W11: =K43
A12: 9 | B12: 期初未分配利润 | C12: =SUM(D12,E12,F12,G12,H12,I12,J12,K12,L12,M12,N12,O12,P12,Q12,R12,S12,T12,U12,V12,W12) | D12: =L24 | E12: =L25 | F12: =L26 | G12: =L27 | H12: =L28 | I12: =L29 | J12: =L30 | K12: =L31 | L12: =L32 | M12: =L33 | N12: =L34 | O12: =L35 | P12: =L36 | Q12: =L37 | R12: =L38 | S12: =L39 | T12: =L40 | U12: =L41 | V12: =L42 | W12: =L43
A13: 10 | B13: 可供分配的利润 | C13: =SUM(D13,E13,F13,G13,H13,I13,J13,K13,L13,M13,N13,O13,P13,Q13,R13,S13,T13,U13,V13,W13) | D13: =M24 | E13: =M25 | F13: =M26 | G13: =M27 | H13: =M28 | I13: =M29 | J13: =M30 | K13: =M31 | L13: =M32 | M13: =M33 | N13: =M34 | O13: =M35 | P13: =M36 | Q13: =M37 | R13: =M38 | S13: =M39 | T13: =M40 | U13: =M41 | V13: =M42 | W13: =M43
A14: 11 | B14: 提取法定盈余公积金 | C14: =SUM(D14,E14,F14,G14,H14,I14,J14,K14,L14,M14,N14,O14,P14,Q14,R14,S14,T14,U14,V14,W14) | D14: =N24 | E14: =N25 | F14: =N26 | G14: =N27 | H14: =N28 | I14: =N29 | J14: =N30 | K14: =N31 | L14: =N32 | M14: =N33 | N14: =N34 | O14: =N35 | P14: =N36 | Q14: =N37 | R14: =N38 | S14: =N39 | T14: =N40 | U14: =N41 | V14: =N42 | W14: =N43
A15: 12 | B15: 可供投资者分配的利润 | C15: =SUM(D15,E15,F15,G15,H15,I15,J15,K15,L15,M15,N15,O15,P15,Q15,R15,S15,T15,U15,V15,W15) | D15: =O24 | E15: =O25 | F15: =O26 | G15: =O27 | H15: =O28 | I15: =O29 | J15: =O30 | K15: =O31 | L15: =O32 | M15: =O33 | N15: =O34 | O15: =O35 | P15: =O36 | Q15: =O37 | R15: =O38 | S15: =O39 | T15: =O40 | U15: =O41 | V15: =O42 | W15: =O43
A16: 13 | B16: 提取任意盈余公积金 | C16: =SUM(D16,E16,F16,G16,H16,I16,J16,K16,L16,M16,N16,O16,P16,Q16,R16,S16,T16,U16,V16,W16) | D16: =P24 | E16: =P25 | F16: =P26 | G16: =P27 | H16: =P28 | I16: =P29 | J16: =P30 | K16: =P31 | L16: =P32 | M16: =P33 | N16: =P34 | O16: =P35 | P16: =P36 | Q16: =P37 | R16: =P38 | S16: =P39 | T16: =P40 | U16: =P41 | V16: =P42 | W16: =P43
A17: 14 | B17: 投资各方利润分配 | C17: =SUM(D17,E17,F17,G17,H17,I17,J17,K17,L17,M17,N17,O17,P17,Q17,R17,S17,T17,U17,V17,W17) | D17: =Q24 | E17: =Q25 | F17: =Q26 | G17: =Q27 | H17: =Q28 | I17: =Q29 | J17: =Q30 | K17: =Q31 | L17: =Q32 | M17: =Q33 | N17: =Q34 | O17: =Q35 | P17: =Q36 | Q17: =Q37 | R17: =Q38 | S17: =Q39 | T17: =Q40 | U17: =Q41 | V17: =Q42 | W17: =Q43
A18: 15 | B18: 未分配利润 | C18: =SUM(D18,E18,F18,G18,H18,I18,J18,K18,L18,M18,N18,O18,P18,Q18,R18,S18,T18,U18,V18,W18) | D18: =R24 | E18: =R25 | F18: =R26 | G18: =R27 | H18: =R28 | I18: =R29 | J18: =R30 | K18: =R31 | L18: =R32 | M18: =R33 | N18: =R34 | O18: =R35 | P18: =R36 | Q18: =R37 | R18: =R38 | S18: =R39 | T18: =R40 | U18: =R41 | V18: =R42 | W18: =R43
A19: 16 | B19: 息税前利润（EBIT） | C19: =SUM(D19,E19,F19,G19,H19,I19,J19,K19,L19,M19,N19,O19,P19,Q19,R19,S19,T19,U19,V19,W19) | D19: =F24 | E19: =F25 | F19: =F26 | G19: =F27 | H19: =F28 | I19: =F29 | J19: =F30 | K19: =F31 | L19: =F32 | M19: =F33 | N19: =F34 | O19: =F35 | P19: =F36 | Q19: =F37 | R19: =F38 | S19: =F39 | T19: =F40 | U19: =F41 | V19: =F42 | W19: =F43
A20: 17 | B20: 息税折旧摊销前利润（EBITDA） | C20: =SUM(D20,E20,F20,G20,H20,I20,J20,K20,L20,M20,N20,O20,P20,Q20,R20,S20,T20,U20,V20,W20) | D20: =G24 | E20: =G25 | F20: =G26 | G20: =G27 | H20: =G28 | I20: =G29 | J20: =G30 | K20: =G31 | L20: =G32 | M20: =G33 | N20: =G34 | O20: =G35 | P20: =G36 | Q20: =G37 | R20: =G38 | S20: =G39 | T20: =G40 | U20: =G41 | V20: =G42 | W20: =G43
A22: 引擎逐年计算区（供公式与跨表追溯）
A23: 运营年 | B23: 营业收入 | C23: 总成本费用 | D23: 税金及附加 | E23: 利润总额 | F23: 息税前利润(EBIT) | G23: 息税折旧摊销前利润(EBITDA) | H23: 弥补以前年度亏损 | I23: 应纳税所得额 | J23: 所得税 | K23: 净利润 | L23: 期初未分配利润 | M23: 可供分配的利润 | N23: 提取法定盈余公积金 | O23: 可供投资者分配的利润 | P23: 提取任意盈余公积金 | Q23: 投资各方利润分配 | R23: 未分配利润
A24: 1 | B24: ='附表5'!B22 | C24: ='附表6'!F17 | D24: ='附表5'!E22 | E24: =B24-C24-D24 | F24: =E24+'附表6'!E17 | G24: =F24+'附表6'!C17+'附表6'!D17 | H24: 0 | I24: =MAX(E24-H24,0) | J24: 277.4 | K24: =E24-J24 | L24: 0 | M24: =L24+K24 | N24: =MAX(K24,0)*10% | O24: =M24-N24 | R24: =O24-N(P24)-N(Q24)
A25: 2 | B25: ='附表5'!B23 | C25: ='附表6'!F18 | D25: ='附表5'!E23 | E25: =B25-C25-D25 | F25: =E25+'附表6'!E18 | G25: =F25+'附表6'!C18+'附表6'!D18 | H25: 0 | I25: =MAX(E25-H25,0) | J25: 588.25 | K25: =E25-J25 | L25: =R24 | M25: =L25+K25 | N25: =MAX(K25,0)*10% | O25: =M25-N25 | R25: =O25-N(P25)-N(Q25)
A26: 3 | B26: ='附表5'!B24 | C26: ='附表6'!F19 | D26: ='附表5'!E24 | E26: =B26-C26-D26 | F26: =E26+'附表6'!E19 | G26: =F26+'附表6'!C19+'附表6'!D19 | H26: 0 | I26: =MAX(E26-H26,0) | J26: 824.77 | K26: =E26-J26 | L26: =R25 | M26: =L26+K26 | N26: =MAX(K26,0)*10% | O26: =M26-N26 | R26: =O26-N(P26)-N(Q26)
A27: 4 | B27: ='附表5'!B25 | C27: ='附表6'!F20 | D27: ='附表5'!E25 | E27: =B27-C27-D27 | F27: =E27+'附表6'!E20 | G27: =F27+'附表6'!C20+'附表6'!D20 | H27: 0 | I27: =MAX(E27-H27,0) | J27: 1061.3 | K27: =E27-J27 | L27: =R26 | M27: =L27+K27 | N27: =MAX(K27,0)*10% | O27: =M27-N27 | R27: =O27-N(P27)-N(Q27)
A28: 5 | B28: ='附表5'!B26 | C28: ='附表6'!F21 | D28: ='附表5'!E26 | E28: =B28-C28-D28 | F28: =E28+'附表6'!E21 | G28: =F28+'附表6'!C21+'附表6'!D21 | H28: 0 | I28: =MAX(E28-H28,0) | J28: 1074.8 | K28: =E28-J28 | L28: =R27 | M28: =L28+K28 | N28: =MAX(K28,0)*10% | O28: =M28-N28 | R28: =O28-N(P28)-N(Q28)
A29: 6 | B29: ='附表5'!B27 | C29: ='附表6'!F22 | D29: ='附表5'!E27 | E29: =B29-C29-D29 | F29: =E29+'附表6'!E22 | G29: =F29+'附表6'!C22+'附表6'!D22 | H29: 0 | I29: =MAX(E29-H29,0) | J29: 1088.3 | K29: =E29-J29 | L29: =R28 | M29: =L29+K29 | N29: =MAX(K29,0)*10% | O29: =M29-N29 | R29: =O29-N(P29)-N(Q29)
A30: 7 | B30: ='附表5'!B28 | C30: ='附表6'!F23 | D30: ='附表5'!E28 | E30: =B30-C30-D30 | F30: =E30+'附表6'!E23 | G30: =F30+'附表6'!C23+'附表6'!D23 | H30: 0 | I30: =MAX(E30-H30,0) | J30: 1101.8 | K30: =E30-J30 | L30: =R29 | M30: =L30+K30 | N30: =MAX(K30,0)*10% | O30: =M30-N30 | R30: =O30-N(P30)-N(Q30)
A31: 8 | B31: ='附表5'!B29 | C31: ='附表6'!F24 | D31: ='附表5'!E29 | E31: =B31-C31-D31 | F31: =E31+'附表6'!E24 | G31: =F31+'附表6'!C24+'附表6'!D24 | H31: 0 | I31: =MAX(E31-H31,0) | J31: 1115.3 | K31: =E31-J31 | L31: =R30 | M31: =L31+K31 | N31: =MAX(K31,0)*10% | O31: =M31-N31 | R31: =O31-N(P31)-N(Q31)
A32: 9 | B32: ='附表5'!B30 | C32: ='附表6'!F25 | D32: ='附表5'!E30 | E32: =B32-C32-D32 | F32: =E32+'附表6'!E25 | G32: =F32+'附表6'!C25+'附表6'!D25 | H32: 0 | I32: =MAX(E32-H32,0) | J32: 1128.8 | K32: =E32-J32 | L32: =R31 | M32: =L32+K32 | N32: =MAX(K32,0)*10% | O32: =M32-N32 | R32: =O32-N(P32)-N(Q32)
A33: 10 | B33: ='附表5'!B31 | C33: ='附表6'!F26 | D33: ='附表5'!E31 | E33: =B33-C33-D33 | F33: =E33+'附表6'!E26 | G33: =F33+'附表6'!C26+'附表6'!D26 | H33: 0 | I33: =MAX(E33-H33,0) | J33: 1142.3 | K33: =E33-J33 | L33: =R32 | M33: =L33+K33 | N33: =MAX(K33,0)*10% | O33: =M33-N33 | R33: =O33-N(P33)-N(Q33)
A34: 11 | B34: ='附表5'!B32 | C34: ='附表6'!F27 | D34: ='附表5'!E32 | E34: =B34-C34-D34 | F34: =E34+'附表6'!E27 | G34: =F34+'附表6'!C27+'附表6'!D27 | H34: 0 | I34: =MAX(E34-H34,0) | J34: 1155.8 | K34: =E34-J34 | L34: =R33 | M34: =L34+K34 | N34: =MAX(K34,0)*10% | O34: =M34-N34 | R34: =O34-N(P34)-N(Q34)
A35: 12 | B35: ='附表5'!B33 | C35: ='附表6'!F28 | D35: ='附表5'!E33 | E35: =B35-C35-D35 | F35: =E35+'附表6'!E28 | G35: =F35+'附表6'!C28+'附表6'!D28 | H35: 0 | I35: =MAX(E35-H35,0) | J35: 1169.3 | K35: =E35-J35 | L35: =R34 | M35: =L35+K35 | N35: =MAX(K35,0)*10% | O35: =M35-N35 | R35: =O35-N(P35)-N(Q35)
A36: 13 | B36: ='附表5'!B34 | C36: ='附表6'!F29 | D36: ='附表5'!E34 | E36: =B36-C36-D36 | F36: =E36+'附表6'!E29 | G36: =F36+'附表6'!C29+'附表6'!D29 | H36: 0 | I36: =MAX(E36-H36,0) | J36: 1182.8 | K36: =E36-J36 | L36: =R35 | M36: =L36+K36 | N36: =MAX(K36,0)*10% | O36: =M36-N36 | R36: =O36-N(P36)-N(Q36)
... A43: 20 | B43: ='附表5'!B41 | C43: ='附表6'!F36 | D43: ='附表5'!E41 | E43: =B43-C43-D43 | F43: =E43+'附表6'!E36 | G43: =F43+'附表6'!C36+'附表6'!D36 | H43: 0 | I43: =MAX(E43-H43,0) | J43: 1182.8 | K43: =E43-J43 | L43: =R42 | M43: =L43+K43 | N43: =MAX(K43,0)*10% | O43: =M43-N43 | R43: =O43-N(P43)-N(Q43)
A44: 说明1：structure_gaps: 行业变体未冻结(variant=tourism, model=tourism)
A45: 跨表依赖复核：附表5 | B45: ='附表5'!A22
A46: 跨表依赖复核：附表6 | B46: ='附表6'!A17
A47: 跨表依赖复核：附表6-2 | B47: ='附表6-2'!A8
...

Sheet 附表8
A1: 附表8 还款付息测算表
A2: 计算状态：computed；口径：summary；有效：是
A3: 序号 | B3: 项目 | C3: 合计 | D3: 分年1 | E3: 分年2 | F3: 分年3 | G3: 分年4 | H3: 分年5 | I3: 分年6 | J3: 分年7 | K3: 分年8 | L3: 分年9 | M3: 分年10 | N3: 分年11 | O3: 分年12 | P3: 分年13 | Q3: 分年14 | R3: 分年15 | S3: 分年16 | T3: 分年17 | U3: 分年18 | V3: 分年19 | W3: 分年20
A4: 1 | B4: 期初借款余额 | C4: =W4 | D4: =B24 | E4: =B25 | F4: =B26 | G4: =B27 | H4: =B28 | I4: =B29 | J4: =B30 | K4: =B31 | L4: =B32 | M4: =B33 | N4: =B34 | O4: =B35 | P4: =B36 | Q4: =B37 | R4: =B38 | S4: =B39 | T4: =B40 | U4: =B41 | V4: =B42 | W4: =B43
A5: 2 | B5: 本年借款 | C5: =SUM(D5,E5,F5,G5,H5,I5,J5,K5,L5,M5,N5,O5,P5,Q5,R5,S5,T5,U5,V5,W5) | D5: =C24 | E5: =C25 | F5: =C26 | G5: =C27 | H5: =C28 | I5: =C29 | J5: =C30 | K5: =C31 | L5: =C32 | M5: =C33 | N5: =C34 | O5: =C35 | P5: =C36 | Q5: =C37 | R5: =C38 | S5: =C39 | T5: =C40 | U5: =C41 | V5: =C42 | W5: =C43
A6: 3 | B6: 当期还本付息 | C6: =SUM(D6,E6,F6,G6,H6,I6,J6,K6,L6,M6,N6,O6,P6,Q6,R6,S6,T6,U6,V6,W6) | D6: =G24 | E6: =G25 | F6: =G26 | G6: =G27 | H6: =G28 | I6: =G29 | J6: =G30 | K6: =G31 | L6: =G32 | M6: =G33 | N6: =G34 | O6: =G35 | P6: =G36 | Q6: =G37 | R6: =G38 | S6: =G39 | T6: =G40 | U6: =G41 | V6: =G42 | W6: =G43
A7: 3.1 | B7: 还本 | C7: =SUM(D7,E7,F7,G7,H7,I7,J7,K7,L7,M7,N7,O7,P7,Q7,R7,S7,T7,U7,V7,W7) | D7: =E24 | E7: =E25 | F7: =E26 | G7: =E27 | H7: =E28 | I7: =E29 | J7: =E30 | K7: =E31 | L7: =E32 | M7: =E33 | N7: =E34 | O7: =E35 | P7: =E36 | Q7: =E37 | R7: =E38 | S7: =E39 | T7: =E40 | U7: =E41 | V7: =E42 | W7: =E43
A8: 3.2 | B8: 付息 | C8: =SUM(D8,E8,F8,G8,H8,I8,J8,K8,L8,M8,N8,O8,P8,Q8,R8,S8,T8,U8,V8,W8) | D8: =F24 | E8: =F25 | F8: =F26 | G8: =F27 | H8: =F28 | I8: =F29 | J8: =F30 | K8: =F31 | L8: =F32 | M8: =F33 | N8: =F34 | O8: =F35 | P8: =F36 | Q8: =F37 | R8: =F38 | S8: =F39 | T8: =F40 | U8: =F41 | V8: =F42 | W8: =F43
A9: 4 | B9: 期末借款余额 | C9: =W9 | D9: =H24 | E9: =H25 | F9: =H26 | G9: =H27 | H9: =H28 | I9: =H29 | J9: =H30 | K9: =H31 | L9: =H32 | M9: =H33 | N9: =H34 | O9: =H35 | P9: =H36 | Q9: =H37 | R9: =H38 | S9: =H39 | T9: =H40 | U9: =H41 | V9: =H42 | W9: =H43
A10: 5 | B10: 偿债资金来源（可用） | C10: 0 | D10: 0 | E10: 0 | F10: 0 | G10: 0 | H10: 0 | I10: 0 | J10: 0 | K10: 0 | L10: 0 | M10: 0 | N10: 0 | O10: 0 | P10: 0 | Q10: 0 | R10: 0 | S10: 0 | T10: 0 | U10: 0 | V10: 0 | W10: 0
A11: 5.1 | B11: 可供投资者分配的利润 | C11: =SUM(D11,E11,F11,G11,H11,I11,J11,K11,L11,M11,N11,O11,P11,Q11,R11,S11,T11,U11,V11,W11) | D11: =I24 | E11: =I25 | F11: =I26 | G11: =I27 | H11: =I28 | I11: =I29 | J11: =I30 | K11: =I31 | L11: =I32 | M11: =I33 | N11: =I34 | O11: =I35 | P11: =I36 | Q11: =I37 | R11: =I38 | S11: =I39 | T11: =I40 | U11: =I41 | V11: =I42 | W11: =I43
A12: 5.2 | B12: 折旧费 | C12: =SUM(D12,E12,F12,G12,H12,I12,J12,K12,L12,M12,N12,O12,P12,Q12,R12,S12,T12,U12,V12,W12) | D12: =J24 | E12: =J25 | F12: =J26 | G12: =J27 | H12: =J28 | I12: =J29 | J12: =J30 | K12: =J31 | L12: =J32 | M12: =J33 | N12: =J34 | O12: =J35 | P12: =J36 | Q12: =J37 | R12: =J38 | S12: =J39 | T12: =J40 | U12: =J41 | V12: =J42 | W12: =J43
A13: 5.3 | B13: 摊销费 | C13: =SUM(D13,E13,F13,G13,H13,I13,J13,K13,L13,M13,N13,O13,P13,Q13,R13,S13,T13,U13,V13,W13) | D13: =K24 | E13: =K25 | F13: =K26 | G13: =K27 | H13: =K28 | I13: =K29 | J13: =K30 | K13: =K31 | L13: =K32 | M13: =K33 | N13: =K34 | O13: =K35 | P13: =K36 | Q13: =K37 | R13: =K38 | S13: =K39 | T13: =K40 | U13: =K41 | V13: =K42 | W13: =K43
A14: 6 | B14: 实际用于偿债的资金 | C14: 0 | D14: 0 | E14: 0 | F14: 0 | G14: 0 | H14: 0 | I14: 0 | J14: 0 | K14: 0 | L14: 0 | M14: 0 | N14: 0 | O14: 0 | P14: 0 | Q14: 0 | R14: 0 | S14: 0 | T14: 0 | U14: 0 | V14: 0 | W14: 0
A15: 6.1 | B15: 实际使用利润 | C15: 0 | D15: 0 | E15: 0 | F15: 0 | G15: 0 | H15: 0 | I15: 0 | J15: 0 | K15: 0 | L15: 0 | M15: 0 | N15: 0 | O15: 0 | P15: 0 | Q15: 0 | R15: 0 | S15: 0 | T15: 0 | U15: 0 | V15: 0 | W15: 0
A16: 6.2 | B16: 实际使用折旧 | C16: 0 | D16: 0 | E16: 0 | F16: 0 | G16: 0 | H16: 0 | I16: 0 | J16: 0 | K16: 0 | L16: 0 | M16: 0 | N16: 0 | O16: 0 | P16: 0 | Q16: 0 | R16: 0 | S16: 0 | T16: 0 | U16: 0 | V16: 0 | W16: 0
A17: 6.3 | B17: 实际使用摊销 | C17: 0 | D17: 0 | E17: 0 | F17: 0 | G17: 0 | H17: 0 | I17: 0 | J17: 0 | K17: 0 | L17: 0 | M17: 0 | N17: 0 | O17: 0 | P17: 0 | Q17: 0 | R17: 0 | S17: 0 | T17: 0 | U17: 0 | V17: 0 | W17: 0
A18: 7 | B18: 偿债后剩余资金 | C18: 0 | D18: 0 | E18: 0 | F18: 0 | G18: 0 | H18: 0 | I18: 0 | J18: 0 | K18: 0 | L18: 0 | M18: 0 | N18: 0 | O18: 0 | P18: 0 | Q18: 0 | R18: 0 | S18: 0 | T18: 0 | U18: 0 | V18: 0 | W18: 0
A19: 8 | B19: 利息备付率（ICR） | C19: =W19 | D19: =M24 | E19: =M25 | F19: =M26 | G19: =M27 | H19: =M28 | I19: =M29 | J19: =M30 | K19: =M31 | L19: =M32 | M19: =M33 | N19: =M34 | O19: =M35 | P19: =M36 | Q19: =M37 | R19: =M38 | S19: =M39 | T19: =M40 | U19: =M41 | V19: =M42 | W19: =M43
A20: 9 | B20: 偿债备付率（DSCR） | C20: =W20 | D20: =L24 | E20: =L25 | F20: =L26 | G20: =L27 | H20: =L28 | I20: =L29 | J20: =L30 | K20: =L31 | L20: =L32 | M20: =L33 | N20: =L34 | O20: =L35 | P20: =L36 | Q20: =L37 | R20: =L38 | S20: =L39 | T20: =L40 | U20: =L41 | V20: =L42 | W20: =L43
A22: 引擎逐年计算区（供公式与跨表追溯）
A23: 运营年 | B23: 期初借款余额 | C23: 本年借款 | D23: 年利率(%) | E23: 当期还本 | F23: 当期付息 | G23: 当期还本付息 | H23: 期末借款余额 | I23: 偿债资金来源-利润 | J23: 偿债资金来源-折旧费 | K23: 偿债资金来源-摊销费 | L23: 偿债备付率(DSCR) | M23: 利息备付率(ICR)
A24: 1 | B24: 14400 | D24: 0.045 | E24: 1200 | F24: =B24*D24 | G24: =E24+F24 | H24: =MAX(B24-E24,0) | L24: =IF(G24>0,SUM(I24,J24,K24)/G24,"") | M24: =IF(F24>0,'附表7'!F24/F24,"")
A25: 2 | B25: =H24 | D25: 0.045 | E25: 1200 | F25: =B25*D25 | G25: =E25+F25 | H25: =MAX(B25-E25,0) | L25: =IF(G25>0,SUM(I25,J25,K25)/G25,"") | M25: =IF(F25>0,'附表7'!F25/F25,"")
A26: 3 | B26: =H25 | D26: 0.045 | E26: 1200 | F26: =B26*D26 | G26: =E26+F26 | H26: =MAX(B26-E26,0) | L26: =IF(G26>0,SUM(I26,J26,K26)/G26,"") | M26: =IF(F26>0,'附表7'!F26/F26,"")
A27: 4 | B27: =H26 | D27: 0.045 | E27: 1200 | F27: =B27*D27 | G27: =E27+F27 | H27: =MAX(B27-E27,0) | L27: =IF(G27>0,SUM(I27,J27,K27)/G27,"") | M27: =IF(F27>0,'附表7'!F27/F27,"")
A28: 5 | B28: =H27 | D28: 0.045 | E28: 1200 | F28: =B28*D28 | G28: =E28+F28 | H28: =MAX(B28-E28,0) | L28: =IF(G28>0,SUM(I28,J28,K28)/G28,"") | M28: =IF(F28>0,'附表7'!F28/F28,"")
A29: 6 | B29: =H28 | D29: 0.045 | E29: 1200 | F29: =B29*D29 | G29: =E29+F29 | H29: =MAX(B29-E29,0) | L29: =IF(G29>0,SUM(I29,J29,K29)/G29,"") | M29: =IF(F29>0,'附表7'!F29/F29,"")
A30: 7 | B30: =H29 | D30: 0.045 | E30: 1200 | F30: =B30*D30 | G30: =E30+F30 | H30: =MAX(B30-E30,0) | L30: =IF(G30>0,SUM(I30,J30,K30)/G30,"") | M30: =IF(F30>0,'附表7'!F30/F30,"")
A31: 8 | B31: =H30 | D31: 0.045 | E31: 1200 | F31: =B31*D31 | G31: =E31+F31 | H31: =MAX(B31-E31,0) | L31: =IF(G31>0,SUM(I31,J31,K31)/G31,"") | M31: =IF(F31>0,'附表7'!F31/F31,"")
A32: 9 | B32: =H31 | D32: 0.045 | E32: 1200 | F32: =B32*D32 | G32: =E32+F32 | H32: =MAX(B32-E32,0) | L32: =IF(G32>0,SUM(I32,J32,K32)/G32,"") | M32: =IF(F32>0,'附表7'!F32/F32,"")
A33: 10 | B33: =H32 | D33: 0.045 | E33: 1200 | F33: =B33*D33 | G33: =E33+F33 | H33: =MAX(B33-E33,0) | L33: =IF(G33>0,SUM(I33,J33,K33)/G33,"") | M33: =IF(F33>0,'附表7'!F33/F33,"")
A34: 11 | B34: =H33 | D34: 0.045 | E34: 1200 | F34: =B34*D34 | G34: =E34+F34 | H34: =MAX(B34-E34,0) | L34: =IF(G34>0,SUM(I34,J34,K34)/G34,"") | M34: =IF(F34>0,'附表7'!F34/F34,"")
A35: 12 | B35: =H34 | D35: 0.045 | E35: 1200 | F35: =B35*D35 | G35: =E35+F35 | H35: =MAX(B35-E35,0) | L35: =IF(G35>0,SUM(I35,J35,K35)/G35,"") | M35: =IF(F35>0,'附表7'!F35/F35,"")
A36: 13 | B36: =H35 | D36: 0.045 | E36: 0 | F36: =B36*D36 | G36: =E36+F36 | H36: =MAX(B36-E36,0) | L36: =IF(G36>0,SUM(I36,J36,K36)/G36,"") | M36: =IF(F36>0,'附表7'!F36/F36,"")
... A43: 20 | B43: =H42 | D43: 0.045 | E43: 0 | F43: =B43*D43 | G43: =E43+F43 | H43: =MAX(B43-E43,0) | L43: =IF(G43>0,SUM(I43,J43,K43)/G43,"") | M43: =IF(F43>0,'附表7'!F43/F43,"")
A44: 说明1：structure_gaps: 偿债资金来源未绑定 confirmed fact_pack 明细；禁止默认 75% 伪造；偿债资金来源的利润/折旧/摊销年度金额不完整；可用偿债资金合计不足以覆盖各年还本额；偿债来源父子不勾稽：可用/实际/剩余三组父子恒等式失败
A45: 跨表依赖复核：附表2 | B45: ='附表2'!A14
A46: 跨表依赖复核：附表6 | B46: ='附表6'!A17
A47: 跨表依赖复核：附表7 | B47: ='附表7'!A24

Sheet 附表9
A1: 附表9 项目投资现金流量表
A2: 计算状态：computed；口径：summary；有效：是
A3: 序号 | B3: 项目 | C3: 合计 | D3: 计算期0 | E3: 计算期1 | F3: 计算期2 | G3: 计算期3 | H3: 计算期4 | I3: 计算期5 | J3: 计算期6 | K3: 计算期7 | L3: 计算期8 | M3: 计算期9 | N3: 计算期10 | O3: 计算期11 | P3: 计算期12 | Q3: 计算期13 | R3: 计算期14 | S3: 计算期15 | T3: 计算期16 | U3: 计算期17 | V3: 计算期18 | W3: 计算期19 | X3: 计算期20 | Y3: 计算期21
A4: 1 | B4: 现金流入
A5: 1.1 | B5: 营业收入 | C5: =SUM(D5,E5,F5,G5,H5,I5,J5,K5,L5,M5,N5,O5,P5,Q5,R5,S5,T5,U5,V5,W5,X5,Y5) | D5: =C20 | E5: =C21 | F5: =C22 | G5: =C23 | H5: =C24 | I5: =C25 | J5: =C26 | K5: =C27 | L5: =C28 | M5: =C29 | N5: =C30 | O5: =C31 | P5: =C32 | Q5: =C33 | R5: =C34 | S5: =C35 | T5: =C36 | U5: =C37 | V5: =C38 | W5: =C39 | X5: =C40 | Y5: =C41
A6: 1.2 | B6: 回收固定资产余值 | C6: 7680 | D6: 0 | E6: 0 | F6: 0 | G6: 0 | H6: 0 | I6: 0 | J6: 0 | K6: 0 | L6: 0 | M6: 0 | N6: 0 | O6: 0 | P6: 0 | Q6: 0 | R6: 0 | S6: 0 | T6: 0 | U6: 0 | V6: 0 | W6: 0 | X6: 0 | Y6: 7680
A7: 1.3 | B7: 回收新增流动资金 | C7: 0 | D7: 0 | E7: 0 | F7: 0 | G7: 0 | H7: 0 | I7: 0 | J7: 0 | K7: 0 | L7: 0 | M7: 0 | N7: 0 | O7: 0 | P7: 0 | Q7: 0 | R7: 0 | S7: 0 | T7: 0 | U7: 0 | V7: 0 | W7: 0 | X7: 0 | Y7: 0
A8: 2 | B8: 现金流出
A9: 2.1 | B9: 固定资产投资 | C9: =SUM(D9,E9,F9,G9,H9,I9,J9,K9,L9,M9,N9,O9,P9,Q9,R9,S9,T9,U9,V9,W9,X9,Y9) | D9: =G20 | E9: =G21 | F9: =G22 | G9: =G23 | H9: =G24 | I9: =G25 | J9: =G26 | K9: =G27 | L9: =G28 | M9: =G29 | N9: =G30 | O9: =G31 | P9: =G32 | Q9: =G33 | R9: =G34 | S9: =G35 | T9: =G36 | U9: =G37 | V9: =G38 | W9: =G39 | X9: =G40 | Y9: =G41
A10: 2.2 | B10: 新增铺底流动资金 | C10: =SUM(D10,E10,F10,G10,H10,I10,J10,K10,L10,M10,N10,O10,P10,Q10,R10,S10,T10,U10,V10,W10,X10,Y10) | D10: =H20 | E10: =H21 | F10: =H22 | G10: =H23 | H10: =H24 | I10: =H25 | J10: =H26 | K10: =H27 | L10: =H28 | M10: =H29 | N10: =H30 | O10: =H31 | P10: =H32 | Q10: =H33 | R10: =H34 | S10: =H35 | T10: =H36 | U10: =H37 | V10: =H38 | W10: =H39 | X10: =H40 | Y10: =H41
A11: 2.3 | B11: 经营成本 | C11: =SUM(D11,E11,F11,G11,H11,I11,J11,K11,L11,M11,N11,O11,P11,Q11,R11,S11,T11,U11,V11,W11,X11,Y11) | D11: =D20 | E11: =D21 | F11: =D22 | G11: =D23 | H11: =D24 | I11: =D25 | J11: =D26 | K11: =D27 | L11: =D28 | M11: =D29 | N11: =D30 | O11: =D31 | P11: =D32 | Q11: =D33 | R11: =D34 | S11: =D35 | T11: =D36 | U11: =D37 | V11: =D38 | W11: =D39 | X11: =D40 | Y11: =D41
A12: 2.4 | B12: 营业税金及附加 | C12: =SUM(D12,E12,F12,G12,H12,I12,J12,K12,L12,M12,N12,O12,P12,Q12,R12,S12,T12,U12,V12,W12,X12,Y12) | D12: =E20 | E12: =E21 | F12: =E22 | G12: =E23 | H12: =E24 | I12: =E25 | J12: =E26 | K12: =E27 | L12: =E28 | M12: =E29 | N12: =E30 | O12: =E31 | P12: =E32 | Q12: =E33 | R12: =E34 | S12: =E35 | T12: =E36 | U12: =E37 | V12: =E38 | W12: =E39 | X12: =E40 | Y12: =E41
A13: 2.5 | B13: 所得税 | C13: =SUM(D13,E13,F13,G13,H13,I13,J13,K13,L13,M13,N13,O13,P13,Q13,R13,S13,T13,U13,V13,W13,X13,Y13) | D13: =F20 | E13: =F21 | F13: =F22 | G13: =F23 | H13: =F24 | I13: =F25 | J13: =F26 | K13: =F27 | L13: =F28 | M13: =F29 | N13: =F30 | O13: =F31 | P13: =F32 | Q13: =F33 | R13: =F34 | S13: =F35 | T13: =F36 | U13: =F37 | V13: =F38 | W13: =F39 | X13: =F40 | Y13: =F41
A14: 3 | B14: 所得税前净现金流量 | C14: 88973.77 | D14: -16000 | E14: -16000 | F14: 2973.59 | G14: 4163.02 | H14: 5055.1 | I14: 5947.18 | J14: 5947.18 | K14: 5947.18 | L14: 5947.18 | M14: 5947.18 | N14: 5947.18 | O14: 5947.18 | P14: 5947.18 | Q14: 5947.18 | R14: 5947.18 | S14: 5947.18 | T14: 5947.18 | U14: 5947.18 | V14: 5947.18 | W14: 5947.18 | X14: 5947.18 | Y14: 13627.18
A15: 4 | B15: 所得税后净现金流量 | C15: =SUM(D15,E15,F15,G15,H15,I15,J15,K15,L15,M15,N15,O15,P15,Q15,R15,S15,T15,U15,V15,W15,X15,Y15) | D15: =J20 | E15: =J21 | F15: =J22 | G15: =J23 | H15: =J24 | I15: =J25 | J15: =J26 | K15: =J27 | L15: =J28 | M15: =J29 | N15: =J30 | O15: =J31 | P15: =J32 | Q15: =J33 | R15: =J34 | S15: =J35 | T15: =J36 | U15: =J37 | V15: =J38 | W15: =J39 | X15: =J40 | Y15: =J41
A16: 5 | B16: 累计所得税后净现金流量 | C16: =Y16 | D16: =K20 | E16: =K21 | F16: =K22 | G16: =K23 | H16: =K24 | I16: =K25 | J16: =K26 | K16: =K27 | L16: =K28 | M16: =K29 | N16: =K30 | O16: =K31 | P16: =K32 | Q16: =K33 | R16: =K34 | S16: =K35 | T16: =K36 | U16: =K37 | V16: =K38 | W16: =K39 | X16: =K40 | Y16: =K41
A18: 引擎逐年计算区（供公式与跨表追溯）
A19: 计算期(年) | B19: 阶段 | C19: 营业收入 | D19: 经营成本 | E19: 税金及附加 | F19: 调整所得税 | G19: 建设投资(含建设期利息) | H19: 流动资金增加 | I19: 回收(流资+余值) | J19: 净现金流 | K19: 累计净现金流
A20: 0 | B20: 建设期 | C20: 0 | D20: 0 | E20: 0 | F20: 0 | G20: =SUM('附表1'!J4,'附表1'!J16,'附表1'!J22)*0.5 | H20: 0 | I20: 0 | J20: -16000 | K20: -16000
A21: 1 | B21: 建设期 | C21: 0 | D21: 0 | E21: 0 | F21: 0 | G21: =SUM('附表1'!J4,'附表1'!J16,'附表1'!J22)*0.5 | H21: 0 | I21: 0 | J21: -16000 | K21: -32000
A22: 2 | B22: 运营期 | C22: ='附表5'!B22 | D22: ='附表6'!B17 | E22: ='附表5'!E22 | F22: ='附表5'!I22 | G22: 0 | H22: ='附表3'!B4 | I22: 0 | J22: =C22-D22-E22-F22-G22-H22+I22 | K22: =K21+J22
A23: 3 | B23: 运营期 | C23: ='附表5'!B23 | D23: ='附表6'!B18 | E23: ='附表5'!E23 | F23: ='附表5'!I23 | G23: 0 | H23: 0 | I23: 0 | J23: =C23-D23-E23-F23-G23-H23+I23 | K23: =K22+J23
A24: 4 | B24: 运营期 | C24: ='附表5'!B24 | D24: ='附表6'!B19 | E24: ='附表5'!E24 | F24: ='附表5'!I24 | G24: 0 | H24: 0 | I24: 0 | J24: =C24-D24-E24-F24-G24-H24+I24 | K24: =K23+J24
A25: 5 | B25: 运营期 | C25: ='附表5'!B25 | D25: ='附表6'!B20 | E25: ='附表5'!E25 | F25: ='附表5'!I25 | G25: 0 | H25: 0 | I25: 0 | J25: =C25-D25-E25-F25-G25-H25+I25 | K25: =K24+J25
A26: 6 | B26: 运营期 | C26: ='附表5'!B26 | D26: ='附表6'!B21 | E26: ='附表5'!E26 | F26: ='附表5'!I26 | G26: 0 | H26: 0 | I26: 0 | J26: =C26-D26-E26-F26-G26-H26+I26 | K26: =K25+J26
A27: 7 | B27: 运营期 | C27: ='附表5'!B27 | D27: ='附表6'!B22 | E27: ='附表5'!E27 | F27: ='附表5'!I27 | G27: 0 | H27: 0 | I27: 0 | J27: =C27-D27-E27-F27-G27-H27+I27 | K27: =K26+J27
A28: 8 | B28: 运营期 | C28: ='附表5'!B28 | D28: ='附表6'!B23 | E28: ='附表5'!E28 | F28: ='附表5'!I28 | G28: 0 | H28: 0 | I28: 0 | J28: =C28-D28-E28-F28-G28-H28+I28 | K28: =K27+J28
A29: 9 | B29: 运营期 | C29: ='附表5'!B29 | D29: ='附表6'!B24 | E29: ='附表5'!E29 | F29: ='附表5'!I29 | G29: 0 | H29: 0 | I29: 0 | J29: =C29-D29-E29-F29-G29-H29+I29 | K29: =K28+J29
A30: 10 | B30: 运营期 | C30: ='附表5'!B30 | D30: ='附表6'!B25 | E30: ='附表5'!E30 | F30: ='附表5'!I30 | G30: 0 | H30: 0 | I30: 0 | J30: =C30-D30-E30-F30-G30-H30+I30 | K30: =K29+J30
A31: 11 | B31: 运营期 | C31: ='附表5'!B31 | D31: ='附表6'!B26 | E31: ='附表5'!E31 | F31: ='附表5'!I31 | G31: 0 | H31: 0 | I31: 0 | J31: =C31-D31-E31-F31-G31-H31+I31 | K31: =K30+J31
A32: 12 | B32: 运营期 | C32: ='附表5'!B32 | D32: ='附表6'!B27 | E32: ='附表5'!E32 | F32: ='附表5'!I32 | G32: 0 | H32: 0 | I32: 0 | J32: =C32-D32-E32-F32-G32-H32+I32 | K32: =K31+J32
A33: 13 | B33: 运营期 | C33: ='附表5'!B33 | D33: ='附表6'!B28 | E33: ='附表5'!E33 | F33: ='附表5'!I33 | G33: 0 | H33: 0 | I33: 0 | J33: =C33-D33-E33-F33-G33-H33+I33 | K33: =K32+J33
A34: 14 | B34: 运营期 | C34: ='附表5'!B34 | D34: ='附表6'!B29 | E34: ='附表5'!E34 | F34: ='附表5'!I34 | G34: 0 | H34: 0 | I34: 0 | J34: =C34-D34-E34-F34-G34-H34+I34 | K34: =K33+J34
... A41: 21 | B41: 运营期 | C41: ='附表5'!B41 | D41: ='附表6'!B36 | E41: ='附表5'!E41 | F41: ='附表5'!I41 | G41: 0 | H41: 0 | I41: 7680 | J41: =C41-D41-E41-F41-G41-H41+I41 | K41: =K40+J41
A42: 说明1：建设投资列含建设期利息（与项目 CF 同源）
A43: 说明2：structure_gaps: 行业变体未冻结(variant=tourism, model=tourism)
A45: 现金流量组成树
A46: 项目 | B46: 0 | C46: 1 | D46: 2 | E46: 3 | F46: 4 | G46: 5 | H46: 6 | I46: 7 | J46: 8 | K46: 9 | L46: 10 | M46: 11 | N46: 12 | O46: 13 | P46: 14 | Q46: 15 | R46: 16 | S46: 17 | T46: 18 | U46: 19 | V46: 20 | W46: 21
A47: 现金流入
A48: revenue | B48: ='附表9'!C20 | C48: ='附表9'!C21 | D48: ='附表9'!C22 | E48: ='附表9'!C23 | F48: ='附表9'!C24 | G48: ='附表9'!C25 | H48: ='附表9'!C26 | I48: ='附表9'!C27 | J48: ='附表9'!C28 | K48: ='附表9'!C29 | L48: ='附表9'!C30 | M48: ='附表9'!C31 | N48: ='附表9'!C32 | O48: ='附表9'!C33 | P48: ='附表9'!C34 | Q48: ='附表9'!C35 | R48: ='附表9'!C36 | S48: ='附表9'!C37 | T48: ='附表9'!C38 | U48: ='附表9'!C39 | V48: ='附表9'!C40 | W48: ='附表9'!C41
...

Sheet 附表10
A1: 附表10 项目资本金流量表
A2: 计算状态：computed；口径：summary；有效：是
A3: 序号 | B3: 项目 | C3: 合计 | D3: 计算期0 | E3: 计算期1 | F3: 计算期2 | G3: 计算期3 | H3: 计算期4 | I3: 计算期5 | J3: 计算期6 | K3: 计算期7 | L3: 计算期8 | M3: 计算期9 | N3: 计算期10 | O3: 计算期11 | P3: 计算期12 | Q3: 计算期13 | R3: 计算期14 | S3: 计算期15 | T3: 计算期16 | U3: 计算期17 | V3: 计算期18 | W3: 计算期19 | X3: 计算期20 | Y3: 计算期21
A4: 1 | B4: 现金流入 | C4: =SUM(D4,E4,F4,G4,H4,I4,J4,K4,L4,M4,N4,O4,P4,Q4,R4,S4,T4,U4,V4,W4,X4,Y4) | D4: =J20 | E4: =J21 | F4: =J22 | G4: =J23 | H4: =J24 | I4: =J25 | J4: =J26 | K4: =J27 | L4: =J28 | M4: =J29 | N4: =J30 | O4: =J31 | P4: =J32 | Q4: =J33 | R4: =J34 | S4: =J35 | T4: =J36 | U4: =J37 | V4: =J38 | W4: =J39 | X4: =J40 | Y4: =J41
A5: 1.1 | B5: 营业收入 | C5: =SUM(D5,E5,F5,G5,H5,I5,J5,K5,L5,M5,N5,O5,P5,Q5,R5,S5,T5,U5,V5,W5,X5,Y5) | D5: =D20 | E5: =D21 | F5: =D22 | G5: =D23 | H5: =D24 | I5: =D25 | J5: =D26 | K5: =D27 | L5: =D28 | M5: =D29 | N5: =D30 | O5: =D31 | P5: =D32 | Q5: =D33 | R5: =D34 | S5: =D35 | T5: =D36 | U5: =D37 | V5: =D38 | W5: =D39 | X5: =D40 | Y5: =D41
A6: 1.2 | B6: 回收固定资产余值 | C6: =SUM(D6,E6,F6,G6,H6,I6,J6,K6,L6,M6,N6,O6,P6,Q6,R6,S6,T6,U6,V6,W6,X6,Y6) | D6: =E20 | E6: =E21 | F6: =E22 | G6: =E23 | H6: =E24 | I6: =E25 | J6: =E26 | K6: =E27 | L6: =E28 | M6: =E29 | N6: =E30 | O6: =E31 | P6: =E32 | Q6: =E33 | R6: =E34 | S6: =E35 | T6: =E36 | U6: =E37 | V6: =E38 | W6: =E39 | X6: =E40 | Y6: =E41
A7: 1.3 | B7: 回收流动资金 | C7: =SUM(D7,E7,F7,G7,H7,I7,J7,K7,L7,M7,N7,O7,P7,Q7,R7,S7,T7,U7,V7,W7,X7,Y7) | D7: =F20 | E7: =F21 | F7: =F22 | G7: =F23 | H7: =F24 | I7: =F25 | J7: =F26 | K7: =F27 | L7: =F28 | M7: =F29 | N7: =F30 | O7: =F31 | P7: =F32 | Q7: =F33 | R7: =F34 | S7: =F35 | T7: =F36 | U7: =F37 | V7: =F38 | W7: =F39 | X7: =F40 | Y7: =F41
A8: 2 | B8: 现金流出 | C8: =SUM(D8,E8,F8,G8,H8,I8,J8,K8,L8,M8,N8,O8,P8,Q8,R8,S8,T8,U8,V8,W8,X8,Y8) | D8: =K20 | E8: =K21 | F8: =K22 | G8: =K23 | H8: =K24 | I8: =K25 | J8: =K26 | K8: =K27 | L8: =K28 | M8: =K29 | N8: =K30 | O8: =K31 | P8: =K32 | Q8: =K33 | R8: =K34 | S8: =K35 | T8: =K36 | U8: =K37 | V8: =K38 | W8: =K39 | X8: =K40 | Y8: =K41
A9: 2.1 | B9: 项目资本金 | C9: =SUM(D9,E9,F9,G9,H9,I9,J9,K9,L9,M9,N9,O9,P9,Q9,R9,S9,T9,U9,V9,W9,X9,Y9) | D9: =C20 | E9: =C21 | F9: =C22 | G9: =C23 | H9: =C24 | I9: =C25 | J9: =C26 | K9: =C27 | L9: =C28 | M9: =C29 | N9: =C30 | O9: =C31 | P9: =C32 | Q9: =C33 | R9: =C34 | S9: =C35 | T9: =C36 | U9: =C37 | V9: =C38 | W9: =C39 | X9: =C40 | Y9: =C41
A10: 2.2 | B10: 借款本金偿还 | C10: =SUM(D10,E10,F10,G10,H10,I10,J10,K10,L10,M10,N10,O10,P10,Q10,R10,S10,T10,U10,V10,W10,X10,Y10) | D10: =M20 | E10: =M21 | F10: =M22 | G10: =M23 | H10: =M24 | I10: =M25 | J10: =M26 | K10: =M27 | L10: =M28 | M10: =M29 | N10: =M30 | O10: =M31 | P10: =M32 | Q10: =M33 | R10: =M34 | S10: =M35 | T10: =M36 | U10: =M37 | V10: =M38 | W10: =M39 | X10: =M40 | Y10: =M41
A11: 2.3 | B11: 借款利息支付 | C11: =SUM(D11,E11,F11,G11,H11,I11,J11,K11,L11,M11,N11,O11,P11,Q11,R11,S11,T11,U11,V11,W11,X11,Y11) | D11: =N20 | E11: =N21 | F11: =N22 | G11: =N23 | H11: =N24 | I11: =N25 | J11: =N26 | K11: =N27 | L11: =N28 | M11: =N29 | N11: =N30 | O11: =N31 | P11: =N32 | Q11: =N33 | R11: =N34 | S11: =N35 | T11: =N36 | U11: =N37 | V11: =N38 | W11: =N39 | X11: =N40 | Y11: =N41
A12: 2.4 | B12: 经营成本 | C12: =SUM(D12,E12,F12,G12,H12,I12,J12,K12,L12,M12,N12,O12,P12,Q12,R12,S12,T12,U12,V12,W12,X12,Y12) | D12: =G20 | E12: =G21 | F12: =G22 | G12: =G23 | H12: =G24 | I12: =G25 | J12: =G26 | K12: =G27 | L12: =G28 | M12: =G29 | N12: =G30 | O12: =G31 | P12: =G32 | Q12: =G33 | R12: =G34 | S12: =G35 | T12: =G36 | U12: =G37 | V12: =G38 | W12: =G39 | X12: =G40 | Y12: =G41
A13: 2.5 | B13: 税金及附加 | C13: =SUM(D13,E13,F13,G13,H13,I13,J13,K13,L13,M13,N13,O13,P13,Q13,R13,S13,T13,U13,V13,W13,X13,Y13) | D13: =H20 | E13: =H21 | F13: =H22 | G13: =H23 | H13: =H24 | I13: =H25 | J13: =H26 | K13: =H27 | L13: =H28 | M13: =H29 | N13: =H30 | O13: =H31 | P13: =H32 | Q13: =H33 | R13: =H34 | S13: =H35 | T13: =H36 | U13: =H37 | V13: =H38 | W13: =H39 | X13: =H40 | Y13: =H41
A14: 2.6 | B14: 所得税 | C14: =SUM(D14,E14,F14,G14,H14,I14,J14,K14,L14,M14,N14,O14,P14,Q14,R14,S14,T14,U14,V14,W14,X14,Y14) | D14: =I20 | E14: =I21 | F14: =I22 | G14: =I23 | H14: =I24 | I14: =I25 | J14: =I26 | K14: =I27 | L14: =I28 | M14: =I29 | N14: =I30 | O14: =I31 | P14: =I32 | Q14: =I33 | R14: =I34 | S14: =I35 | T14: =I36 | U14: =I37 | V14: =I38 | W14: =I39 | X14: =I40 | Y14: =I41
A15: 3 | B15: 资本金净现金流量 | C15: =SUM(D15,E15,F15,G15,H15,I15,J15,K15,L15,M15,N15,O15,P15,Q15,R15,S15,T15,U15,V15,W15,X15,Y15) | D15: =O20 | E15: =O21 | F15: =O22 | G15: =O23 | H15: =O24 | I15: =O25 | J15: =O26 | K15: =O27 | L15: =O28 | M15: =O29 | N15: =O30 | O15: =O31 | P15: =O32 | Q15: =O33 | R15: =O34 | S15: =O35 | T15: =O36 | U15: =O37 | V15: =O38 | W15: =O39 | X15: =O40 | Y15: =O41
A16: 4 | B16: 累计净现金流量 | C16: 62518.25 | D16: -8800 | E16: -17600 | F16: -16913.81 | G16: -15281.54 | H16: -12926.21 | I16: -9847.83 | J16: -6715.45 | K16: -3529.07 | L16: -288.69 | M16: 3005.69 | N16: 6354.07 | O16: 9756.45 | P16: 13212.83 | Q16: 16723.21 | R16: 21487.59 | S16: 26251.97 | T16: 31016.35 | U16: 35780.73 | V16: 40545.11 | W16: 45309.49 | X16: 50073.87 | Y16: 62518.25
A18: 引擎逐年计算区（供公式与跨表追溯）
A19: 计算期(年) | B19: 阶段 | C19: 资本金投入 | D19: 营业收入 | E19: 回收固定资产余值 | F19: 回收流动资金 | G19: 经营成本 | H19: 税金及附加 | I19: 所得税 | J19: 现金流入 | K19: 现金流出 | L19: 经营现金流入 | M19: 还本 | N19: 付息 | O19: 资本金净现金流
A20: 0 | B20: 建设期 | C20: 8800 | D20: 0 | E20: 0 | F20: 0 | G20: 0 | H20: 0 | I20: 0 | J20: =SUM(D20,E20,F20) | K20: =SUM(C20,G20,H20,I20,M20,N20) | L20: 0 | M20: 0 | N20: 0 | O20: =J20-K20
A21: 1 | B21: 建设期 | C21: 8800 | D21: 0 | E21: 0 | F21: 0 | G21: 0 | H21: 0 | I21: 0 | J21: =SUM(D21,E21,F21) | K21: =SUM(C21,G21,H21,I21,M21,N21) | L21: 0 | M21: 0 | N21: 0 | O21: =J21-K21
A22: 2 | B22: 运营期 | C22: 0 | D22: 5085 | E22: 0 | F22: 0 | G22: 2100 | H22: 11.41 | I22: 439.4 | J22: =SUM(D22,E22,F22) | K22: =SUM(C22,G22,H22,I22,M22,N22) | L22: 2534.19 | M22: ='附表8'!E24 | N22: ='附表8'!F24 | O22: =J22-K22
A23: 3 | B23: 运营期 | C23: 0 | D23: 7119 | E23: 0 | F23: 0 | G23: 2940 | H23: 15.98 | I23: 736.75 | J23: =SUM(D23,E23,F23) | K23: =SUM(C23,G23,H23,I23,M23,N23) | L23: 3426.27 | M23: ='附表8'!E25 | N23: ='附表8'!F25 | O23: =J23-K23
A24: 4 | B24: 运营期 | C24: 0 | D24: 8644.5 | E24: 0 | F24: 0 | G24: 3570 | H24: 19.4 | I24: 959.77 | J24: =SUM(D24,E24,F24) | K24: =SUM(C24,G24,H24,I24,M24,N24) | L24: 4095.33 | M24: ='附表8'!E26 | N24: ='附表8'!F26 | O24: =J24-K24
A25: 5 | B25: 运营期 | C25: 0 | D25: 10170 | E25: 0 | F25: 0 | G25: 4200 | H25: 22.82 | I25: 1182.8 | J25: =SUM(D25,E25,F25) | K25: =SUM(C25,G25,H25,I25,M25,N25) | L25: 4764.38 | M25: ='附表8'!E27 | N25: ='附表8'!F27 | O25: =J25-K25
A26: 6 | B26: 运营期 | C26: 0 | D26: 10170 | E26: 0 | F26: 0 | G26: 4200 | H26: 22.82 | I26: 1182.8 | J26: =SUM(D26,E26,F26) | K26: =SUM(C26,G26,H26,I26,M26,N26) | L26: 4764.38 | M26: ='附表8'!E28 | N26: ='附表8'!F28 | O26: =J26-K26
A27: 7 | B27: 运营期 | C27: 0 | D27: 10170 | E27: 0 | F27: 0 | G27: 4200 | H27: 22.82 | I27: 1182.8 | J27: =SUM(D27,E27,F27) | K27: =SUM(C27,G27,H27,I27,M27,N27) | L27: 4764.38 | M27: ='附表8'!E29 | N27: ='附表8'!F29 | O27: =J27-K27
A28: 8 | B28: 运营期 | C28: 0 | D28: 10170 | E28: 0 | F28: 0 | G28: 4200 | H28: 22.82 | I28: 1182.8 | J28: =SUM(D28,E28,F28) | K28: =SUM(C28,G28,H28,I28,M28,N28) | L28: 4764.38 | M28: ='附表8'!E30 | N28: ='附表8'!F30 | O28: =J28-K28
A29: 9 | B29: 运营期 | C29: 0 | D29: 10170 | E29: 0 | F29: 0 | G29: 4200 | H29: 22.82 | I29: 1182.8 | J29: =SUM(D29,E29,F29) | K29: =SUM(C29,G29,H29,I29,M29,N29) | L29: 4764.38 | M29: ='附表8'!E31 | N29: ='附表8'!F31 | O29: =J29-K29
A30: 10 | B30: 运营期 | C30: 0 | D30: 10170 | E30: 0 | F30: 0 | G30: 4200 | H30: 22.82 | I30: 1182.8 | J30: =SUM(D30,E30,F30) | K30: =SUM(C30,G30,H30,I30,M30,N30) | L30: 4764.38 | M30: ='附表8'!E32 | N30: ='附表8'!F32 | O30: =J30-K30
A31: 11 | B31: 运营期 | C31: 0 | D31: 10170 | E31: 0 | F31: 0 | G31: 4200 | H31: 22.82 | I31: 1182.8 | J31: =SUM(D31,E31,F31) | K31: =SUM(C31,G31,H31,I31,M31,N31) | L31: 4764.38 | M31: ='附表8'!E33 | N31: ='附表8'!F33 | O31: =J31-K31
A32: 12 | B32: 运营期 | C32: 0 | D32: 10170 | E32: 0 | F32: 0 | G32: 4200 | H32: 22.82 | I32: 1182.8 | J32: =SUM(D32,E32,F32) | K32: =SUM(C32,G32,H32,I32,M32,N32) | L32: 4764.38 | M32: ='附表8'!E34 | N32: ='附表8'!F34 | O32: =J32-K32
A33: 13 | B33: 运营期 | C33: 0 | D33: 10170 | E33: 0 | F33: 0 | G33: 4200 | H33: 22.82 | I33: 1182.8 | J33: =SUM(D33,E33,F33) | K33: =SUM(C33,G33,H33,I33,M33,N33) | L33: 4764.38 | M33: ='附表8'!E35 | N33: ='附表8'!F35 | O33: =J33-K33
... A41: 21 | B41: 运营期 | C41: 0 | D41: 10170 | E41: 7680 | F41: 0 | G41: 4200 | H41: 22.82 | I41: 1182.8 | J41: =SUM(D41,E41,F41) | K41: =SUM(C41,G41,H41,I41,M41,N41) | L41: 12444.38 | M41: ='附表8'!E43 | N41: ='附表8'!F43 | O41: =J41-K41
A42: 说明1：资本金IRR=14.39
A43: 说明2：项目IRR=11.58
A44: 说明3：structure_gaps: 行业变体未冻结(variant=tourism, model=tourism)
A46: 现金流量组成树
A47: 项目 | B47: 0 | C47: 1 | D47: 2 | E47: 3 | F47: 4 | G47: 5 | H47: 6 | I47: 7 | J47: 8 | K47: 9 | L47: 10 | M47: 11 | N47: 12 | O47: 13 | P47: 14 | Q47: 15 | R47: 16 | S47: 17 | T47: 18 | U47: 19 | V47: 20 | W47: 21
A48: 现金流入
A49: revenue | B49: ='附表10'!D20 | C49: ='附表10'!D21 | D49: ='附表10'!D22 | E49: ='附表10'!D23 | F49: ='附表10'!D24 | G49: ='附表10'!D25 | H49: ='附表10'!D26 | I49: ='附表10'!D27 | J49: ='附表10'!D28 | K49: ='附表10'!D29 | L49: ='附表10'!D30 | M49: ='附表10'!D31 | N49: ='附表10'!D32 | O49: ='附表10'!D33 | P49: ='附表10'!D34 | Q49: ='附表10'!D35 | R49: ='附表10'!D36 | S49: ='附表10'!D37 | T49: ='附表10'!D38 | U49: ='附表10'!D39 | V49: ='附表10'!D40 | W49: ='附表10'!D41
...
